Workbook

Sheet README
B2: Stripe × Xero Financial Dashboard
B3: FY2025 · Multi-currency · Live formulas · Meta discount add-back
B6: PURPOSE
B7: This workbook consolidates financial data from Stripe, Xero, Bank statements, and Meta (Facebook/WhatsApp) invoices into a single live-formula dashboard. It tracks revenue across WhatsApp, Subscription, and Development streams; monitors receivables for UAE and Singapore entities; and applies a special Meta discount add-back logic so each customer shows a single net Meta cost. Every derived number is a live Excel formula — paste raw rows into the input sheets and every dashboard, KPI, and chart updates automatically.
B13: DATA FLOW
B15: ① PASTE | C15: Raw_Stripe, Raw_Xero, Raw_Bank, Raw_Meta | D15: Drop your exports / CSV rows into these four input sheets.
B17: ② CONFIG | C17: Settings_FX | D17: Edit FX rates monthly, maintain customer master, set company names.
B19: ③ CALCULATE | C19: Revenue_Dashboard, Meta_Expenses, PnL_Statement | D19: Live SUMIFS formulas aggregate raw rows by month, category, customer.
B21: ④ MONITOR | C21: Receivables_Aging | D21: A/R aging by customer across UAE & Singapore entities.
B23: ⑤ REVIEW | C23: Executive_Summary | D23: KPI cards + trend charts for the leadership view.
B25: ⑥ AUDIT | C25: Formula_Audit | D25: Every key formula listed with its description for transparency.
B28: META DISCOUNT ADD-BACK LOGIC
B29: Meta invoices typically show: • Gross Billed (list price) • Discount Given (credit applied by Meta) • Net Paid (amount actually charged to your card = Gross − Discount) Add-Back Formula: Amount_With_AddBack = Net_Paid + Discount_Given This reverses the discount so the dashboard shows the full gross charge per customer — useful for cost-pass-through billing and customer profitability analysis where the discount is yours, not your customer's.
B35: MULTI-CURRENCY HANDLING
B36: Each raw transaction keeps its NATIVE currency (USD, AED, SGD, EUR). A USD-equivalent column on every raw sheet converts via the monthly FX rate table in Settings_FX using: Amount_USD = Amount × FX_Rate(month, currency). Update the FX rate table once per month — every downstream USD total refreshes automatically. Native-currency subtotals are preserved on each dashboard for entity-level reporting (UAE books in AED, Singapore books in SGD).
B42: SHEET DIRECTORY
B44: Settings_FX | C44: FX rates, customer master, company config
B45: Raw_Stripe | C45: Stripe transaction paste-zone
B46: Raw_Xero | C46: Xero journal paste-zone
B47: Raw_Bank | C47: Bank statement paste-zone
B48: Raw_Meta | C48: Meta invoice paste-zone
B49: Revenue_Dashboard | C49: Revenue by category × month + charts
B50: Receivables_Aging | C50: A/R aging by customer (UAE & SG)
B51: Meta_Expenses | C51: Meta cost per customer with add-back
B52: PnL_Statement | C52: Monthly P&L
B53: Executive_Summary | C53: KPI cards + trend charts
B54: Formula_Audit | C54: Every key formula documented

Sheet Executive_Summary
B2: Executive Summary · FY2025 YTD
B3: Stripe × Xero consolidated financial snapshot — live from Raw sheets
B5: TOTAL REVENUE YTD | E5: TOTAL EXPENSES YTD | H5: NET PROFIT YTD | K5: GROSS MARGIN YTD
B6: =PnL_Statement!O10 -> 135760.17 | E6: =PnL_Statement!O14+PnL_Statement!O23 -> 358157.72 | H6: =PnL_Statement!O25 -> -222397.55 | K6: =PnL_Statement!P15 -> 0.015911662
B9: NET PROFIT MARGIN | E9: A/R OUTSTANDING (USD) | H9: META COST YTD (ADD-BACK) | K9: META DISCOUNTS CAPTURED
B10: =PnL_Statement!P25 -> -1.6381649 | E10: =SUM(Raw_Stripe!L6:L33) -> 7147.4 | H10: =SUM(Raw_Meta!L6:L28) -> 133600 | K10: =SUMPRODUCT(Raw_Meta!H6:H28,Raw_Meta!G6:G28)/SUMIF(Raw_Meta!G6:G28,">0",Raw_Meta!G6:G28)*SUM(Raw_Meta!H6:H28) -> 6355179.6
B13: MONTHLY SNAPSHOT
B14: Month | C14: Revenue | D14: Meta Cost | E14: OpEx | F14: Net Profit | G14: Margin %
B15: Jan-25 | C15: =PnL_Statement!C10 -> 24784.46 | D15: =PnL_Statement!C14 -> 19700 | E15: =PnL_Statement!C23 -> 39527.015 | F15: =PnL_Statement!C25 -> -34442.555 | G15: =IFERROR(F15/C15,0) -> -1.3896835
B16: Feb-25 | C16: =PnL_Statement!D10 -> 16234.3 | D16: =PnL_Statement!D14 -> 16300 | E16: =PnL_Statement!D23 -> 40419.25 | F16: =PnL_Statement!D25 -> -40484.95 | G16: =IFERROR(F16/C16,0) -> -2.4937909
B17: Mar-25 | C17: =PnL_Statement!E10 -> 23120.94 | D17: =PnL_Statement!E14 -> 30300 | E17: =PnL_Statement!E23 -> 42379.69 | F17: =PnL_Statement!E25 -> -49558.75 | G17: =IFERROR(F17/C17,0) -> -2.1434574
B18: Apr-25 | C18: =PnL_Statement!F10 -> 3888.26 | D18: =PnL_Statement!F14 -> 9300 | E18: =PnL_Statement!F23 -> 42191.57 | F18: =PnL_Statement!F25 -> -47603.31 | G18: =IFERROR(F18/C18,0) -> -12.242831
B19: May-25 | C19: =PnL_Statement!G10 -> 11173.47 | D19: =PnL_Statement!G14 -> 17300 | E19: =PnL_Statement!G23 -> 18697.1 | F19: =PnL_Statement!G25 -> -24823.63 | G19: =IFERROR(F19/C19,0) -> -2.2216581
B20: Jun-25 | C20: =PnL_Statement!H10 -> 31061.03 | D20: =PnL_Statement!H14 -> 12400 | E20: =PnL_Statement!H23 -> 20075.97 | F20: =PnL_Statement!H25 -> -1414.94 | G20: =IFERROR(F20/C20,0) -> -0.045553544
B21: Jul-25 | C21: =PnL_Statement!I10 -> 11466.71 | D21: =PnL_Statement!I14 -> 14000 | E21: =PnL_Statement!I23 -> 20854.65 | F21: =PnL_Statement!I25 -> -23387.94 | G21: =IFERROR(F21/C21,0) -> -2.0396382
B22: Aug-25 | C22: =PnL_Statement!J10 -> 2831 | D22: =PnL_Statement!J14 -> 4500 | E22: =PnL_Statement!J23 -> 114.5 | F22: =PnL_Statement!J25 -> -1783.5 | G22: =IFERROR(F22/C22,0) -> -0.6299894
B23: Sep-25 | C23: =PnL_Statement!K10 -> 11200 | D23: =PnL_Statement!K14 -> 9800 | E23: =PnL_Statement!K23 -> 297.97 | F23: =PnL_Statement!K25 -> 1102.03 | G23: =IFERROR(F23/C23,0) -> 0.098395536
B24: Oct-25 | C24: =PnL_Statement!L10 -> 0 | D24: =PnL_Statement!L14 -> 0 | E24: =PnL_Statement!L23 -> 0 | F24: =PnL_Statement!L25 -> 0 | G24: =IFERROR(F24/C24,0) -> 0
B25: Nov-25 | C25: =PnL_Statement!M10 -> 0 | D25: =PnL_Statement!M14 -> 0 | E25: =PnL_Statement!M23 -> 0 | F25: =PnL_Statement!M25 -> 0 | G25: =IFERROR(F25/C25,0) -> 0
B26: Dec-25 | C26: =PnL_Statement!N10 -> 0 | D26: =PnL_Statement!N14 -> 0 | E26: =PnL_Statement!N23 -> 0 | F26: =PnL_Statement!N25 -> 0 | G26: =IFERROR(F26/C26,0) -> 0
B27: YTD TOTAL | C27: =SUM(C15:C26) -> 135760.17 | D27: =SUM(D15:D26) -> 133600 | E27: =SUM(E15:E26) -> 224557.71 | F27: =SUM(F15:F26) -> -222397.55 | G27: =IFERROR(F27/C27,0) -> -1.6381649
B30: REVENUE vs EXPENSES TREND
B54: NET PROFIT BY MONTH

Sheet Revenue_Dashboard
B2: Revenue Dashboard · FY2025
B3: Live SUMIFS by category × month — auto-updates from Raw_Stripe
B5: REVENUE BY CATEGORY × MONTH (USD equivalent)
B6: Category | C6: Jan-25 | D6: Feb-25 | E6: Mar-25 | F6: Apr-25 | G6: May-25 | H6: Jun-25 | I6: Jul-25 | J6: Aug-25 | K6: Sep-25 | L6: Oct-25 | M6: Nov-25 | N6: Dec-25 | O6: YTD Total
B7: WhatsApp | C7: =SUMIFS(Raw_Stripe!$H$6:$H$33,Raw_Stripe!$M$6:$M$33,"Jan-25",Raw_Stripe!$N$6:$N$33,"WhatsApp") -> 4202.01 | D7: =SUMIFS(Raw_Stripe!$H$6:$H$33,Raw_Stripe!$M$6:$M$33,"Feb-25",Raw_Stripe!$N$6:$N$33,"WhatsApp") -> 3825.85 | E7: =SUMIFS(Raw_Stripe!$H$6:$H$33,Raw_Stripe!$M$6:$M$33,"Mar-25",Raw_Stripe!$N$6:$N$33,"WhatsApp") -> 4625.64 | F7: =SUMIFS(Raw_Stripe!$H$6:$H$33,Raw_Stripe!$M$6:$M$33,"Apr-25",Raw_Stripe!$N$6:$N$33,"WhatsApp") -> 1279.81 | G7: =SUMIFS(Raw_Stripe!$H$6:$H$33,Raw_Stripe!$M$6:$M$33,"May-25",Raw_Stripe!$N$6:$N$33,"WhatsApp") -> 1334.27 | H7: =SUMIFS(Raw_Stripe!$H$6:$H$33,Raw_Stripe!$M$6:$M$33,"Jun-25",Raw_Stripe!$N$6:$N$33,"WhatsApp") -> 7061.03 | I7: =SUMIFS(Raw_Stripe!$H$6:$H$33,Raw_Stripe!$M$6:$M$33,"Jul-25",Raw_Stripe!$N$6:$N$33,"WhatsApp") -> 1415.96 | J7: =SUMIFS(Raw_Stripe!$H$6:$H$33,Raw_Stripe!$M$6:$M$33,"Aug-25",Raw_Stripe!$N$6:$N$33,"WhatsApp") -> 2831 | K7: =SUMIFS(Raw_Stripe!$H$6:$H$33,Raw_Stripe!$M$6:$M$33,"Sep-25",Raw_Stripe!$N$6:$N$33,"WhatsApp") -> 0 | L7: =SUMIFS(Raw_Stripe!$H$6:$H$33,Raw_Stripe!$M$6:$M$33,"Oct-25",Raw_Stripe!$N$6:$N$33,"WhatsApp") -> 0 | M7: =SUMIFS(Raw_Stripe!$H$6:$H$33,Raw_Stripe!$M$6:$M$33,"Nov-25",Raw_Stripe!$N$6:$N$33,"WhatsApp") -> 0 | N7: =SUMIFS(Raw_Stripe!$H$6:$H$33,Raw_Stripe!$M$6:$M$33,"Dec-25",Raw_Stripe!$N$6:$N$33,"WhatsApp") -> 0 | O7: =SUM(C7:N7) -> 26575.57
B8: Subscription | C8: =SUMIFS(Raw_Stripe!$H$6:$H$33,Raw_Stripe!$M$6:$M$33,"Jan-25",Raw_Stripe!$N$6:$N$33,"Subscription") -> 13782.45 | D8: =SUMIFS(Raw_Stripe!$H$6:$H$33,Raw_Stripe!$M$6:$M$33,"Feb-25",Raw_Stripe!$N$6:$N$33,"Subscription") -> 408.45 | E8: =SUMIFS(Raw_Stripe!$H$6:$H$33,Raw_Stripe!$M$6:$M$33,"Mar-25",Raw_Stripe!$N$6:$N$33,"Subscription") -> 408.45 | F8: =SUMIFS(Raw_Stripe!$H$6:$H$33,Raw_Stripe!$M$6:$M$33,"Apr-25",Raw_Stripe!$N$6:$N$33,"Subscription") -> 2608.45 | G8: =SUMIFS(Raw_Stripe!$H$6:$H$33,Raw_Stripe!$M$6:$M$33,"May-25",Raw_Stripe!$N$6:$N$33,"Subscription") -> 1339.2 | H8: =SUMIFS(Raw_Stripe!$H$6:$H$33,Raw_Stripe!$M$6:$M$33,"Jun-25",Raw_Stripe!$N$6:$N$33,"Subscription") -> 24000 | I8: =SUMIFS(Raw_Stripe!$H$6:$H$33,Raw_Stripe!$M$6:$M$33,"Jul-25",Raw_Stripe!$N$6:$N$33,"Subscription") -> 0 | J8: =SUMIFS(Raw_Stripe!$H$6:$H$33,Raw_Stripe!$M$6:$M$33,"Aug-25",Raw_Stripe!$N$6:$N$33,"Subscription") -> 0 | K8: =SUMIFS(Raw_Stripe!$H$6:$H$33,Raw_Stripe!$M$6:$M$33,"Sep-25",Raw_Stripe!$N$6:$N$33,"Subscription") -> 0 | L8: =SUMIFS(Raw_Stripe!$H$6:$H$33,Raw_Stripe!$M$6:$M$33,"Oct-25",Raw_Stripe!$N$6:$N$33,"Subscription") -> 0 | M8: =SUMIFS(Raw_Stripe!$H$6:$H$33,Raw_Stripe!$M$6:$M$33,"Nov-25",Raw_Stripe!$N$6:$N$33,"Subscription") -> 0 | N8: =SUMIFS(Raw_Stripe!$H$6:$H$33,Raw_Stripe!$M$6:$M$33,"Dec-25",Raw_Stripe!$N$6:$N$33,"Subscription") -> 0 | O8: =SUM(C8:N8) -> 42547
B9: Development | C9: =SUMIFS(Raw_Stripe!$H$6:$H$33,Raw_Stripe!$M$6:$M$33,"Jan-25",Raw_Stripe!$N$6:$N$33,"Development") -> 6800 | D9: =SUMIFS(Raw_Stripe!$H$6:$H$33,Raw_Stripe!$M$6:$M$33,"Feb-25",Raw_Stripe!$N$6:$N$33,"Development") -> 12000 | E9: =SUMIFS(Raw_Stripe!$H$6:$H$33,Raw_Stripe!$M$6:$M$33,"Mar-25",Raw_Stripe!$N$6:$N$33,"Development") -> 18086.85 | F9: =SUMIFS(Raw_Stripe!$H$6:$H$33,Raw_Stripe!$M$6:$M$33,"Apr-25",Raw_Stripe!$N$6:$N$33,"Development") -> 0 | G9: =SUMIFS(Raw_Stripe!$H$6:$H$33,Raw_Stripe!$M$6:$M$33,"May-25",Raw_Stripe!$N$6:$N$33,"Development") -> 8500 | H9: =SUMIFS(Raw_Stripe!$H$6:$H$33,Raw_Stripe!$M$6:$M$33,"Jun-25",Raw_Stripe!$N$6:$N$33,"Development") -> 0 | I9: =SUMIFS(Raw_Stripe!$H$6:$H$33,Raw_Stripe!$M$6:$M$33,"Jul-25",Raw_Stripe!$N$6:$N$33,"Development") -> 10050.75 | J9: =SUMIFS(Raw_Stripe!$H$6:$H$33,Raw_Stripe!$M$6:$M$33,"Aug-25",Raw_Stripe!$N$6:$N$33,"Development") -> 0 | K9: =SUMIFS(Raw_Stripe!$H$6:$H$33,Raw_Stripe!$M$6:$M$33,"Sep-25",Raw_Stripe!$N$6:$N$33,"Development") -> 11200 | L9: =SUMIFS(Raw_Stripe!$H$6:$H$33,Raw_Stripe!$M$6:$M$33,"Oct-25",Raw_Stripe!$N$6:$N$33,"Development") -> 0 | M9: =SUMIFS(Raw_Stripe!$H$6:$H$33,Raw_Stripe!$M$6:$M$33,"Nov-25",Raw_Stripe!$N$6:$N$33,"Development") -> 0 | N9: =SUMIFS(Raw_Stripe!$H$6:$H$33,Raw_Stripe!$M$6:$M$33,"Dec-25",Raw_Stripe!$N$6:$N$33,"Development") -> 0 | O9: =SUM(C9:N9) -> 66637.6
B10: TOTAL REVENUE | C10: =SUM(C7:C9) -> 24784.46 | D10: =SUM(D7:D9) -> 16234.3 | E10: =SUM(E7:E9) -> 23120.94 | F10: =SUM(F7:F9) -> 3888.26 | G10: =SUM(G7:G9) -> 11173.47 | H10: =SUM(H7:H9) -> 31061.03 | I10: =SUM(I7:I9) -> 11466.71 | J10: =SUM(J7:J9) -> 2831 | ... N10: =SUM(N7:N9) -> 0 | O10: =SUM(C10:N10) -> 135760.17
B11: MoM Growth % | C11: — | D11: =IFERROR((D10/C10)-1,"-") -> -0.34498069 | E11: =IFERROR((E10/D10)-1,"-") -> 0.42420308 | F11: =IFERROR((F10/E10)-1,"-") -> -0.8318295 | G11: =IFERROR((G10/F10)-1,"-") -> 1.8736427 | H11: =IFERROR((H10/G10)-1,"-") -> 1.7798911 | I11: =IFERROR((I10/H10)-1,"-") -> -0.63083291 | J11: =IFERROR((J10/I10)-1,"-") -> -0.7531114 | K11: =IFERROR((K10/J10)-1,"-") -> 2.9561992 | ... N11: =IFERROR((N10/M10)-1,"-") -> -
B14: REVENUE TREND CHART (clustered bar — categories × months)

Sheet Receivables_Aging
B2: Receivables Aging · UAE & Singapore
B3: Outstanding by customer, bucketed by invoice age — live from Raw_Stripe
B5: UAE Company (UAE)
B6: Customer | C6: Total Outstanding | D6: Current (0-30) | E6: 31-60 days | F6: 60+ days | G6: Currency | H6: USD Equivalent | I6: % of Total | J6: Oldest Inv. | K6: Status
B7: Alphabet Logistics LLC | C7: =SUMIFS(Raw_Stripe!$L$6:$L$33,Raw_Stripe!$D$6:$D$33,B7,Raw_Stripe!$O$6:$O$33,"UAE") -> 2054.5 | D7: =SUMIFS(Raw_Stripe!$L$6:$L$33,Raw_Stripe!$D$6:$D$33,B7,Raw_Stripe!$O$6:$O$33,"UAE",Raw_Stripe!$C$6:$C$33,">="&(TODAY()-30)) -> 0 | E7: =SUMIFS(Raw_Stripe!$L$6:$L$33,Raw_Stripe!$D$6:$D$33,B7,Raw_Stripe!$O$6:$O$33,"UAE",Raw_Stripe!$C$6:$C$33,">="&(TODAY()-60),Raw_Stripe!$C$6:$C$33,"<"&(TODAY()-30)) -> 0 | F7: =SUMIFS(Raw_Stripe!$L$6:$L$33,Raw_Stripe!$D$6:$D$33,B7,Raw_Stripe!$O$6:$O$33,"UAE",Raw_Stripe!$C$6:$C$33,"<"&(TODAY()-60)) -> 2054.5 | G7: AED | H7: =C7*Settings_FX!D$27 -> 559.44035 | I7: =IFERROR(C7/$C$15,0) -> 1 | J7: =IFERROR(minifs(Raw_Stripe!$C$6:$C$33,Raw_Stripe!$D$6:$D$33,B7,Raw_Stripe!$L$6:$L$33,">0"),"") | K7: =IF(F7>0,"⚠ 60+ days",IF(E7>0,"⚠ 31-60 days","✓ Current")) -> ⚠ 60+ days
B8: Emirates Retail Group | C8: =SUMIFS(Raw_Stripe!$L$6:$L$33,Raw_Stripe!$D$6:$D$33,B8,Raw_Stripe!$O$6:$O$33,"UAE") -> 0 | D8: =SUMIFS(Raw_Stripe!$L$6:$L$33,Raw_Stripe!$D$6:$D$33,B8,Raw_Stripe!$O$6:$O$33,"UAE",Raw_Stripe!$C$6:$C$33,">="&(TODAY()-30)) -> 0 | E8: =SUMIFS(Raw_Stripe!$L$6:$L$33,Raw_Stripe!$D$6:$D$33,B8,Raw_Stripe!$O$6:$O$33,"UAE",Raw_Stripe!$C$6:$C$33,">="&(TODAY()-60),Raw_Stripe!$C$6:$C$33,"<"&(TODAY()-30)) -> 0 | F8: =SUMIFS(Raw_Stripe!$L$6:$L$33,Raw_Stripe!$D$6:$D$33,B8,Raw_Stripe!$O$6:$O$33,"UAE",Raw_Stripe!$C$6:$C$33,"<"&(TODAY()-60)) -> 0 | G8: AED | H8: =C8*Settings_FX!D$27 -> 0 | I8: =IFERROR(C8/$C$15,0) -> 0 | J8: =IFERROR(minifs(Raw_Stripe!$C$6:$C$33,Raw_Stripe!$D$6:$D$33,B8,Raw_Stripe!$L$6:$L$33,">0"),"") | K8: =IF(F8>0,"⚠ 60+ days",IF(E8>0,"⚠ 31-60 days","✓ Current")) -> ✓ Current
B9: Gulf Tech Distribution | C9: =SUMIFS(Raw_Stripe!$L$6:$L$33,Raw_Stripe!$D$6:$D$33,B9,Raw_Stripe!$O$6:$O$33,"UAE") -> 0 | D9: =SUMIFS(Raw_Stripe!$L$6:$L$33,Raw_Stripe!$D$6:$D$33,B9,Raw_Stripe!$O$6:$O$33,"UAE",Raw_Stripe!$C$6:$C$33,">="&(TODAY()-30)) -> 0 | E9: =SUMIFS(Raw_Stripe!$L$6:$L$33,Raw_Stripe!$D$6:$D$33,B9,Raw_Stripe!$O$6:$O$33,"UAE",Raw_Stripe!$C$6:$C$33,">="&(TODAY()-60),Raw_Stripe!$C$6:$C$33,"<"&(TODAY()-30)) -> 0 | F9: =SUMIFS(Raw_Stripe!$L$6:$L$33,Raw_Stripe!$D$6:$D$33,B9,Raw_Stripe!$O$6:$O$33,"UAE",Raw_Stripe!$C$6:$C$33,"<"&(TODAY()-60)) -> 0 | G9: USD | H9: =C9 -> 0 | I9: =IFERROR(C9/$C$15,0) -> 0 | J9: =IFERROR(minifs(Raw_Stripe!$C$6:$C$33,Raw_Stripe!$D$6:$D$33,B9,Raw_Stripe!$L$6:$L$33,">0"),"") | K9: =IF(F9>0,"⚠ 60+ days",IF(E9>0,"⚠ 31-60 days","✓ Current")) -> ✓ Current
B10: Dubai Properties Co | C10: =SUMIFS(Raw_Stripe!$L$6:$L$33,Raw_Stripe!$D$6:$D$33,B10,Raw_Stripe!$O$6:$O$33,"UAE") -> 0 | D10: =SUMIFS(Raw_Stripe!$L$6:$L$33,Raw_Stripe!$D$6:$D$33,B10,Raw_Stripe!$O$6:$O$33,"UAE",Raw_Stripe!$C$6:$C$33,">="&(TODAY()-30)) -> 0 | E10: =SUMIFS(Raw_Stripe!$L$6:$L$33,Raw_Stripe!$D$6:$D$33,B10,Raw_Stripe!$O$6:$O$33,"UAE",Raw_Stripe!$C$6:$C$33,">="&(TODAY()-60),Raw_Stripe!$C$6:$C$33,"<"&(TODAY()-30)) -> 0 | F10: =SUMIFS(Raw_Stripe!$L$6:$L$33,Raw_Stripe!$D$6:$D$33,B10,Raw_Stripe!$O$6:$O$33,"UAE",Raw_Stripe!$C$6:$C$33,"<"&(TODAY()-60)) -> 0 | G10: AED | H10: =C10*Settings_FX!D$27 -> 0 | I10: =IFERROR(C10/$C$15,0) -> 0 | J10: =IFERROR(minifs(Raw_Stripe!$C$6:$C$33,Raw_Stripe!$D$6:$D$33,B10,Raw_Stripe!$L$6:$L$33,">0"),"") | K10: =IF(F10>0,"⚠ 60+ days",IF(E10>0,"⚠ 31-60 days","✓ Current")) -> ✓ Current
B11: Abu Dhabi Trading | C11: =SUMIFS(Raw_Stripe!$L$6:$L$33,Raw_Stripe!$D$6:$D$33,B11,Raw_Stripe!$O$6:$O$33,"UAE") -> 0 | D11: =SUMIFS(Raw_Stripe!$L$6:$L$33,Raw_Stripe!$D$6:$D$33,B11,Raw_Stripe!$O$6:$O$33,"UAE",Raw_Stripe!$C$6:$C$33,">="&(TODAY()-30)) -> 0 | E11: =SUMIFS(Raw_Stripe!$L$6:$L$33,Raw_Stripe!$D$6:$D$33,B11,Raw_Stripe!$O$6:$O$33,"UAE",Raw_Stripe!$C$6:$C$33,">="&(TODAY()-60),Raw_Stripe!$C$6:$C$33,"<"&(TODAY()-30)) -> 0 | F11: =SUMIFS(Raw_Stripe!$L$6:$L$33,Raw_Stripe!$D$6:$D$33,B11,Raw_Stripe!$O$6:$O$33,"UAE",Raw_Stripe!$C$6:$C$33,"<"&(TODAY()-60)) -> 0 | G11: AED | H11: =C11*Settings_FX!D$27 -> 0 | I11: =IFERROR(C11/$C$15,0) -> 0 | J11: =IFERROR(minifs(Raw_Stripe!$C$6:$C$33,Raw_Stripe!$D$6:$D$33,B11,Raw_Stripe!$L$6:$L$33,">0"),"") | K11: =IF(F11>0,"⚠ 60+ days",IF(E11>0,"⚠ 31-60 days","✓ Current")) -> ✓ Current
B12: Rak Bank Digital | C12: =SUMIFS(Raw_Stripe!$L$6:$L$33,Raw_Stripe!$D$6:$D$33,B12,Raw_Stripe!$O$6:$O$33,"UAE") -> 0 | D12: =SUMIFS(Raw_Stripe!$L$6:$L$33,Raw_Stripe!$D$6:$D$33,B12,Raw_Stripe!$O$6:$O$33,"UAE",Raw_Stripe!$C$6:$C$33,">="&(TODAY()-30)) -> 0 | E12: =SUMIFS(Raw_Stripe!$L$6:$L$33,Raw_Stripe!$D$6:$D$33,B12,Raw_Stripe!$O$6:$O$33,"UAE",Raw_Stripe!$C$6:$C$33,">="&(TODAY()-60),Raw_Stripe!$C$6:$C$33,"<"&(TODAY()-30)) -> 0 | F12: =SUMIFS(Raw_Stripe!$L$6:$L$33,Raw_Stripe!$D$6:$D$33,B12,Raw_Stripe!$O$6:$O$33,"UAE",Raw_Stripe!$C$6:$C$33,"<"&(TODAY()-60)) -> 0 | G12: AED | H12: =C12*Settings_FX!D$27 -> 0 | I12: =IFERROR(C12/$C$15,0) -> 0 | J12: =IFERROR(minifs(Raw_Stripe!$C$6:$C$33,Raw_Stripe!$D$6:$D$33,B12,Raw_Stripe!$L$6:$L$33,">0"),"") | K12: =IF(F12>0,"⚠ 60+ days",IF(E12>0,"⚠ 31-60 days","✓ Current")) -> ✓ Current
B13: Global SaaS Inc | C13: =SUMIFS(Raw_Stripe!$L$6:$L$33,Raw_Stripe!$D$6:$D$33,B13,Raw_Stripe!$O$6:$O$33,"UAE") -> 0 | D13: =SUMIFS(Raw_Stripe!$L$6:$L$33,Raw_Stripe!$D$6:$D$33,B13,Raw_Stripe!$O$6:$O$33,"UAE",Raw_Stripe!$C$6:$C$33,">="&(TODAY()-30)) -> 0 | E13: =SUMIFS(Raw_Stripe!$L$6:$L$33,Raw_Stripe!$D$6:$D$33,B13,Raw_Stripe!$O$6:$O$33,"UAE",Raw_Stripe!$C$6:$C$33,">="&(TODAY()-60),Raw_Stripe!$C$6:$C$33,"<"&(TODAY()-30)) -> 0 | F13: =SUMIFS(Raw_Stripe!$L$6:$L$33,Raw_Stripe!$D$6:$D$33,B13,Raw_Stripe!$O$6:$O$33,"UAE",Raw_Stripe!$C$6:$C$33,"<"&(TODAY()-60)) -> 0 | G13: USD | H13: =C13 -> 0 | I13: =IFERROR(C13/$C$15,0) -> 0 | J13: =IFERROR(minifs(Raw_Stripe!$C$6:$C$33,Raw_Stripe!$D$6:$D$33,B13,Raw_Stripe!$L$6:$L$33,">0"),"") | K13: =IF(F13>0,"⚠ 60+ days",IF(E13>0,"⚠ 31-60 days","✓ Current")) -> ✓ Current
B14: Mena Apps FZ-LLC | C14: =SUMIFS(Raw_Stripe!$L$6:$L$33,Raw_Stripe!$D$6:$D$33,B14,Raw_Stripe!$O$6:$O$33,"UAE") -> 0 | D14: =SUMIFS(Raw_Stripe!$L$6:$L$33,Raw_Stripe!$D$6:$D$33,B14,Raw_Stripe!$O$6:$O$33,"UAE",Raw_Stripe!$C$6:$C$33,">="&(TODAY()-30)) -> 0 | E14: =SUMIFS(Raw_Stripe!$L$6:$L$33,Raw_Stripe!$D$6:$D$33,B14,Raw_Stripe!$O$6:$O$33,"UAE",Raw_Stripe!$C$6:$C$33,">="&(TODAY()-60),Raw_Stripe!$C$6:$C$33,"<"&(TODAY()-30)) -> 0 | F14: =SUMIFS(Raw_Stripe!$L$6:$L$33,Raw_Stripe!$D$6:$D$33,B14,Raw_Stripe!$O$6:$O$33,"UAE",Raw_Stripe!$C$6:$C$33,"<"&(TODAY()-60)) -> 0 | G14: USD | H14: =C14 -> 0 | I14: =IFERROR(C14/$C$15,0) -> 0 | J14: =IFERROR(minifs(Raw_Stripe!$C$6:$C$33,Raw_Stripe!$D$6:$D$33,B14,Raw_Stripe!$L$6:$L$33,">0"),"") | K14: =IF(F14>0,"⚠ 60+ days",IF(E14>0,"⚠ 31-60 days","✓ Current")) -> ✓ Current
B15: TOTAL UAE | C15: =SUM(C7:C14) -> 2054.5 | D15: =SUM(D7:D14) -> 0 | E15: =SUM(E7:E14) -> 0 | F15: =SUM(F7:F14) -> 2054.5 | H15: =SUM(H7:H14) -> 559.44035
B18: Singapore Company (SG)
B19: Customer | C19: Total Outstanding | D19: Current (0-30) | E19: 31-60 days | F19: 60+ days | G19: Currency | H19: USD Equivalent | I19: % of Total | J19: Oldest Inv. | K19: Status
B20: Singapore FinTech Hub | C20: =SUMIFS(Raw_Stripe!$L$6:$L$33,Raw_Stripe!$D$6:$D$33,B20,Raw_Stripe!$O$6:$O$33,"SG") -> 0 | D20: =SUMIFS(Raw_Stripe!$L$6:$L$33,Raw_Stripe!$D$6:$D$33,B20,Raw_Stripe!$O$6:$O$33,"SG",Raw_Stripe!$C$6:$C$33,">="&(TODAY()-30)) -> 0 | E20: =SUMIFS(Raw_Stripe!$L$6:$L$33,Raw_Stripe!$D$6:$D$33,B20,Raw_Stripe!$O$6:$O$33,"SG",Raw_Stripe!$C$6:$C$33,">="&(TODAY()-60),Raw_Stripe!$C$6:$C$33,"<"&(TODAY()-30)) -> 0 | F20: =SUMIFS(Raw_Stripe!$L$6:$L$33,Raw_Stripe!$D$6:$D$33,B20,Raw_Stripe!$O$6:$O$33,"SG",Raw_Stripe!$C$6:$C$33,"<"&(TODAY()-60)) -> 0 | G20: SGD | H20: =C20*Settings_FX!E$27 -> 0 | I20: =IFERROR(C20/$C$27,0) -> 0 | J20: =IFERROR(minifs(Raw_Stripe!$C$6:$C$33,Raw_Stripe!$D$6:$D$33,B20,Raw_Stripe!$L$6:$L$33,">0"),"") | K20: =IF(F20>0,"⚠ 60+ days",IF(E20>0,"⚠ 31-60 days","✓ Current")) -> ✓ Current
B21: Asia Pacific Solutions | C21: =SUMIFS(Raw_Stripe!$L$6:$L$33,Raw_Stripe!$D$6:$D$33,B21,Raw_Stripe!$O$6:$O$33,"SG") -> 0 | D21: =SUMIFS(Raw_Stripe!$L$6:$L$33,Raw_Stripe!$D$6:$D$33,B21,Raw_Stripe!$O$6:$O$33,"SG",Raw_Stripe!$C$6:$C$33,">="&(TODAY()-30)) -> 0 | E21: =SUMIFS(Raw_Stripe!$L$6:$L$33,Raw_Stripe!$D$6:$D$33,B21,Raw_Stripe!$O$6:$O$33,"SG",Raw_Stripe!$C$6:$C$33,">="&(TODAY()-60),Raw_Stripe!$C$6:$C$33,"<"&(TODAY()-30)) -> 0 | F21: =SUMIFS(Raw_Stripe!$L$6:$L$33,Raw_Stripe!$D$6:$D$33,B21,Raw_Stripe!$O$6:$O$33,"SG",Raw_Stripe!$C$6:$C$33,"<"&(TODAY()-60)) -> 0 | G21: USD | H21: =C21 -> 0 | I21: =IFERROR(C21/$C$27,0) -> 0 | J21: =IFERROR(minifs(Raw_Stripe!$C$6:$C$33,Raw_Stripe!$D$6:$D$33,B21,Raw_Stripe!$L$6:$L$33,">0"),"") | K21: =IF(F21>0,"⚠ 60+ days",IF(E21>0,"⚠ 31-60 days","✓ Current")) -> ✓ Current
B22: Marina Bay Holdings | C22: =SUMIFS(Raw_Stripe!$L$6:$L$33,Raw_Stripe!$D$6:$D$33,B22,Raw_Stripe!$O$6:$O$33,"SG") -> 0 | D22: =SUMIFS(Raw_Stripe!$L$6:$L$33,Raw_Stripe!$D$6:$D$33,B22,Raw_Stripe!$O$6:$O$33,"SG",Raw_Stripe!$C$6:$C$33,">="&(TODAY()-30)) -> 0 | E22: =SUMIFS(Raw_Stripe!$L$6:$L$33,Raw_Stripe!$D$6:$D$33,B22,Raw_Stripe!$O$6:$O$33,"SG",Raw_Stripe!$C$6:$C$33,">="&(TODAY()-60),Raw_Stripe!$C$6:$C$33,"<"&(TODAY()-30)) -> 0 | F22: =SUMIFS(Raw_Stripe!$L$6:$L$33,Raw_Stripe!$D$6:$D$33,B22,Raw_Stripe!$O$6:$O$33,"SG",Raw_Stripe!$C$6:$C$33,"<"&(TODAY()-60)) -> 0 | G22: SGD | H22: =C22*Settings_FX!E$27 -> 0 | I22: =IFERROR(C22/$C$27,0) -> 0 | J22: =IFERROR(minifs(Raw_Stripe!$C$6:$C$33,Raw_Stripe!$D$6:$D$33,B22,Raw_Stripe!$L$6:$L$33,">0"),"") | K22: =IF(F22>0,"⚠ 60+ days",IF(E22>0,"⚠ 31-60 days","✓ Current")) -> ✓ Current
B23: Lion City Media | C23: =SUMIFS(Raw_Stripe!$L$6:$L$33,Raw_Stripe!$D$6:$D$33,B23,Raw_Stripe!$O$6:$O$33,"SG") -> 0 | D23: =SUMIFS(Raw_Stripe!$L$6:$L$33,Raw_Stripe!$D$6:$D$33,B23,Raw_Stripe!$O$6:$O$33,"SG",Raw_Stripe!$C$6:$C$33,">="&(TODAY()-30)) -> 0 | E23: =SUMIFS(Raw_Stripe!$L$6:$L$33,Raw_Stripe!$D$6:$D$33,B23,Raw_Stripe!$O$6:$O$33,"SG",Raw_Stripe!$C$6:$C$33,">="&(TODAY()-60),Raw_Stripe!$C$6:$C$33,"<"&(TODAY()-30)) -> 0 | F23: =SUMIFS(Raw_Stripe!$L$6:$L$33,Raw_Stripe!$D$6:$D$33,B23,Raw_Stripe!$O$6:$O$33,"SG",Raw_Stripe!$C$6:$C$33,"<"&(TODAY()-60)) -> 0 | G23: SGD | H23: =C23*Settings_FX!E$27 -> 0 | I23: =IFERROR(C23/$C$27,0) -> 0 | J23: =IFERROR(minifs(Raw_Stripe!$C$6:$C$33,Raw_Stripe!$D$6:$D$33,B23,Raw_Stripe!$L$6:$L$33,">0"),"") | K23: =IF(F23>0,"⚠ 60+ days",IF(E23>0,"⚠ 31-60 days","✓ Current")) -> ✓ Current
B24: Sentosa E-Commerce | C24: =SUMIFS(Raw_Stripe!$L$6:$L$33,Raw_Stripe!$D$6:$D$33,B24,Raw_Stripe!$O$6:$O$33,"SG") -> 0 | D24: =SUMIFS(Raw_Stripe!$L$6:$L$33,Raw_Stripe!$D$6:$D$33,B24,Raw_Stripe!$O$6:$O$33,"SG",Raw_Stripe!$C$6:$C$33,">="&(TODAY()-30)) -> 0 | E24: =SUMIFS(Raw_Stripe!$L$6:$L$33,Raw_Stripe!$D$6:$D$33,B24,Raw_Stripe!$O$6:$O$33,"SG",Raw_Stripe!$C$6:$C$33,">="&(TODAY()-60),Raw_Stripe!$C$6:$C$33,"<"&(TODAY()-30)) -> 0 | F24: =SUMIFS(Raw_Stripe!$L$6:$L$33,Raw_Stripe!$D$6:$D$33,B24,Raw_Stripe!$O$6:$O$33,"SG",Raw_Stripe!$C$6:$C$33,"<"&(TODAY()-60)) -> 0 | G24: USD | H24: =C24 -> 0 | I24: =IFERROR(C24/$C$27,0) -> 0 | J24: =IFERROR(minifs(Raw_Stripe!$C$6:$C$33,Raw_Stripe!$D$6:$D$33,B24,Raw_Stripe!$L$6:$L$33,">0"),"") | K24: =IF(F24>0,"⚠ 60+ days",IF(E24>0,"⚠ 31-60 days","✓ Current")) -> ✓ Current
B25: Orchard Retail Pte | C25: =SUMIFS(Raw_Stripe!$L$6:$L$33,Raw_Stripe!$D$6:$D$33,B25,Raw_Stripe!$O$6:$O$33,"SG") -> 5092.9 | D25: =SUMIFS(Raw_Stripe!$L$6:$L$33,Raw_Stripe!$D$6:$D$33,B25,Raw_Stripe!$O$6:$O$33,"SG",Raw_Stripe!$C$6:$C$33,">="&(TODAY()-30)) -> 0 | E25: =SUMIFS(Raw_Stripe!$L$6:$L$33,Raw_Stripe!$D$6:$D$33,B25,Raw_Stripe!$O$6:$O$33,"SG",Raw_Stripe!$C$6:$C$33,">="&(TODAY()-60),Raw_Stripe!$C$6:$C$33,"<"&(TODAY()-30)) -> 0 | F25: =SUMIFS(Raw_Stripe!$L$6:$L$33,Raw_Stripe!$D$6:$D$33,B25,Raw_Stripe!$O$6:$O$33,"SG",Raw_Stripe!$C$6:$C$33,"<"&(TODAY()-60)) -> 5092.9 | G25: SGD | H25: =C25*Settings_FX!E$27 -> 3804.3963 | I25: =IFERROR(C25/$C$27,0) -> 1 | J25: =IFERROR(minifs(Raw_Stripe!$C$6:$C$33,Raw_Stripe!$D$6:$D$33,B25,Raw_Stripe!$L$6:$L$33,">0"),"") | K25: =IF(F25>0,"⚠ 60+ days",IF(E25>0,"⚠ 31-60 days","✓ Current")) -> ⚠ 60+ days
B26: Jakarta Digital Ventures | C26: =SUMIFS(Raw_Stripe!$L$6:$L$33,Raw_Stripe!$D$6:$D$33,B26,Raw_Stripe!$O$6:$O$33,"SG") -> 0 | D26: =SUMIFS(Raw_Stripe!$L$6:$L$33,Raw_Stripe!$D$6:$D$33,B26,Raw_Stripe!$O$6:$O$33,"SG",Raw_Stripe!$C$6:$C$33,">="&(TODAY()-30)) -> 0 | E26: =SUMIFS(Raw_Stripe!$L$6:$L$33,Raw_Stripe!$D$6:$D$33,B26,Raw_Stripe!$O$6:$O$33,"SG",Raw_Stripe!$C$6:$C$33,">="&(TODAY()-60),Raw_Stripe!$C$6:$C$33,"<"&(TODAY()-30)) -> 0 | F26: =SUMIFS(Raw_Stripe!$L$6:$L$33,Raw_Stripe!$D$6:$D$33,B26,Raw_Stripe!$O$6:$O$33,"SG",Raw_Stripe!$C$6:$C$33,"<"&(TODAY()-60)) -> 0 | G26: USD | H26: =C26 -> 0 | I26: =IFERROR(C26/$C$27,0) -> 0 | J26: =IFERROR(minifs(Raw_Stripe!$C$6:$C$33,Raw_Stripe!$D$6:$D$33,B26,Raw_Stripe!$L$6:$L$33,">0"),"") | K26: =IF(F26>0,"⚠ 60+ days",IF(E26>0,"⚠ 31-60 days","✓ Current")) -> ✓ Current
B27: TOTAL SG | C27: =SUM(C20:C26) -> 5092.9 | D27: =SUM(D20:D26) -> 0 | E27: =SUM(E20:E26) -> 0 | F27: =SUM(F20:F26) -> 5092.9 | H27: =SUM(H20:H26) -> 3804.3963
B29: COMBINED A/R SUMMARY
B30: Total UAE Outstanding (USD) | C30: =H15 -> 559.44035
B31: Total SG Outstanding (USD) | C31: =H27 -> 3804.3963
B32: Combined Outstanding (USD) | C32: =H15+H27 -> 4363.8367
B33: Customers with 60+ days A/R | C33: =COUNTIF(K6:K14,"*60+*")+COUNTIF(K19:K26,"*60+*") -> 2

Sheet Meta_Expenses
B2: Meta Expenses · With Discount Add-Back
B3: Per-customer Meta cost: Net Paid + Discount Given = Amount With Add-Back (USD)
B5: PER-CUSTOMER META COST (USD equivalent, with add-back)
B6: Customer | C6: Gross Billed | D6: Discount Given | E6: Net Paid | F6: Amount With AddBack | G6: % Discount | H6: # Invoices | I6: Jan | J6: Feb | K6: Mar | L6: Apr | M6: May | N6: Jun | O6: Jul-Aug-Dec
B7: Alphabet Logistics LLC | C7: =SUMIFS(Raw_Meta!$L$6:$L$28,Raw_Meta!$E$6:$E$28,B7) -> 35700 | D7: =IFERROR(SUMIFS(Raw_Meta!$L$6:$L$28,Raw_Meta!$E$6:$E$28,B7)*SUMIFS(Raw_Meta!$H$6:$H$28,Raw_Meta!$E$6:$E$28,B7)/SUMIFS(Raw_Meta!$G$6:$G$28,Raw_Meta!$E$6:$E$28,B7),0) -> 3500 | E7: =C7-D7 -> 32200 | F7: =C7 -> 35700 | G7: =IFERROR(D7/C7,0) -> 0.098039216 | H7: =COUNTIFS(Raw_Meta!$E$6:$E$28,B7) -> 6 | I7: =SUMIFS(Raw_Meta!$L$6:$L$28,Raw_Meta!$E$6:$E$28,B7,Raw_Meta!$N$6:$N$28,"Jan-25") -> 5200 | J7: =SUMIFS(Raw_Meta!$L$6:$L$28,Raw_Meta!$E$6:$E$28,B7,Raw_Meta!$N$6:$N$28,"Feb-25") -> 5500 | K7: =SUMIFS(Raw_Meta!$L$6:$L$28,Raw_Meta!$E$6:$E$28,B7,Raw_Meta!$N$6:$N$28,"Mar-25") -> 5800 | L7: =SUMIFS(Raw_Meta!$L$6:$L$28,Raw_Meta!$E$6:$E$28,B7,Raw_Meta!$N$6:$N$28,"Apr-25") -> 6100 | M7: =SUMIFS(Raw_Meta!$L$6:$L$28,Raw_Meta!$E$6:$E$28,B7,Raw_Meta!$N$6:$N$28,"May-25") -> 6300 | N7: =SUMIFS(Raw_Meta!$L$6:$L$28,Raw_Meta!$E$6:$E$28,B7,Raw_Meta!$N$6:$N$28,"Jun-25") -> 0 | O7: =SUMIFS(Raw_Meta!$L$6:$L$28,Raw_Meta!$E$6:$E$28,B7,Raw_Meta!$N$6:$N$28,"Jul-25")+SUMIFS(Raw_Meta!$L$6:$L$28,Raw_Meta!$E$6:$E$28,B7,Raw_Meta!$N$6:$N$28,"Aug-25")+SUMIFS(Raw_Meta!$L$6:$L$28,Raw_Meta!$E$6:$E$28,B7,Raw_Meta!$N$6:$N$28,"Sep-25")+SUMIFS(Raw_Meta!$L$6:$L$28,Raw_Meta!$E$6:$E$28,B7,Raw_Meta!$N$6:$N$28,"Oct-25")+SUMIFS(Raw_Meta!$L$6:$L$28,Raw_Meta!$E$6:$E$28,B7,Raw_Meta!$N$6:$N$28,"Nov-25")+SUMIFS(Raw_Meta!$L$6:$L$28,Raw_Meta!$E$6:$E$28,B7,Raw_Meta!$N$6:$N$28,"Dec-25") -> 6800
B8: Emirates Retail Group | C8: =SUMIFS(Raw_Meta!$L$6:$L$28,Raw_Meta!$E$6:$E$28,B8) -> 7800 | D8: =IFERROR(SUMIFS(Raw_Meta!$L$6:$L$28,Raw_Meta!$E$6:$E$28,B8)*SUMIFS(Raw_Meta!$H$6:$H$28,Raw_Meta!$E$6:$E$28,B8)/SUMIFS(Raw_Meta!$G$6:$G$28,Raw_Meta!$E$6:$E$28,B8),0) -> 600 | E8: =C8-D8 -> 7200 | F8: =C8 -> 7800 | G8: =IFERROR(D8/C8,0) -> 0.076923077 | H8: =COUNTIFS(Raw_Meta!$E$6:$E$28,B8) -> 2 | I8: =SUMIFS(Raw_Meta!$L$6:$L$28,Raw_Meta!$E$6:$E$28,B8,Raw_Meta!$N$6:$N$28,"Jan-25") -> 3800 | J8: =SUMIFS(Raw_Meta!$L$6:$L$28,Raw_Meta!$E$6:$E$28,B8,Raw_Meta!$N$6:$N$28,"Feb-25") -> 4000 | K8: =SUMIFS(Raw_Meta!$L$6:$L$28,Raw_Meta!$E$6:$E$28,B8,Raw_Meta!$N$6:$N$28,"Mar-25") -> 0 | L8: =SUMIFS(Raw_Meta!$L$6:$L$28,Raw_Meta!$E$6:$E$28,B8,Raw_Meta!$N$6:$N$28,"Apr-25") -> 0 | M8: =SUMIFS(Raw_Meta!$L$6:$L$28,Raw_Meta!$E$6:$E$28,B8,Raw_Meta!$N$6:$N$28,"May-25") -> 0 | N8: =SUMIFS(Raw_Meta!$L$6:$L$28,Raw_Meta!$E$6:$E$28,B8,Raw_Meta!$N$6:$N$28,"Jun-25") -> 0 | O8: =SUMIFS(Raw_Meta!$L$6:$L$28,Raw_Meta!$E$6:$E$28,B8,Raw_Meta!$N$6:$N$28,"Jul-25")+SUMIFS(Raw_Meta!$L$6:$L$28,Raw_Meta!$E$6:$E$28,B8,Raw_Meta!$N$6:$N$28,"Aug-25")+SUMIFS(Raw_Meta!$L$6:$L$28,Raw_Meta!$E$6:$E$28,B8,Raw_Meta!$N$6:$N$28,"Sep-25")+SUMIFS(Raw_Meta!$L$6:$L$28,Raw_Meta!$E$6:$E$28,B8,Raw_Meta!$N$6:$N$28,"Oct-25")+SUMIFS(Raw_Meta!$L$6:$L$28,Raw_Meta!$E$6:$E$28,B8,Raw_Meta!$N$6:$N$28,"Nov-25")+SUMIFS(Raw_Meta!$L$6:$L$28,Raw_Meta!$E$6:$E$28,B8,Raw_Meta!$N$6:$N$28,"Dec-25") -> 0
B9: Gulf Tech Distribution | C9: =SUMIFS(Raw_Meta!$L$6:$L$28,Raw_Meta!$E$6:$E$28,B9) -> 20400 | D9: =IFERROR(SUMIFS(Raw_Meta!$L$6:$L$28,Raw_Meta!$E$6:$E$28,B9)*SUMIFS(Raw_Meta!$H$6:$H$28,Raw_Meta!$E$6:$E$28,B9)/SUMIFS(Raw_Meta!$G$6:$G$28,Raw_Meta!$E$6:$E$28,B9),0) -> 1650 | E9: =C9-D9 -> 18750 | F9: =C9 -> 20400 | G9: =IFERROR(D9/C9,0) -> 0.080882353 | H9: =COUNTIFS(Raw_Meta!$E$6:$E$28,B9) -> 3 | I9: =SUMIFS(Raw_Meta!$L$6:$L$28,Raw_Meta!$E$6:$E$28,B9,Raw_Meta!$N$6:$N$28,"Jan-25") -> 6500 | J9: =SUMIFS(Raw_Meta!$L$6:$L$28,Raw_Meta!$E$6:$E$28,B9,Raw_Meta!$N$6:$N$28,"Feb-25") -> 6800 | K9: =SUMIFS(Raw_Meta!$L$6:$L$28,Raw_Meta!$E$6:$E$28,B9,Raw_Meta!$N$6:$N$28,"Mar-25") -> 0 | L9: =SUMIFS(Raw_Meta!$L$6:$L$28,Raw_Meta!$E$6:$E$28,B9,Raw_Meta!$N$6:$N$28,"Apr-25") -> 0 | M9: =SUMIFS(Raw_Meta!$L$6:$L$28,Raw_Meta!$E$6:$E$28,B9,Raw_Meta!$N$6:$N$28,"May-25") -> 7100 | N9: =SUMIFS(Raw_Meta!$L$6:$L$28,Raw_Meta!$E$6:$E$28,B9,Raw_Meta!$N$6:$N$28,"Jun-25") -> 0 | O9: =SUMIFS(Raw_Meta!$L$6:$L$28,Raw_Meta!$E$6:$E$28,B9,Raw_Meta!$N$6:$N$28,"Jul-25")+SUMIFS(Raw_Meta!$L$6:$L$28,Raw_Meta!$E$6:$E$28,B9,Raw_Meta!$N$6:$N$28,"Aug-25")+SUMIFS(Raw_Meta!$L$6:$L$28,Raw_Meta!$E$6:$E$28,B9,Raw_Meta!$N$6:$N$28,"Sep-25")+SUMIFS(Raw_Meta!$L$6:$L$28,Raw_Meta!$E$6:$E$28,B9,Raw_Meta!$N$6:$N$28,"Oct-25")+SUMIFS(Raw_Meta!$L$6:$L$28,Raw_Meta!$E$6:$E$28,B9,Raw_Meta!$N$6:$N$28,"Nov-25")+SUMIFS(Raw_Meta!$L$6:$L$28,Raw_Meta!$E$6:$E$28,B9,Raw_Meta!$N$6:$N$28,"Dec-25") -> 0
B10: Singapore FinTech Hub | C10: =SUMIFS(Raw_Meta!$L$6:$L$28,Raw_Meta!$E$6:$E$28,B10) -> 8700 | D10: =IFERROR(SUMIFS(Raw_Meta!$L$6:$L$28,Raw_Meta!$E$6:$E$28,B10)*SUMIFS(Raw_Meta!$H$6:$H$28,Raw_Meta!$E$6:$E$28,B10)/SUMIFS(Raw_Meta!$G$6:$G$28,Raw_Meta!$E$6:$E$28,B10),0) -> 750 | E10: =C10-D10 -> 7950 | F10: =C10 -> 8700 | G10: =IFERROR(D10/C10,0) -> 0.086206897 | H10: =COUNTIFS(Raw_Meta!$E$6:$E$28,B10) -> 2 | I10: =SUMIFS(Raw_Meta!$L$6:$L$28,Raw_Meta!$E$6:$E$28,B10,Raw_Meta!$N$6:$N$28,"Jan-25") -> 4200 | J10: =SUMIFS(Raw_Meta!$L$6:$L$28,Raw_Meta!$E$6:$E$28,B10,Raw_Meta!$N$6:$N$28,"Feb-25") -> 0 | K10: =SUMIFS(Raw_Meta!$L$6:$L$28,Raw_Meta!$E$6:$E$28,B10,Raw_Meta!$N$6:$N$28,"Mar-25") -> 0 | L10: =SUMIFS(Raw_Meta!$L$6:$L$28,Raw_Meta!$E$6:$E$28,B10,Raw_Meta!$N$6:$N$28,"Apr-25") -> 0 | M10: =SUMIFS(Raw_Meta!$L$6:$L$28,Raw_Meta!$E$6:$E$28,B10,Raw_Meta!$N$6:$N$28,"May-25") -> 0 | N10: =SUMIFS(Raw_Meta!$L$6:$L$28,Raw_Meta!$E$6:$E$28,B10,Raw_Meta!$N$6:$N$28,"Jun-25") -> 0 | O10: =SUMIFS(Raw_Meta!$L$6:$L$28,Raw_Meta!$E$6:$E$28,B10,Raw_Meta!$N$6:$N$28,"Jul-25")+SUMIFS(Raw_Meta!$L$6:$L$28,Raw_Meta!$E$6:$E$28,B10,Raw_Meta!$N$6:$N$28,"Aug-25")+SUMIFS(Raw_Meta!$L$6:$L$28,Raw_Meta!$E$6:$E$28,B10,Raw_Meta!$N$6:$N$28,"Sep-25")+SUMIFS(Raw_Meta!$L$6:$L$28,Raw_Meta!$E$6:$E$28,B10,Raw_Meta!$N$6:$N$28,"Oct-25")+SUMIFS(Raw_Meta!$L$6:$L$28,Raw_Meta!$E$6:$E$28,B10,Raw_Meta!$N$6:$N$28,"Nov-25")+SUMIFS(Raw_Meta!$L$6:$L$28,Raw_Meta!$E$6:$E$28,B10,Raw_Meta!$N$6:$N$28,"Dec-25") -> 4500
B11: Abu Dhabi Trading | C11: =SUMIFS(Raw_Meta!$L$6:$L$28,Raw_Meta!$E$6:$E$28,B11) -> 4500 | D11: =IFERROR(SUMIFS(Raw_Meta!$L$6:$L$28,Raw_Meta!$E$6:$E$28,B11)*SUMIFS(Raw_Meta!$H$6:$H$28,Raw_Meta!$E$6:$E$28,B11)/SUMIFS(Raw_Meta!$G$6:$G$28,Raw_Meta!$E$6:$E$28,B11),0) -> 400 | E11: =C11-D11 -> 4100 | F11: =C11 -> 4500 | G11: =IFERROR(D11/C11,0) -> 0.088888889 | H11: =COUNTIFS(Raw_Meta!$E$6:$E$28,B11) -> 1 | I11: =SUMIFS(Raw_Meta!$L$6:$L$28,Raw_Meta!$E$6:$E$28,B11,Raw_Meta!$N$6:$N$28,"Jan-25") -> 0 | J11: =SUMIFS(Raw_Meta!$L$6:$L$28,Raw_Meta!$E$6:$E$28,B11,Raw_Meta!$N$6:$N$28,"Feb-25") -> 0 | K11: =SUMIFS(Raw_Meta!$L$6:$L$28,Raw_Meta!$E$6:$E$28,B11,Raw_Meta!$N$6:$N$28,"Mar-25") -> 4500 | L11: =SUMIFS(Raw_Meta!$L$6:$L$28,Raw_Meta!$E$6:$E$28,B11,Raw_Meta!$N$6:$N$28,"Apr-25") -> 0 | M11: =SUMIFS(Raw_Meta!$L$6:$L$28,Raw_Meta!$E$6:$E$28,B11,Raw_Meta!$N$6:$N$28,"May-25") -> 0 | N11: =SUMIFS(Raw_Meta!$L$6:$L$28,Raw_Meta!$E$6:$E$28,B11,Raw_Meta!$N$6:$N$28,"Jun-25") -> 0 | O11: =SUMIFS(Raw_Meta!$L$6:$L$28,Raw_Meta!$E$6:$E$28,B11,Raw_Meta!$N$6:$N$28,"Jul-25")+SUMIFS(Raw_Meta!$L$6:$L$28,Raw_Meta!$E$6:$E$28,B11,Raw_Meta!$N$6:$N$28,"Aug-25")+SUMIFS(Raw_Meta!$L$6:$L$28,Raw_Meta!$E$6:$E$28,B11,Raw_Meta!$N$6:$N$28,"Sep-25")+SUMIFS(Raw_Meta!$L$6:$L$28,Raw_Meta!$E$6:$E$28,B11,Raw_Meta!$N$6:$N$28,"Oct-25")+SUMIFS(Raw_Meta!$L$6:$L$28,Raw_Meta!$E$6:$E$28,B11,Raw_Meta!$N$6:$N$28,"Nov-25")+SUMIFS(Raw_Meta!$L$6:$L$28,Raw_Meta!$E$6:$E$28,B11,Raw_Meta!$N$6:$N$28,"Dec-25") -> 0
B12: Rak Bank Digital | C12: =SUMIFS(Raw_Meta!$L$6:$L$28,Raw_Meta!$E$6:$E$28,B12) -> 7200 | D12: =IFERROR(SUMIFS(Raw_Meta!$L$6:$L$28,Raw_Meta!$E$6:$E$28,B12)*SUMIFS(Raw_Meta!$H$6:$H$28,Raw_Meta!$E$6:$E$28,B12)/SUMIFS(Raw_Meta!$G$6:$G$28,Raw_Meta!$E$6:$E$28,B12),0) -> 600 | E12: =C12-D12 -> 6600 | F12: =C12 -> 7200 | G12: =IFERROR(D12/C12,0) -> 0.083333333 | H12: =COUNTIFS(Raw_Meta!$E$6:$E$28,B12) -> 1 | I12: =SUMIFS(Raw_Meta!$L$6:$L$28,Raw_Meta!$E$6:$E$28,B12,Raw_Meta!$N$6:$N$28,"Jan-25") -> 0 | J12: =SUMIFS(Raw_Meta!$L$6:$L$28,Raw_Meta!$E$6:$E$28,B12,Raw_Meta!$N$6:$N$28,"Feb-25") -> 0 | K12: =SUMIFS(Raw_Meta!$L$6:$L$28,Raw_Meta!$E$6:$E$28,B12,Raw_Meta!$N$6:$N$28,"Mar-25") -> 7200 | L12: =SUMIFS(Raw_Meta!$L$6:$L$28,Raw_Meta!$E$6:$E$28,B12,Raw_Meta!$N$6:$N$28,"Apr-25") -> 0 | M12: =SUMIFS(Raw_Meta!$L$6:$L$28,Raw_Meta!$E$6:$E$28,B12,Raw_Meta!$N$6:$N$28,"May-25") -> 0 | N12: =SUMIFS(Raw_Meta!$L$6:$L$28,Raw_Meta!$E$6:$E$28,B12,Raw_Meta!$N$6:$N$28,"Jun-25") -> 0 | O12: =SUMIFS(Raw_Meta!$L$6:$L$28,Raw_Meta!$E$6:$E$28,B12,Raw_Meta!$N$6:$N$28,"Jul-25")+SUMIFS(Raw_Meta!$L$6:$L$28,Raw_Meta!$E$6:$E$28,B12,Raw_Meta!$N$6:$N$28,"Aug-25")+SUMIFS(Raw_Meta!$L$6:$L$28,Raw_Meta!$E$6:$E$28,B12,Raw_Meta!$N$6:$N$28,"Sep-25")+SUMIFS(Raw_Meta!$L$6:$L$28,Raw_Meta!$E$6:$E$28,B12,Raw_Meta!$N$6:$N$28,"Oct-25")+SUMIFS(Raw_Meta!$L$6:$L$28,Raw_Meta!$E$6:$E$28,B12,Raw_Meta!$N$6:$N$28,"Nov-25")+SUMIFS(Raw_Meta!$L$6:$L$28,Raw_Meta!$E$6:$E$28,B12,Raw_Meta!$N$6:$N$28,"Dec-25") -> 0
B13: Asia Pacific Solutions | C13: =SUMIFS(Raw_Meta!$L$6:$L$28,Raw_Meta!$E$6:$E$28,B13) -> 8500 | D13: =IFERROR(SUMIFS(Raw_Meta!$L$6:$L$28,Raw_Meta!$E$6:$E$28,B13)*SUMIFS(Raw_Meta!$H$6:$H$28,Raw_Meta!$E$6:$E$28,B13)/SUMIFS(Raw_Meta!$G$6:$G$28,Raw_Meta!$E$6:$E$28,B13),0) -> 700 | E13: =C13-D13 -> 7800 | F13: =C13 -> 8500 | G13: =IFERROR(D13/C13,0) -> 0.082352941 | H13: =COUNTIFS(Raw_Meta!$E$6:$E$28,B13) -> 1 | I13: =SUMIFS(Raw_Meta!$L$6:$L$28,Raw_Meta!$E$6:$E$28,B13,Raw_Meta!$N$6:$N$28,"Jan-25") -> 0 | J13: =SUMIFS(Raw_Meta!$L$6:$L$28,Raw_Meta!$E$6:$E$28,B13,Raw_Meta!$N$6:$N$28,"Feb-25") -> 0 | K13: =SUMIFS(Raw_Meta!$L$6:$L$28,Raw_Meta!$E$6:$E$28,B13,Raw_Meta!$N$6:$N$28,"Mar-25") -> 8500 | L13: =SUMIFS(Raw_Meta!$L$6:$L$28,Raw_Meta!$E$6:$E$28,B13,Raw_Meta!$N$6:$N$28,"Apr-25") -> 0 | M13: =SUMIFS(Raw_Meta!$L$6:$L$28,Raw_Meta!$E$6:$E$28,B13,Raw_Meta!$N$6:$N$28,"May-25") -> 0 | N13: =SUMIFS(Raw_Meta!$L$6:$L$28,Raw_Meta!$E$6:$E$28,B13,Raw_Meta!$N$6:$N$28,"Jun-25") -> 0 | O13: =SUMIFS(Raw_Meta!$L$6:$L$28,Raw_Meta!$E$6:$E$28,B13,Raw_Meta!$N$6:$N$28,"Jul-25")+SUMIFS(Raw_Meta!$L$6:$L$28,Raw_Meta!$E$6:$E$28,B13,Raw_Meta!$N$6:$N$28,"Aug-25")+SUMIFS(Raw_Meta!$L$6:$L$28,Raw_Meta!$E$6:$E$28,B13,Raw_Meta!$N$6:$N$28,"Sep-25")+SUMIFS(Raw_Meta!$L$6:$L$28,Raw_Meta!$E$6:$E$28,B13,Raw_Meta!$N$6:$N$28,"Oct-25")+SUMIFS(Raw_Meta!$L$6:$L$28,Raw_Meta!$E$6:$E$28,B13,Raw_Meta!$N$6:$N$28,"Nov-25")+SUMIFS(Raw_Meta!$L$6:$L$28,Raw_Meta!$E$6:$E$28,B13,Raw_Meta!$N$6:$N$28,"Dec-25") -> 0
B14: Lion City Media | C14: =SUMIFS(Raw_Meta!$L$6:$L$28,Raw_Meta!$E$6:$E$28,B14) -> 4300 | D14: =IFERROR(SUMIFS(Raw_Meta!$L$6:$L$28,Raw_Meta!$E$6:$E$28,B14)*SUMIFS(Raw_Meta!$H$6:$H$28,Raw_Meta!$E$6:$E$28,B14)/SUMIFS(Raw_Meta!$G$6:$G$28,Raw_Meta!$E$6:$E$28,B14),0) -> 350 | E14: =C14-D14 -> 3950 | F14: =C14 -> 4300 | G14: =IFERROR(D14/C14,0) -> 0.081395349 | H14: =COUNTIFS(Raw_Meta!$E$6:$E$28,B14) -> 1 | I14: =SUMIFS(Raw_Meta!$L$6:$L$28,Raw_Meta!$E$6:$E$28,B14,Raw_Meta!$N$6:$N$28,"Jan-25") -> 0 | J14: =SUMIFS(Raw_Meta!$L$6:$L$28,Raw_Meta!$E$6:$E$28,B14,Raw_Meta!$N$6:$N$28,"Feb-25") -> 0 | K14: =SUMIFS(Raw_Meta!$L$6:$L$28,Raw_Meta!$E$6:$E$28,B14,Raw_Meta!$N$6:$N$28,"Mar-25") -> 4300 | L14: =SUMIFS(Raw_Meta!$L$6:$L$28,Raw_Meta!$E$6:$E$28,B14,Raw_Meta!$N$6:$N$28,"Apr-25") -> 0 | M14: =SUMIFS(Raw_Meta!$L$6:$L$28,Raw_Meta!$E$6:$E$28,B14,Raw_Meta!$N$6:$N$28,"May-25") -> 0 | N14: =SUMIFS(Raw_Meta!$L$6:$L$28,Raw_Meta!$E$6:$E$28,B14,Raw_Meta!$N$6:$N$28,"Jun-25") -> 0 | O14: =SUMIFS(Raw_Meta!$L$6:$L$28,Raw_Meta!$E$6:$E$28,B14,Raw_Meta!$N$6:$N$28,"Jul-25")+SUMIFS(Raw_Meta!$L$6:$L$28,Raw_Meta!$E$6:$E$28,B14,Raw_Meta!$N$6:$N$28,"Aug-25")+SUMIFS(Raw_Meta!$L$6:$L$28,Raw_Meta!$E$6:$E$28,B14,Raw_Meta!$N$6:$N$28,"Sep-25")+SUMIFS(Raw_Meta!$L$6:$L$28,Raw_Meta!$E$6:$E$28,B14,Raw_Meta!$N$6:$N$28,"Oct-25")+SUMIFS(Raw_Meta!$L$6:$L$28,Raw_Meta!$E$6:$E$28,B14,Raw_Meta!$N$6:$N$28,"Nov-25")+SUMIFS(Raw_Meta!$L$6:$L$28,Raw_Meta!$E$6:$E$28,B14,Raw_Meta!$N$6:$N$28,"Dec-25") -> 0
B15: Sentosa E-Commerce | C15: =SUMIFS(Raw_Meta!$L$6:$L$28,Raw_Meta!$E$6:$E$28,B15) -> 3200 | D15: =IFERROR(SUMIFS(Raw_Meta!$L$6:$L$28,Raw_Meta!$E$6:$E$28,B15)*SUMIFS(Raw_Meta!$H$6:$H$28,Raw_Meta!$E$6:$E$28,B15)/SUMIFS(Raw_Meta!$G$6:$G$28,Raw_Meta!$E$6:$E$28,B15),0) -> 250 | E15: =C15-D15 -> 2950 | F15: =C15 -> 3200 | G15: =IFERROR(D15/C15,0) -> 0.078125 | H15: =COUNTIFS(Raw_Meta!$E$6:$E$28,B15) -> 1 | I15: =SUMIFS(Raw_Meta!$L$6:$L$28,Raw_Meta!$E$6:$E$28,B15,Raw_Meta!$N$6:$N$28,"Jan-25") -> 0 | J15: =SUMIFS(Raw_Meta!$L$6:$L$28,Raw_Meta!$E$6:$E$28,B15,Raw_Meta!$N$6:$N$28,"Feb-25") -> 0 | K15: =SUMIFS(Raw_Meta!$L$6:$L$28,Raw_Meta!$E$6:$E$28,B15,Raw_Meta!$N$6:$N$28,"Mar-25") -> 0 | L15: =SUMIFS(Raw_Meta!$L$6:$L$28,Raw_Meta!$E$6:$E$28,B15,Raw_Meta!$N$6:$N$28,"Apr-25") -> 3200 | M15: =SUMIFS(Raw_Meta!$L$6:$L$28,Raw_Meta!$E$6:$E$28,B15,Raw_Meta!$N$6:$N$28,"May-25") -> 0 | N15: =SUMIFS(Raw_Meta!$L$6:$L$28,Raw_Meta!$E$6:$E$28,B15,Raw_Meta!$N$6:$N$28,"Jun-25") -> 0 | O15: =SUMIFS(Raw_Meta!$L$6:$L$28,Raw_Meta!$E$6:$E$28,B15,Raw_Meta!$N$6:$N$28,"Jul-25")+SUMIFS(Raw_Meta!$L$6:$L$28,Raw_Meta!$E$6:$E$28,B15,Raw_Meta!$N$6:$N$28,"Aug-25")+SUMIFS(Raw_Meta!$L$6:$L$28,Raw_Meta!$E$6:$E$28,B15,Raw_Meta!$N$6:$N$28,"Sep-25")+SUMIFS(Raw_Meta!$L$6:$L$28,Raw_Meta!$E$6:$E$28,B15,Raw_Meta!$N$6:$N$28,"Oct-25")+SUMIFS(Raw_Meta!$L$6:$L$28,Raw_Meta!$E$6:$E$28,B15,Raw_Meta!$N$6:$N$28,"Nov-25")+SUMIFS(Raw_Meta!$L$6:$L$28,Raw_Meta!$E$6:$E$28,B15,Raw_Meta!$N$6:$N$28,"Dec-25") -> 0
B16: Marina Bay Holdings | C16: =SUMIFS(Raw_Meta!$L$6:$L$28,Raw_Meta!$E$6:$E$28,B16) -> 3900 | D16: =IFERROR(SUMIFS(Raw_Meta!$L$6:$L$28,Raw_Meta!$E$6:$E$28,B16)*SUMIFS(Raw_Meta!$H$6:$H$28,Raw_Meta!$E$6:$E$28,B16)/SUMIFS(Raw_Meta!$G$6:$G$28,Raw_Meta!$E$6:$E$28,B16),0) -> 300 | E16: =C16-D16 -> 3600 | F16: =C16 -> 3900 | G16: =IFERROR(D16/C16,0) -> 0.076923077 | H16: =COUNTIFS(Raw_Meta!$E$6:$E$28,B16) -> 1 | I16: =SUMIFS(Raw_Meta!$L$6:$L$28,Raw_Meta!$E$6:$E$28,B16,Raw_Meta!$N$6:$N$28,"Jan-25") -> 0 | J16: =SUMIFS(Raw_Meta!$L$6:$L$28,Raw_Meta!$E$6:$E$28,B16,Raw_Meta!$N$6:$N$28,"Feb-25") -> 0 | K16: =SUMIFS(Raw_Meta!$L$6:$L$28,Raw_Meta!$E$6:$E$28,B16,Raw_Meta!$N$6:$N$28,"Mar-25") -> 0 | L16: =SUMIFS(Raw_Meta!$L$6:$L$28,Raw_Meta!$E$6:$E$28,B16,Raw_Meta!$N$6:$N$28,"Apr-25") -> 0 | M16: =SUMIFS(Raw_Meta!$L$6:$L$28,Raw_Meta!$E$6:$E$28,B16,Raw_Meta!$N$6:$N$28,"May-25") -> 3900 | N16: =SUMIFS(Raw_Meta!$L$6:$L$28,Raw_Meta!$E$6:$E$28,B16,Raw_Meta!$N$6:$N$28,"Jun-25") -> 0 | O16: =SUMIFS(Raw_Meta!$L$6:$L$28,Raw_Meta!$E$6:$E$28,B16,Raw_Meta!$N$6:$N$28,"Jul-25")+SUMIFS(Raw_Meta!$L$6:$L$28,Raw_Meta!$E$6:$E$28,B16,Raw_Meta!$N$6:$N$28,"Aug-25")+SUMIFS(Raw_Meta!$L$6:$L$28,Raw_Meta!$E$6:$E$28,B16,Raw_Meta!$N$6:$N$28,"Sep-25")+SUMIFS(Raw_Meta!$L$6:$L$28,Raw_Meta!$E$6:$E$28,B16,Raw_Meta!$N$6:$N$28,"Oct-25")+SUMIFS(Raw_Meta!$L$6:$L$28,Raw_Meta!$E$6:$E$28,B16,Raw_Meta!$N$6:$N$28,"Nov-25")+SUMIFS(Raw_Meta!$L$6:$L$28,Raw_Meta!$E$6:$E$28,B16,Raw_Meta!$N$6:$N$28,"Dec-25") -> 0
B17: Dubai Properties Co | C17: =SUMIFS(Raw_Meta!$L$6:$L$28,Raw_Meta!$E$6:$E$28,B17) -> 6600 | D17: =IFERROR(SUMIFS(Raw_Meta!$L$6:$L$28,Raw_Meta!$E$6:$E$28,B17)*SUMIFS(Raw_Meta!$H$6:$H$28,Raw_Meta!$E$6:$E$28,B17)/SUMIFS(Raw_Meta!$G$6:$G$28,Raw_Meta!$E$6:$E$28,B17),0) -> 700 | E17: =C17-D17 -> 5900 | F17: =C17 -> 6600 | G17: =IFERROR(D17/C17,0) -> 0.10606061 | H17: =COUNTIFS(Raw_Meta!$E$6:$E$28,B17) -> 1 | I17: =SUMIFS(Raw_Meta!$L$6:$L$28,Raw_Meta!$E$6:$E$28,B17,Raw_Meta!$N$6:$N$28,"Jan-25") -> 0 | J17: =SUMIFS(Raw_Meta!$L$6:$L$28,Raw_Meta!$E$6:$E$28,B17,Raw_Meta!$N$6:$N$28,"Feb-25") -> 0 | K17: =SUMIFS(Raw_Meta!$L$6:$L$28,Raw_Meta!$E$6:$E$28,B17,Raw_Meta!$N$6:$N$28,"Mar-25") -> 0 | L17: =SUMIFS(Raw_Meta!$L$6:$L$28,Raw_Meta!$E$6:$E$28,B17,Raw_Meta!$N$6:$N$28,"Apr-25") -> 0 | M17: =SUMIFS(Raw_Meta!$L$6:$L$28,Raw_Meta!$E$6:$E$28,B17,Raw_Meta!$N$6:$N$28,"May-25") -> 0 | N17: =SUMIFS(Raw_Meta!$L$6:$L$28,Raw_Meta!$E$6:$E$28,B17,Raw_Meta!$N$6:$N$28,"Jun-25") -> 6600 | O17: =SUMIFS(Raw_Meta!$L$6:$L$28,Raw_Meta!$E$6:$E$28,B17,Raw_Meta!$N$6:$N$28,"Jul-25")+SUMIFS(Raw_Meta!$L$6:$L$28,Raw_Meta!$E$6:$E$28,B17,Raw_Meta!$N$6:$N$28,"Aug-25")+SUMIFS(Raw_Meta!$L$6:$L$28,Raw_Meta!$E$6:$E$28,B17,Raw_Meta!$N$6:$N$28,"Sep-25")+SUMIFS(Raw_Meta!$L$6:$L$28,Raw_Meta!$E$6:$E$28,B17,Raw_Meta!$N$6:$N$28,"Oct-25")+SUMIFS(Raw_Meta!$L$6:$L$28,Raw_Meta!$E$6:$E$28,B17,Raw_Meta!$N$6:$N$28,"Nov-25")+SUMIFS(Raw_Meta!$L$6:$L$28,Raw_Meta!$E$6:$E$28,B17,Raw_Meta!$N$6:$N$28,"Dec-25") -> 0
B18: Mena Apps FZ-LLC | C18: =SUMIFS(Raw_Meta!$L$6:$L$28,Raw_Meta!$E$6:$E$28,B18) -> 5800 | D18: =IFERROR(SUMIFS(Raw_Meta!$L$6:$L$28,Raw_Meta!$E$6:$E$28,B18)*SUMIFS(Raw_Meta!$H$6:$H$28,Raw_Meta!$E$6:$E$28,B18)/SUMIFS(Raw_Meta!$G$6:$G$28,Raw_Meta!$E$6:$E$28,B18),0) -> 450 | E18: =C18-D18 -> 5350 | F18: =C18 -> 5800 | G18: =IFERROR(D18/C18,0) -> 0.077586207 | H18: =COUNTIFS(Raw_Meta!$E$6:$E$28,B18) -> 1 | I18: =SUMIFS(Raw_Meta!$L$6:$L$28,Raw_Meta!$E$6:$E$28,B18,Raw_Meta!$N$6:$N$28,"Jan-25") -> 0 | J18: =SUMIFS(Raw_Meta!$L$6:$L$28,Raw_Meta!$E$6:$E$28,B18,Raw_Meta!$N$6:$N$28,"Feb-25") -> 0 | K18: =SUMIFS(Raw_Meta!$L$6:$L$28,Raw_Meta!$E$6:$E$28,B18,Raw_Meta!$N$6:$N$28,"Mar-25") -> 0 | L18: =SUMIFS(Raw_Meta!$L$6:$L$28,Raw_Meta!$E$6:$E$28,B18,Raw_Meta!$N$6:$N$28,"Apr-25") -> 0 | M18: =SUMIFS(Raw_Meta!$L$6:$L$28,Raw_Meta!$E$6:$E$28,B18,Raw_Meta!$N$6:$N$28,"May-25") -> 0 | N18: =SUMIFS(Raw_Meta!$L$6:$L$28,Raw_Meta!$E$6:$E$28,B18,Raw_Meta!$N$6:$N$28,"Jun-25") -> 5800 | O18: =SUMIFS(Raw_Meta!$L$6:$L$28,Raw_Meta!$E$6:$E$28,B18,Raw_Meta!$N$6:$N$28,"Jul-25")+SUMIFS(Raw_Meta!$L$6:$L$28,Raw_Meta!$E$6:$E$28,B18,Raw_Meta!$N$6:$N$28,"Aug-25")+SUMIFS(Raw_Meta!$L$6:$L$28,Raw_Meta!$E$6:$E$28,B18,Raw_Meta!$N$6:$N$28,"Sep-25")+SUMIFS(Raw_Meta!$L$6:$L$28,Raw_Meta!$E$6:$E$28,B18,Raw_Meta!$N$6:$N$28,"Oct-25")+SUMIFS(Raw_Meta!$L$6:$L$28,Raw_Meta!$E$6:$E$28,B18,Raw_Meta!$N$6:$N$28,"Nov-25")+SUMIFS(Raw_Meta!$L$6:$L$28,Raw_Meta!$E$6:$E$28,B18,Raw_Meta!$N$6:$N$28,"Dec-25") -> 0
... B20: Jakarta Digital Ventures | C20: =SUMIFS(Raw_Meta!$L$6:$L$28,Raw_Meta!$E$6:$E$28,B20) -> 9800 | D20: =IFERROR(SUMIFS(Raw_Meta!$L$6:$L$28,Raw_Meta!$E$6:$E$28,B20)*SUMIFS(Raw_Meta!$H$6:$H$28,Raw_Meta!$E$6:$E$28,B20)/SUMIFS(Raw_Meta!$G$6:$G$28,Raw_Meta!$E$6:$E$28,B20),0) -> 800 | E20: =C20-D20 -> 9000 | F20: =C20 -> 9800 | G20: =IFERROR(D20/C20,0) -> 0.081632653 | H20: =COUNTIFS(Raw_Meta!$E$6:$E$28,B20) -> 1 | I20: =SUMIFS(Raw_Meta!$L$6:$L$28,Raw_Meta!$E$6:$E$28,B20,Raw_Meta!$N$6:$N$28,"Jan-25") -> 0 | J20: =SUMIFS(Raw_Meta!$L$6:$L$28,Raw_Meta!$E$6:$E$28,B20,Raw_Meta!$N$6:$N$28,"Feb-25") -> 0 | K20: =SUMIFS(Raw_Meta!$L$6:$L$28,Raw_Meta!$E$6:$E$28,B20,Raw_Meta!$N$6:$N$28,"Mar-25") -> 0 | L20: =SUMIFS(Raw_Meta!$L$6:$L$28,Raw_Meta!$E$6:$E$28,B20,Raw_Meta!$N$6:$N$28,"Apr-25") -> 0 | M20: =SUMIFS(Raw_Meta!$L$6:$L$28,Raw_Meta!$E$6:$E$28,B20,Raw_Meta!$N$6:$N$28,"May-25") -> 0 | N20: =SUMIFS(Raw_Meta!$L$6:$L$28,Raw_Meta!$E$6:$E$28,B20,Raw_Meta!$N$6:$N$28,"Jun-25") -> 0 | O20: =SUMIFS(Raw_Meta!$L$6:$L$28,Raw_Meta!$E$6:$E$28,B20,Raw_Meta!$N$6:$N$28,"Jul-25")+SUMIFS(Raw_Meta!$L$6:$L$28,Raw_Meta!$E$6:$E$28,B20,Raw_Meta!$N$6:$N$28,"Aug-25")+SUMIFS(Raw_Meta!$L$6:$L$28,Raw_Meta!$E$6:$E$28,B20,Raw_Meta!$N$6:$N$28,"Sep-25")+SUMIFS(Raw_Meta!$L$6:$L$28,Raw_Meta!$E$6:$E$28,B20,Raw_Meta!$N$6:$N$28,"Oct-25")+SUMIFS(Raw_Meta!$L$6:$L$28,Raw_Meta!$E$6:$E$28,B20,Raw_Meta!$N$6:$N$28,"Nov-25")+SUMIFS(Raw_Meta!$L$6:$L$28,Raw_Meta!$E$6:$E$28,B20,Raw_Meta!$N$6:$N$28,"Dec-25") -> 9800
B21: TOTAL | C21: =SUM(C7:C20) -> 133600 | D21: =SUM(D7:D20) -> 11650 | E21: =SUM(E7:E20) -> 121950 | F21: =SUM(F7:F20) -> 133600 | G21: =IFERROR(D21/C21,0) -> 0.087200599 | H21: =SUM(H7:H20) -> 23 | I21: =SUM(I7:I20) -> 19700 | J21: =SUM(J7:J20) -> 16300 | K21: =SUM(K7:K20) -> 30300 | L21: =SUM(L7:L20) -> 9300 | M21: =SUM(M7:M20) -> 17300 | N21: =SUM(N7:N20) -> 12400 | O21: =SUM(O7:O20) -> 28300
B24: MONTHLY META COST TREND (USD with add-back)
B25: Month | C25: Net Paid USD | D25: Discount USD | E25: AddBack USD
B26: Jan-25 | C26: =E26-D26 -> 18100 | D26: =IFERROR(SUMIFS(Raw_Meta!$L$6:$L$28,Raw_Meta!$N$6:$N$28,B26)*SUMIFS(Raw_Meta!$H$6:$H$28,Raw_Meta!$N$6:$N$28,B26)/SUMIFS(Raw_Meta!$G$6:$G$28,Raw_Meta!$N$6:$N$28,B26),0) -> 1600 | E26: =SUMIFS(Raw_Meta!$L$6:$L$28,Raw_Meta!$N$6:$N$28,B26) -> 19700
B27: Feb-25 | C27: =E27-D27 -> 14950 | D27: =IFERROR(SUMIFS(Raw_Meta!$L$6:$L$28,Raw_Meta!$N$6:$N$28,B27)*SUMIFS(Raw_Meta!$H$6:$H$28,Raw_Meta!$N$6:$N$28,B27)/SUMIFS(Raw_Meta!$G$6:$G$28,Raw_Meta!$N$6:$N$28,B27),0) -> 1350 | E27: =SUMIFS(Raw_Meta!$L$6:$L$28,Raw_Meta!$N$6:$N$28,B27) -> 16300
B28: Mar-25 | C28: =E28-D28 -> 27650 | D28: =IFERROR(SUMIFS(Raw_Meta!$L$6:$L$28,Raw_Meta!$N$6:$N$28,B28)*SUMIFS(Raw_Meta!$H$6:$H$28,Raw_Meta!$N$6:$N$28,B28)/SUMIFS(Raw_Meta!$G$6:$G$28,Raw_Meta!$N$6:$N$28,B28),0) -> 2650 | E28: =SUMIFS(Raw_Meta!$L$6:$L$28,Raw_Meta!$N$6:$N$28,B28) -> 30300
B29: Apr-25 | C29: =E29-D29 -> 8450 | D29: =IFERROR(SUMIFS(Raw_Meta!$L$6:$L$28,Raw_Meta!$N$6:$N$28,B29)*SUMIFS(Raw_Meta!$H$6:$H$28,Raw_Meta!$N$6:$N$28,B29)/SUMIFS(Raw_Meta!$G$6:$G$28,Raw_Meta!$N$6:$N$28,B29),0) -> 850 | E29: =SUMIFS(Raw_Meta!$L$6:$L$28,Raw_Meta!$N$6:$N$28,B29) -> 9300
B30: May-25 | C30: =E30-D30 -> 15750 | D30: =IFERROR(SUMIFS(Raw_Meta!$L$6:$L$28,Raw_Meta!$N$6:$N$28,B30)*SUMIFS(Raw_Meta!$H$6:$H$28,Raw_Meta!$N$6:$N$28,B30)/SUMIFS(Raw_Meta!$G$6:$G$28,Raw_Meta!$N$6:$N$28,B30),0) -> 1550 | E30: =SUMIFS(Raw_Meta!$L$6:$L$28,Raw_Meta!$N$6:$N$28,B30) -> 17300
B31: Jun-25 | C31: =E31-D31 -> 11250 | D31: =IFERROR(SUMIFS(Raw_Meta!$L$6:$L$28,Raw_Meta!$N$6:$N$28,B31)*SUMIFS(Raw_Meta!$H$6:$H$28,Raw_Meta!$N$6:$N$28,B31)/SUMIFS(Raw_Meta!$G$6:$G$28,Raw_Meta!$N$6:$N$28,B31),0) -> 1150 | E31: =SUMIFS(Raw_Meta!$L$6:$L$28,Raw_Meta!$N$6:$N$28,B31) -> 12400
B32: Jul-25 | C32: =E32-D32 -> 12700 | D32: =IFERROR(SUMIFS(Raw_Meta!$L$6:$L$28,Raw_Meta!$N$6:$N$28,B32)*SUMIFS(Raw_Meta!$H$6:$H$28,Raw_Meta!$N$6:$N$28,B32)/SUMIFS(Raw_Meta!$G$6:$G$28,Raw_Meta!$N$6:$N$28,B32),0) -> 1300 | E32: =SUMIFS(Raw_Meta!$L$6:$L$28,Raw_Meta!$N$6:$N$28,B32) -> 14000
B33: Aug-25 | C33: =E33-D33 -> 4100 | D33: =IFERROR(SUMIFS(Raw_Meta!$L$6:$L$28,Raw_Meta!$N$6:$N$28,B33)*SUMIFS(Raw_Meta!$H$6:$H$28,Raw_Meta!$N$6:$N$28,B33)/SUMIFS(Raw_Meta!$G$6:$G$28,Raw_Meta!$N$6:$N$28,B33),0) -> 400 | E33: =SUMIFS(Raw_Meta!$L$6:$L$28,Raw_Meta!$N$6:$N$28,B33) -> 4500
B34: Sep-25 | C34: =E34-D34 -> 9000 | D34: =IFERROR(SUMIFS(Raw_Meta!$L$6:$L$28,Raw_Meta!$N$6:$N$28,B34)*SUMIFS(Raw_Meta!$H$6:$H$28,Raw_Meta!$N$6:$N$28,B34)/SUMIFS(Raw_Meta!$G$6:$G$28,Raw_Meta!$N$6:$N$28,B34),0) -> 800 | E34: =SUMIFS(Raw_Meta!$L$6:$L$28,Raw_Meta!$N$6:$N$28,B34) -> 9800
B35: Oct-25 | C35: =E35-D35 -> 0 | D35: =IFERROR(SUMIFS(Raw_Meta!$L$6:$L$28,Raw_Meta!$N$6:$N$28,B35)*SUMIFS(Raw_Meta!$H$6:$H$28,Raw_Meta!$N$6:$N$28,B35)/SUMIFS(Raw_Meta!$G$6:$G$28,Raw_Meta!$N$6:$N$28,B35),0) -> 0 | E35: =SUMIFS(Raw_Meta!$L$6:$L$28,Raw_Meta!$N$6:$N$28,B35) -> 0
B36: Nov-25 | C36: =E36-D36 -> 0 | D36: =IFERROR(SUMIFS(Raw_Meta!$L$6:$L$28,Raw_Meta!$N$6:$N$28,B36)*SUMIFS(Raw_Meta!$H$6:$H$28,Raw_Meta!$N$6:$N$28,B36)/SUMIFS(Raw_Meta!$G$6:$G$28,Raw_Meta!$N$6:$N$28,B36),0) -> 0 | E36: =SUMIFS(Raw_Meta!$L$6:$L$28,Raw_Meta!$N$6:$N$28,B36) -> 0
B37: Dec-25 | C37: =E37-D37 -> 0 | D37: =IFERROR(SUMIFS(Raw_Meta!$L$6:$L$28,Raw_Meta!$N$6:$N$28,B37)*SUMIFS(Raw_Meta!$H$6:$H$28,Raw_Meta!$N$6:$N$28,B37)/SUMIFS(Raw_Meta!$G$6:$G$28,Raw_Meta!$N$6:$N$28,B37),0) -> 0 | E37: =SUMIFS(Raw_Meta!$L$6:$L$28,Raw_Meta!$N$6:$N$28,B37) -> 0
B38: YTD TOTAL | C38: =SUM(C26:C37) -> 121950 | D38: =SUM(D26:D37) -> 11650 | E38: =SUM(E26:E37) -> 133600
B41: META COST CHART (Net Paid vs Add-Back, monthly)

Sheet PnL_Statement
B2: P&L Statement · Monthly FY2025
B3: Revenue − Meta Costs − Stripe Fees − OpEx (Xero) − Bank Charges = Net Profit
B5: PROFIT & LOSS (USD equivalent)
B6: Line Item | C6: Jan-25 | D6: Feb-25 | E6: Mar-25 | F6: Apr-25 | G6: May-25 | H6: Jun-25 | I6: Jul-25 | J6: Aug-25 | K6: Sep-25 | L6: Oct-25 | M6: Nov-25 | N6: Dec-25 | O6: YTD Total | P6: % Rev
B7: WhatsApp Revenue | C7: =SUMIFS(Raw_Stripe!$H$6:$H$33,Raw_Stripe!$M$6:$M$33,"Jan-25",Raw_Stripe!$N$6:$N$33,"WhatsApp") -> 4202.01 | D7: =SUMIFS(Raw_Stripe!$H$6:$H$33,Raw_Stripe!$M$6:$M$33,"Feb-25",Raw_Stripe!$N$6:$N$33,"WhatsApp") -> 3825.85 | E7: =SUMIFS(Raw_Stripe!$H$6:$H$33,Raw_Stripe!$M$6:$M$33,"Mar-25",Raw_Stripe!$N$6:$N$33,"WhatsApp") -> 4625.64 | F7: =SUMIFS(Raw_Stripe!$H$6:$H$33,Raw_Stripe!$M$6:$M$33,"Apr-25",Raw_Stripe!$N$6:$N$33,"WhatsApp") -> 1279.81 | G7: =SUMIFS(Raw_Stripe!$H$6:$H$33,Raw_Stripe!$M$6:$M$33,"May-25",Raw_Stripe!$N$6:$N$33,"WhatsApp") -> 1334.27 | H7: =SUMIFS(Raw_Stripe!$H$6:$H$33,Raw_Stripe!$M$6:$M$33,"Jun-25",Raw_Stripe!$N$6:$N$33,"WhatsApp") -> 7061.03 | I7: =SUMIFS(Raw_Stripe!$H$6:$H$33,Raw_Stripe!$M$6:$M$33,"Jul-25",Raw_Stripe!$N$6:$N$33,"WhatsApp") -> 1415.96 | J7: =SUMIFS(Raw_Stripe!$H$6:$H$33,Raw_Stripe!$M$6:$M$33,"Aug-25",Raw_Stripe!$N$6:$N$33,"WhatsApp") -> 2831 | K7: =SUMIFS(Raw_Stripe!$H$6:$H$33,Raw_Stripe!$M$6:$M$33,"Sep-25",Raw_Stripe!$N$6:$N$33,"WhatsApp") -> 0 | L7: =SUMIFS(Raw_Stripe!$H$6:$H$33,Raw_Stripe!$M$6:$M$33,"Oct-25",Raw_Stripe!$N$6:$N$33,"WhatsApp") -> 0 | M7: =SUMIFS(Raw_Stripe!$H$6:$H$33,Raw_Stripe!$M$6:$M$33,"Nov-25",Raw_Stripe!$N$6:$N$33,"WhatsApp") -> 0 | N7: =SUMIFS(Raw_Stripe!$H$6:$H$33,Raw_Stripe!$M$6:$M$33,"Dec-25",Raw_Stripe!$N$6:$N$33,"WhatsApp") -> 0 | O7: =SUM(C7:N7) -> 26575.57 | P7: =IFERROR(O7/$O$10,0) -> 0.19575381
B8: Subscription Revenue | C8: =SUMIFS(Raw_Stripe!$H$6:$H$33,Raw_Stripe!$M$6:$M$33,"Jan-25",Raw_Stripe!$N$6:$N$33,"Subscription") -> 13782.45 | D8: =SUMIFS(Raw_Stripe!$H$6:$H$33,Raw_Stripe!$M$6:$M$33,"Feb-25",Raw_Stripe!$N$6:$N$33,"Subscription") -> 408.45 | E8: =SUMIFS(Raw_Stripe!$H$6:$H$33,Raw_Stripe!$M$6:$M$33,"Mar-25",Raw_Stripe!$N$6:$N$33,"Subscription") -> 408.45 | F8: =SUMIFS(Raw_Stripe!$H$6:$H$33,Raw_Stripe!$M$6:$M$33,"Apr-25",Raw_Stripe!$N$6:$N$33,"Subscription") -> 2608.45 | G8: =SUMIFS(Raw_Stripe!$H$6:$H$33,Raw_Stripe!$M$6:$M$33,"May-25",Raw_Stripe!$N$6:$N$33,"Subscription") -> 1339.2 | H8: =SUMIFS(Raw_Stripe!$H$6:$H$33,Raw_Stripe!$M$6:$M$33,"Jun-25",Raw_Stripe!$N$6:$N$33,"Subscription") -> 24000 | I8: =SUMIFS(Raw_Stripe!$H$6:$H$33,Raw_Stripe!$M$6:$M$33,"Jul-25",Raw_Stripe!$N$6:$N$33,"Subscription") -> 0 | J8: =SUMIFS(Raw_Stripe!$H$6:$H$33,Raw_Stripe!$M$6:$M$33,"Aug-25",Raw_Stripe!$N$6:$N$33,"Subscription") -> 0 | K8: =SUMIFS(Raw_Stripe!$H$6:$H$33,Raw_Stripe!$M$6:$M$33,"Sep-25",Raw_Stripe!$N$6:$N$33,"Subscription") -> 0 | L8: =SUMIFS(Raw_Stripe!$H$6:$H$33,Raw_Stripe!$M$6:$M$33,"Oct-25",Raw_Stripe!$N$6:$N$33,"Subscription") -> 0 | M8: =SUMIFS(Raw_Stripe!$H$6:$H$33,Raw_Stripe!$M$6:$M$33,"Nov-25",Raw_Stripe!$N$6:$N$33,"Subscription") -> 0 | N8: =SUMIFS(Raw_Stripe!$H$6:$H$33,Raw_Stripe!$M$6:$M$33,"Dec-25",Raw_Stripe!$N$6:$N$33,"Subscription") -> 0 | O8: =SUM(C8:N8) -> 42547 | P8: =IFERROR(O8/$O$10,0) -> 0.31339825
B9: Development Revenue | C9: =SUMIFS(Raw_Stripe!$H$6:$H$33,Raw_Stripe!$M$6:$M$33,"Jan-25",Raw_Stripe!$N$6:$N$33,"Development") -> 6800 | D9: =SUMIFS(Raw_Stripe!$H$6:$H$33,Raw_Stripe!$M$6:$M$33,"Feb-25",Raw_Stripe!$N$6:$N$33,"Development") -> 12000 | E9: =SUMIFS(Raw_Stripe!$H$6:$H$33,Raw_Stripe!$M$6:$M$33,"Mar-25",Raw_Stripe!$N$6:$N$33,"Development") -> 18086.85 | F9: =SUMIFS(Raw_Stripe!$H$6:$H$33,Raw_Stripe!$M$6:$M$33,"Apr-25",Raw_Stripe!$N$6:$N$33,"Development") -> 0 | G9: =SUMIFS(Raw_Stripe!$H$6:$H$33,Raw_Stripe!$M$6:$M$33,"May-25",Raw_Stripe!$N$6:$N$33,"Development") -> 8500 | H9: =SUMIFS(Raw_Stripe!$H$6:$H$33,Raw_Stripe!$M$6:$M$33,"Jun-25",Raw_Stripe!$N$6:$N$33,"Development") -> 0 | I9: =SUMIFS(Raw_Stripe!$H$6:$H$33,Raw_Stripe!$M$6:$M$33,"Jul-25",Raw_Stripe!$N$6:$N$33,"Development") -> 10050.75 | J9: =SUMIFS(Raw_Stripe!$H$6:$H$33,Raw_Stripe!$M$6:$M$33,"Aug-25",Raw_Stripe!$N$6:$N$33,"Development") -> 0 | K9: =SUMIFS(Raw_Stripe!$H$6:$H$33,Raw_Stripe!$M$6:$M$33,"Sep-25",Raw_Stripe!$N$6:$N$33,"Development") -> 11200 | L9: =SUMIFS(Raw_Stripe!$H$6:$H$33,Raw_Stripe!$M$6:$M$33,"Oct-25",Raw_Stripe!$N$6:$N$33,"Development") -> 0 | M9: =SUMIFS(Raw_Stripe!$H$6:$H$33,Raw_Stripe!$M$6:$M$33,"Nov-25",Raw_Stripe!$N$6:$N$33,"Development") -> 0 | N9: =SUMIFS(Raw_Stripe!$H$6:$H$33,Raw_Stripe!$M$6:$M$33,"Dec-25",Raw_Stripe!$N$6:$N$33,"Development") -> 0 | O9: =SUM(C9:N9) -> 66637.6 | P9: =IFERROR(O9/$O$10,0) -> 0.49084794
B10: TOTAL REVENUE | C10: =SUM(C7:C9) -> 24784.46 | D10: =SUM(D7:D9) -> 16234.3 | E10: =SUM(E7:E9) -> 23120.94 | F10: =SUM(F7:F9) -> 3888.26 | G10: =SUM(G7:G9) -> 11173.47 | H10: =SUM(H7:H9) -> 31061.03 | I10: =SUM(I7:I9) -> 11466.71 | J10: =SUM(J7:J9) -> 2831 | ... N10: =SUM(N7:N9) -> 0 | O10: =SUM(C10:N10) -> 135760.17 | P10: 1
B12: COST OF REVENUE
B13: Meta Cost (with add-back) | C13: =SUMIFS(Raw_Meta!$L$6:$L$28,Raw_Meta!$N$6:$N$28,"Jan-25") -> 19700 | D13: =SUMIFS(Raw_Meta!$L$6:$L$28,Raw_Meta!$N$6:$N$28,"Feb-25") -> 16300 | E13: =SUMIFS(Raw_Meta!$L$6:$L$28,Raw_Meta!$N$6:$N$28,"Mar-25") -> 30300 | F13: =SUMIFS(Raw_Meta!$L$6:$L$28,Raw_Meta!$N$6:$N$28,"Apr-25") -> 9300 | G13: =SUMIFS(Raw_Meta!$L$6:$L$28,Raw_Meta!$N$6:$N$28,"May-25") -> 17300 | H13: =SUMIFS(Raw_Meta!$L$6:$L$28,Raw_Meta!$N$6:$N$28,"Jun-25") -> 12400 | I13: =SUMIFS(Raw_Meta!$L$6:$L$28,Raw_Meta!$N$6:$N$28,"Jul-25") -> 14000 | J13: =SUMIFS(Raw_Meta!$L$6:$L$28,Raw_Meta!$N$6:$N$28,"Aug-25") -> 4500 | K13: =SUMIFS(Raw_Meta!$L$6:$L$28,Raw_Meta!$N$6:$N$28,"Sep-25") -> 9800 | L13: =SUMIFS(Raw_Meta!$L$6:$L$28,Raw_Meta!$N$6:$N$28,"Oct-25") -> 0 | M13: =SUMIFS(Raw_Meta!$L$6:$L$28,Raw_Meta!$N$6:$N$28,"Nov-25") -> 0 | N13: =SUMIFS(Raw_Meta!$L$6:$L$28,Raw_Meta!$N$6:$N$28,"Dec-25") -> 0 | O13: =SUM(C13:N13) -> 133600
B14: Total COGS | C14: =C13 -> 19700 | D14: =D13 -> 16300 | E14: =E13 -> 30300 | F14: =F13 -> 9300 | G14: =G13 -> 17300 | H14: =H13 -> 12400 | I14: =I13 -> 14000 | J14: =J13 -> 4500 | ... N14: =N13 -> 0 | O14: =SUM(C14:N14) -> 133600 | P14: =IFERROR(O14/$O$10,0) -> 0.98408834
B15: GROSS PROFIT | C15: =C10-C14 -> 5084.46 | D15: =D10-D14 -> -65.7 | E15: =E10-E14 -> -7179.06 | F15: =F10-F14 -> -5411.74 | G15: =G10-G14 -> -6126.53 | H15: =H10-H14 -> 18661.03 | I15: =I10-I14 -> -2533.29 | J15: =J10-J14 -> -1669 | ... N15: =N10-N14 -> 0 | O15: =SUM(C15:N15) -> 2160.17 | P15: =IFERROR(O15/$O$10,0) -> 0.015911662
B17: OPERATING EXPENSES
B18: Stripe Processing Fees | C18: =SUMIFS(Raw_Stripe!$I$6:$I$33,Raw_Stripe!$M$6:$M$33,"Jan-25") -> 1088.4 | D18: =SUMIFS(Raw_Stripe!$I$6:$I$33,Raw_Stripe!$M$6:$M$33,"Feb-25") -> 639.8 | E18: =SUMIFS(Raw_Stripe!$I$6:$I$33,Raw_Stripe!$M$6:$M$33,"Mar-25") -> 1094.8 | F18: =SUMIFS(Raw_Stripe!$I$6:$I$33,Raw_Stripe!$M$6:$M$33,"Apr-25") -> 256.1 | G18: =SUMIFS(Raw_Stripe!$I$6:$I$33,Raw_Stripe!$M$6:$M$33,"May-25") -> 453 | H18: =SUMIFS(Raw_Stripe!$I$6:$I$33,Raw_Stripe!$M$6:$M$33,"Jun-25") -> 1042.2 | I18: =SUMIFS(Raw_Stripe!$I$6:$I$33,Raw_Stripe!$M$6:$M$33,"Jul-25") -> 568.3 | J18: =SUMIFS(Raw_Stripe!$I$6:$I$33,Raw_Stripe!$M$6:$M$33,"Aug-25") -> 114.5 | K18: =SUMIFS(Raw_Stripe!$I$6:$I$33,Raw_Stripe!$M$6:$M$33,"Sep-25") -> 325.2 | L18: =SUMIFS(Raw_Stripe!$I$6:$I$33,Raw_Stripe!$M$6:$M$33,"Oct-25") -> 0 | M18: =SUMIFS(Raw_Stripe!$I$6:$I$33,Raw_Stripe!$M$6:$M$33,"Nov-25") -> 0 | N18: =SUMIFS(Raw_Stripe!$I$6:$I$33,Raw_Stripe!$M$6:$M$33,"Dec-25") -> 0 | O18: =SUM(C18:N18) -> 5582.3 | P18: =IFERROR(O18/$O$10,0) -> 0.041118835
B19: Bank Charges | C19: =SUMIFS(Raw_Bank!$H$6:$H$26,Raw_Bank!$J$6:$J$26,"Jan-25",Raw_Bank!$E$6:$E$26,">0") -> -53.235 | D19: =SUMIFS(Raw_Bank!$H$6:$H$26,Raw_Bank!$J$6:$J$26,"Feb-25",Raw_Bank!$E$6:$E$26,">0") -> -27.23 | E19: =SUMIFS(Raw_Bank!$H$6:$H$26,Raw_Bank!$J$6:$J$26,"Mar-25",Raw_Bank!$E$6:$E$26,">0") -> -27.23 | F19: =SUMIFS(Raw_Bank!$H$6:$H$26,Raw_Bank!$J$6:$J$26,"Apr-25",Raw_Bank!$E$6:$E$26,">0") -> -27.23 | G19: =SUMIFS(Raw_Bank!$H$6:$H$26,Raw_Bank!$J$6:$J$26,"May-25",Raw_Bank!$E$6:$E$26,">0") -> 0 | H19: =SUMIFS(Raw_Bank!$H$6:$H$26,Raw_Bank!$J$6:$J$26,"Jun-25",Raw_Bank!$E$6:$E$26,">0") -> -27.23 | I19: =SUMIFS(Raw_Bank!$H$6:$H$26,Raw_Bank!$J$6:$J$26,"Jul-25",Raw_Bank!$E$6:$E$26,">0") -> 0 | J19: =SUMIFS(Raw_Bank!$H$6:$H$26,Raw_Bank!$J$6:$J$26,"Aug-25",Raw_Bank!$E$6:$E$26,">0") -> 0 | K19: =SUMIFS(Raw_Bank!$H$6:$H$26,Raw_Bank!$J$6:$J$26,"Sep-25",Raw_Bank!$E$6:$E$26,">0") -> -27.23 | L19: =SUMIFS(Raw_Bank!$H$6:$H$26,Raw_Bank!$J$6:$J$26,"Oct-25",Raw_Bank!$E$6:$E$26,">0") -> 0 | M19: =SUMIFS(Raw_Bank!$H$6:$H$26,Raw_Bank!$J$6:$J$26,"Nov-25",Raw_Bank!$E$6:$E$26,">0") -> 0 | N19: =SUMIFS(Raw_Bank!$H$6:$H$26,Raw_Bank!$J$6:$J$26,"Dec-25",Raw_Bank!$E$6:$E$26,">0") -> 0 | O19: =SUM(C19:N19) -> -189.385 | P19: =IFERROR(O19/$O$10,0) -> -0.0013949968
B20: Salaries & Wages | C20: =SUMIFS(Raw_Xero!$I$6:$I$30,Raw_Xero!$K$6:$K$30,"Jan-25",Raw_Xero!$C$6:$C$30,"5000") -> 28599.5 | D20: =SUMIFS(Raw_Xero!$I$6:$I$30,Raw_Xero!$K$6:$K$30,"Feb-25",Raw_Xero!$C$6:$C$30,"5000") -> 29887.1 | E20: =SUMIFS(Raw_Xero!$I$6:$I$30,Raw_Xero!$K$6:$K$30,"Mar-25",Raw_Xero!$C$6:$C$30,"5000") -> 31447 | F20: =SUMIFS(Raw_Xero!$I$6:$I$30,Raw_Xero!$K$6:$K$30,"Apr-25",Raw_Xero!$C$6:$C$30,"5000") -> 32747.1 | G20: =SUMIFS(Raw_Xero!$I$6:$I$30,Raw_Xero!$K$6:$K$30,"May-25",Raw_Xero!$C$6:$C$30,"5000") -> 14976.5 | H20: =SUMIFS(Raw_Xero!$I$6:$I$30,Raw_Xero!$K$6:$K$30,"Jun-25",Raw_Xero!$C$6:$C$30,"5000") -> 15793.4 | I20: =SUMIFS(Raw_Xero!$I$6:$I$30,Raw_Xero!$K$6:$K$30,"Jul-25",Raw_Xero!$C$6:$C$30,"5000") -> 16882.6 | J20: =SUMIFS(Raw_Xero!$I$6:$I$30,Raw_Xero!$K$6:$K$30,"Aug-25",Raw_Xero!$C$6:$C$30,"5000") -> 0 | K20: =SUMIFS(Raw_Xero!$I$6:$I$30,Raw_Xero!$K$6:$K$30,"Sep-25",Raw_Xero!$C$6:$C$30,"5000") -> 0 | L20: =SUMIFS(Raw_Xero!$I$6:$I$30,Raw_Xero!$K$6:$K$30,"Oct-25",Raw_Xero!$C$6:$C$30,"5000") -> 0 | M20: =SUMIFS(Raw_Xero!$I$6:$I$30,Raw_Xero!$K$6:$K$30,"Nov-25",Raw_Xero!$C$6:$C$30,"5000") -> 0 | N20: =SUMIFS(Raw_Xero!$I$6:$I$30,Raw_Xero!$K$6:$K$30,"Dec-25",Raw_Xero!$C$6:$C$30,"5000") -> 0 | O20: =SUM(C20:N20) -> 170333.2 | P20: =IFERROR(O20/$O$10,0) -> 1.2546625
