Workbook

Sheet README
B2: Stripe × Xero Financial Dashboard
B3: FY2025 · Multi-currency · Live formulas · Meta discount add-back
B6: PURPOSE
B7: This workbook consolidates financial data from Stripe, Xero, Bank statements, and Meta (Facebook/WhatsApp) invoices into a single live-formula dashboard. It tracks revenue across WhatsApp, Subscription, and Development streams; monitors receivables for UAE and Singapore entities; and applies a special Meta discount add-back logic so each customer shows a single net Meta cost. Every derived number is a live Excel formula — paste raw rows into the input sheets and every dashboard, KPI, and chart updates automatically.
B13: DATA FLOW
B15: ① PASTE | C15: Raw_Stripe, Raw_Xero, Raw_Bank, Raw_Meta | D15: Drop your exports / CSV rows into these four input sheets.
B17: ② CONFIG | C17: Settings_FX | D17: Edit FX rates monthly, maintain customer master, set company names.
B19: ③ CALCULATE | C19: Revenue_Dashboard, Meta_Expenses, PnL_Statement | D19: Live SUMIFS formulas aggregate raw rows by month, category, customer.
B21: ④ MONITOR | C21: Receivables_Aging | D21: A/R aging by customer across UAE & Singapore entities.
B23: ⑤ REVIEW | C23: Executive_Summary | D23: KPI cards + trend charts for the leadership view.
B25: ⑥ AUDIT | C25: Formula_Audit | D25: Every key formula listed with its description for transparency.
B28: META DISCOUNT ADD-BACK LOGIC
B29: Meta invoices typically show: • Gross Billed (list price) • Discount Given (credit applied by Meta) • Net Paid (amount actually charged to your card = Gross − Discount) Add-Back Formula: Amount_With_AddBack = Net_Paid + Discount_Given This reverses the discount so the dashboard shows the full gross charge per customer — useful for cost-pass-through billing and customer profitability analysis where the discount is yours, not your customer's.
B35: MULTI-CURRENCY HANDLING
B36: Each raw transaction keeps its NATIVE currency (USD, AED, SGD, EUR). A USD-equivalent column on every raw sheet converts via the monthly FX rate table in Settings_FX using: Amount_USD = Amount × FX_Rate(month, currency). Update the FX rate table once per month — every downstream USD total refreshes automatically. Native-currency subtotals are preserved on each dashboard for entity-level reporting (UAE books in AED, Singapore books in SGD).
B42: SHEET DIRECTORY
B44: Settings_FX | C44: FX rates, customer master, company config, category map
B45: Raw_Stripe | C45: Stripe transaction paste-zone (with Void/Draft/Unsent statuses)
B46: Raw_Xero | C46: Xero journal paste-zone (P&L opex)
B47: Raw_Xero_Invoices | C47: Xero customer invoice paste-zone (with Void/Draft/Unsent/AwaitPay)
B48: Raw_Bank | C48: Bank statement paste-zone
B49: Raw_Meta | C49: Meta invoice paste-zone (with discount add-back)
B50: Revenue_Dashboard | C50: Revenue by 4 categories × month + bar + pie charts
B51: Receivables_Aging | C51: A/R aging by customer (UAE & SG) — 0-30/31-60/60+ buckets
B52: Customer_Receivables | C52: ★ Per-customer invoice status breakdown — Xero + Stripe
B53: Meta_Expenses | C53: Meta cost per customer with add-back
B54: PnL_Statement | C54: Monthly P&L — 4 revenue categories − Meta − OpEx
B55: Executive_Summary | C55: KPI cards + trend charts
B56: Formula_Audit | C56: Every key formula documented

Sheet Executive_Summary
B2: Executive Summary · FY2025 YTD
B3: Stripe × Xero consolidated financial snapshot — live from Raw sheets
B5: TOTAL REVENUE YTD | E5: TOTAL EXPENSES YTD | H5: NET PROFIT YTD | K5: GROSS MARGIN YTD
B6: =PnL_Statement!O11 -> 218895.77 | E6: =PnL_Statement!O15+PnL_Statement!O24 -> 359508.91 | H6: =PnL_Statement!O26 -> -140613.14 | K6: =PnL_Statement!P16 -> 0.38966386
B9: NET PROFIT MARGIN | E9: A/R OUTSTANDING (USD) | H9: META COST YTD (ADD-BACK) | K9: META DISCOUNTS CAPTURED
B10: =PnL_Statement!P26 -> -0.64237488 | E10: =SUM(Raw_Stripe!L6:L49) -> 72647.4 | H10: =SUM(Raw_Meta!L6:L28) -> 133600 | K10: =SUMPRODUCT(Raw_Meta!H6:H28,Raw_Meta!G6:G28)/SUMIF(Raw_Meta!G6:G28,">0",Raw_Meta!G6:G28)*SUM(Raw_Meta!H6:H28) -> 6355179.6
B13: MONTHLY SNAPSHOT
B14: Month | C14: Revenue | D14: Meta Cost | E14: OpEx | F14: Net Profit | G14: Margin %
B15: Jan-25 | C15: =PnL_Statement!C11 -> 25737.51 | D15: =PnL_Statement!C15 -> 19700 | E15: =PnL_Statement!C24 -> 39635.515 | F15: =PnL_Statement!C26 -> -33598.005 | G15: =IFERROR(F15/C15,0) -> -1.3054101
B16: Feb-25 | C16: =PnL_Statement!D11 -> 23034.3 | D16: =PnL_Statement!D15 -> 16300 | E16: =PnL_Statement!D24 -> 40616.45 | F16: =PnL_Statement!D26 -> -33882.15 | G16: =IFERROR(F16/C16,0) -> -1.4709433
B17: Mar-25 | C17: =PnL_Statement!E11 -> 26464.44 | D17: =PnL_Statement!E15 -> 30300 | E17: =PnL_Statement!E24 -> 42515.19 | F17: =PnL_Statement!E26 -> -46350.75 | G17: =IFERROR(F17/C17,0) -> -1.7514351
B18: Apr-25 | C18: =PnL_Statement!F11 -> 13088.26 | D18: =PnL_Statement!F15 -> 9300 | E18: =PnL_Statement!F24 -> 42458.97 | F18: =PnL_Statement!F26 -> -38670.71 | G18: =IFERROR(F18/C18,0) -> -2.9546105
B19: May-25 | C19: =PnL_Statement!G11 -> 12589.43 | D19: =PnL_Statement!G15 -> 17300 | E19: =PnL_Statement!G24 -> 18858.3 | F19: =PnL_Statement!G26 -> -23568.87 | G19: =IFERROR(F19/C19,0) -> -1.8721157
B20: Jun-25 | C20: =PnL_Statement!H11 -> 33888.23 | D20: =PnL_Statement!H15 -> 12400 | E20: =PnL_Statement!H24 -> 20190.47 | F20: =PnL_Statement!H26 -> 1297.76 | G20: =IFERROR(F20/C20,0) -> 0.038295302
B21: Jul-25 | C21: =PnL_Statement!I11 -> 12773.75 | D21: =PnL_Statement!I15 -> 14000 | E21: =PnL_Statement!I24 -> 21003.45 | F21: =PnL_Statement!I26 -> -22229.7 | G21: =IFERROR(F21/C21,0) -> -1.7402642
B22: Aug-25 | C22: =PnL_Statement!J11 -> 10331 | D22: =PnL_Statement!J15 -> 4500 | E22: =PnL_Statement!J24 -> 332.6 | F22: =PnL_Statement!J26 -> 5498.4 | G22: =IFERROR(F22/C22,0) -> 0.53222341
B23: Sep-25 | C23: =PnL_Statement!K11 -> 13051.64 | D23: =PnL_Statement!K15 -> 9800 | E23: =PnL_Statement!K24 -> 297.97 | F23: =PnL_Statement!K26 -> 2953.67 | G23: =IFERROR(F23/C23,0) -> 0.22630643
B24: Oct-25 | C24: =PnL_Statement!L11 -> 26314.55 | D24: =PnL_Statement!L15 -> 0 | E24: =PnL_Statement!L24 -> 0 | F24: =PnL_Statement!L26 -> 26314.55 | G24: =IFERROR(F24/C24,0) -> 1
B25: Nov-25 | C25: =PnL_Statement!M11 -> 10979 | D25: =PnL_Statement!M15 -> 0 | E25: =PnL_Statement!M24 -> 0 | F25: =PnL_Statement!M26 -> 10979 | G25: =IFERROR(F25/C25,0) -> 1
B26: Dec-25 | C26: =PnL_Statement!N11 -> 10643.66 | D26: =PnL_Statement!N15 -> 0 | E26: =PnL_Statement!N24 -> 0 | F26: =PnL_Statement!N26 -> 10643.66 | G26: =IFERROR(F26/C26,0) -> 1
B27: YTD TOTAL | C27: =SUM(C15:C26) -> 218895.77 | D27: =SUM(D15:D26) -> 133600 | E27: =SUM(E15:E26) -> 225908.92 | F27: =SUM(F15:F26) -> -140613.14 | G27: =IFERROR(F27/C27,0) -> -0.64237488
B30: REVENUE vs EXPENSES TREND
B54: NET PROFIT BY MONTH

Sheet Revenue_Dashboard
B2: Revenue Dashboard · FY2025
B3: Live SUMIFS by category × month — auto-updates from Raw_Stripe
B5: REVENUE BY CATEGORY × MONTH (USD equivalent)
B6: Category | C6: Jan-25 | D6: Feb-25 | E6: Mar-25 | F6: Apr-25 | G6: May-25 | H6: Jun-25 | I6: Jul-25 | J6: Aug-25 | K6: Sep-25 | L6: Oct-25 | M6: Nov-25 | N6: Dec-25 | O6: YTD Total
B7: WhatsApp | C7: =SUMIFS(Raw_Stripe!$H$6:$H$49,Raw_Stripe!$M$6:$M$49,"Jan-25",Raw_Stripe!$N$6:$N$49,"WhatsApp") -> 4202.01 | D7: =SUMIFS(Raw_Stripe!$H$6:$H$49,Raw_Stripe!$M$6:$M$49,"Feb-25",Raw_Stripe!$N$6:$N$49,"WhatsApp") -> 3825.85 | E7: =SUMIFS(Raw_Stripe!$H$6:$H$49,Raw_Stripe!$M$6:$M$49,"Mar-25",Raw_Stripe!$N$6:$N$49,"WhatsApp") -> 4625.64 | F7: =SUMIFS(Raw_Stripe!$H$6:$H$49,Raw_Stripe!$M$6:$M$49,"Apr-25",Raw_Stripe!$N$6:$N$49,"WhatsApp") -> 1279.81 | G7: =SUMIFS(Raw_Stripe!$H$6:$H$49,Raw_Stripe!$M$6:$M$49,"May-25",Raw_Stripe!$N$6:$N$49,"WhatsApp") -> 1334.27 | H7: =SUMIFS(Raw_Stripe!$H$6:$H$49,Raw_Stripe!$M$6:$M$49,"Jun-25",Raw_Stripe!$N$6:$N$49,"WhatsApp") -> 7061.03 | I7: =SUMIFS(Raw_Stripe!$H$6:$H$49,Raw_Stripe!$M$6:$M$49,"Jul-25",Raw_Stripe!$N$6:$N$49,"WhatsApp") -> 1415.96 | J7: =SUMIFS(Raw_Stripe!$H$6:$H$49,Raw_Stripe!$M$6:$M$49,"Aug-25",Raw_Stripe!$N$6:$N$49,"WhatsApp") -> 2831 | K7: =SUMIFS(Raw_Stripe!$H$6:$H$49,Raw_Stripe!$M$6:$M$49,"Sep-25",Raw_Stripe!$N$6:$N$49,"WhatsApp") -> 1851.64 | L7: =SUMIFS(Raw_Stripe!$H$6:$H$49,Raw_Stripe!$M$6:$M$49,"Oct-25",Raw_Stripe!$N$6:$N$49,"WhatsApp") -> 0 | M7: =SUMIFS(Raw_Stripe!$H$6:$H$49,Raw_Stripe!$M$6:$M$49,"Nov-25",Raw_Stripe!$N$6:$N$49,"WhatsApp") -> 3135.3 | N7: =SUMIFS(Raw_Stripe!$H$6:$H$49,Raw_Stripe!$M$6:$M$49,"Dec-25",Raw_Stripe!$N$6:$N$49,"WhatsApp") -> 0 | O7: =SUM(C7:N7) -> 31562.51
B8: Subscription | C8: =SUMIFS(Raw_Stripe!$H$6:$H$49,Raw_Stripe!$M$6:$M$49,"Jan-25",Raw_Stripe!$N$6:$N$49,"Subscription") -> 13782.45 | D8: =SUMIFS(Raw_Stripe!$H$6:$H$49,Raw_Stripe!$M$6:$M$49,"Feb-25",Raw_Stripe!$N$6:$N$49,"Subscription") -> 408.45 | E8: =SUMIFS(Raw_Stripe!$H$6:$H$49,Raw_Stripe!$M$6:$M$49,"Mar-25",Raw_Stripe!$N$6:$N$49,"Subscription") -> 408.45 | F8: =SUMIFS(Raw_Stripe!$H$6:$H$49,Raw_Stripe!$M$6:$M$49,"Apr-25",Raw_Stripe!$N$6:$N$49,"Subscription") -> 2608.45 | G8: =SUMIFS(Raw_Stripe!$H$6:$H$49,Raw_Stripe!$M$6:$M$49,"May-25",Raw_Stripe!$N$6:$N$49,"Subscription") -> 1339.2 | H8: =SUMIFS(Raw_Stripe!$H$6:$H$49,Raw_Stripe!$M$6:$M$49,"Jun-25",Raw_Stripe!$N$6:$N$49,"Subscription") -> 24000 | I8: =SUMIFS(Raw_Stripe!$H$6:$H$49,Raw_Stripe!$M$6:$M$49,"Jul-25",Raw_Stripe!$N$6:$N$49,"Subscription") -> 0 | J8: =SUMIFS(Raw_Stripe!$H$6:$H$49,Raw_Stripe!$M$6:$M$49,"Aug-25",Raw_Stripe!$N$6:$N$49,"Subscription") -> 0 | K8: =SUMIFS(Raw_Stripe!$H$6:$H$49,Raw_Stripe!$M$6:$M$49,"Sep-25",Raw_Stripe!$N$6:$N$49,"Subscription") -> 0 | L8: =SUMIFS(Raw_Stripe!$H$6:$H$49,Raw_Stripe!$M$6:$M$49,"Oct-25",Raw_Stripe!$N$6:$N$49,"Subscription") -> 24000 | M8: =SUMIFS(Raw_Stripe!$H$6:$H$49,Raw_Stripe!$M$6:$M$49,"Nov-25",Raw_Stripe!$N$6:$N$49,"Subscription") -> 1343.7 | N8: =SUMIFS(Raw_Stripe!$H$6:$H$49,Raw_Stripe!$M$6:$M$49,"Dec-25",Raw_Stripe!$N$6:$N$49,"Subscription") -> 0 | O8: =SUM(C8:N8) -> 67890.7
B9: Development | C9: =SUMIFS(Raw_Stripe!$H$6:$H$49,Raw_Stripe!$M$6:$M$49,"Jan-25",Raw_Stripe!$N$6:$N$49,"Development") -> 6800 | D9: =SUMIFS(Raw_Stripe!$H$6:$H$49,Raw_Stripe!$M$6:$M$49,"Feb-25",Raw_Stripe!$N$6:$N$49,"Development") -> 12000 | E9: =SUMIFS(Raw_Stripe!$H$6:$H$49,Raw_Stripe!$M$6:$M$49,"Mar-25",Raw_Stripe!$N$6:$N$49,"Development") -> 18086.85 | F9: =SUMIFS(Raw_Stripe!$H$6:$H$49,Raw_Stripe!$M$6:$M$49,"Apr-25",Raw_Stripe!$N$6:$N$49,"Development") -> 0 | G9: =SUMIFS(Raw_Stripe!$H$6:$H$49,Raw_Stripe!$M$6:$M$49,"May-25",Raw_Stripe!$N$6:$N$49,"Development") -> 8500 | H9: =SUMIFS(Raw_Stripe!$H$6:$H$49,Raw_Stripe!$M$6:$M$49,"Jun-25",Raw_Stripe!$N$6:$N$49,"Development") -> 0 | I9: =SUMIFS(Raw_Stripe!$H$6:$H$49,Raw_Stripe!$M$6:$M$49,"Jul-25",Raw_Stripe!$N$6:$N$49,"Development") -> 10050.75 | J9: =SUMIFS(Raw_Stripe!$H$6:$H$49,Raw_Stripe!$M$6:$M$49,"Aug-25",Raw_Stripe!$N$6:$N$49,"Development") -> 0 | K9: =SUMIFS(Raw_Stripe!$H$6:$H$49,Raw_Stripe!$M$6:$M$49,"Sep-25",Raw_Stripe!$N$6:$N$49,"Development") -> 11200 | L9: =SUMIFS(Raw_Stripe!$H$6:$H$49,Raw_Stripe!$M$6:$M$49,"Oct-25",Raw_Stripe!$N$6:$N$49,"Development") -> 2314.55 | M9: =SUMIFS(Raw_Stripe!$H$6:$H$49,Raw_Stripe!$M$6:$M$49,"Nov-25",Raw_Stripe!$N$6:$N$49,"Development") -> 0 | N9: =SUMIFS(Raw_Stripe!$H$6:$H$49,Raw_Stripe!$M$6:$M$49,"Dec-25",Raw_Stripe!$N$6:$N$49,"Development") -> 9500 | O9: =SUM(C9:N9) -> 78452.15
B10: Other Services | C10: =SUMIFS(Raw_Stripe!$H$6:$H$49,Raw_Stripe!$M$6:$M$49,"Jan-25",Raw_Stripe!$N$6:$N$49,"Other Services") -> 953.05 | D10: =SUMIFS(Raw_Stripe!$H$6:$H$49,Raw_Stripe!$M$6:$M$49,"Feb-25",Raw_Stripe!$N$6:$N$49,"Other Services") -> 6800 | E10: =SUMIFS(Raw_Stripe!$H$6:$H$49,Raw_Stripe!$M$6:$M$49,"Mar-25",Raw_Stripe!$N$6:$N$49,"Other Services") -> 3343.5 | F10: =SUMIFS(Raw_Stripe!$H$6:$H$49,Raw_Stripe!$M$6:$M$49,"Apr-25",Raw_Stripe!$N$6:$N$49,"Other Services") -> 9200 | G10: =SUMIFS(Raw_Stripe!$H$6:$H$49,Raw_Stripe!$M$6:$M$49,"May-25",Raw_Stripe!$N$6:$N$49,"Other Services") -> 1415.96 | H10: =SUMIFS(Raw_Stripe!$H$6:$H$49,Raw_Stripe!$M$6:$M$49,"Jun-25",Raw_Stripe!$N$6:$N$49,"Other Services") -> 2827.2 | I10: =SUMIFS(Raw_Stripe!$H$6:$H$49,Raw_Stripe!$M$6:$M$49,"Jul-25",Raw_Stripe!$N$6:$N$49,"Other Services") -> 1307.04 | J10: =SUMIFS(Raw_Stripe!$H$6:$H$49,Raw_Stripe!$M$6:$M$49,"Aug-25",Raw_Stripe!$N$6:$N$49,"Other Services") -> 7500 | K10: =SUMIFS(Raw_Stripe!$H$6:$H$49,Raw_Stripe!$M$6:$M$49,"Sep-25",Raw_Stripe!$N$6:$N$49,"Other Services") -> 0 | L10: =SUMIFS(Raw_Stripe!$H$6:$H$49,Raw_Stripe!$M$6:$M$49,"Oct-25",Raw_Stripe!$N$6:$N$49,"Other Services") -> 0 | M10: =SUMIFS(Raw_Stripe!$H$6:$H$49,Raw_Stripe!$M$6:$M$49,"Nov-25",Raw_Stripe!$N$6:$N$49,"Other Services") -> 6500 | N10: =SUMIFS(Raw_Stripe!$H$6:$H$49,Raw_Stripe!$M$6:$M$49,"Dec-25",Raw_Stripe!$N$6:$N$49,"Other Services") -> 1143.66 | O10: =SUM(C10:N10) -> 40990.41
B11: TOTAL REVENUE | C11: =SUM(C7:C10) -> 25737.51 | D11: =SUM(D7:D10) -> 23034.3 | E11: =SUM(E7:E10) -> 26464.44 | F11: =SUM(F7:F10) -> 13088.26 | G11: =SUM(G7:G10) -> 12589.43 | H11: =SUM(H7:H10) -> 33888.23 | I11: =SUM(I7:I10) -> 12773.75 | J11: =SUM(J7:J10) -> 10331 | ... N11: =SUM(N7:N10) -> 10643.66 | O11: =SUM(C11:N11) -> 218895.77
B12: MoM Growth % | C12: — | D12: =IFERROR((D11/C11)-1,"-") -> -0.10502997 | E12: =IFERROR((E11/D11)-1,"-") -> 0.14891444 | F12: =IFERROR((F11/E11)-1,"-") -> -0.50543975 | G12: =IFERROR((G11/F11)-1,"-") -> -0.038112782 | H12: =IFERROR((H11/G11)-1,"-") -> 1.6918002 | I12: =IFERROR((I11/H11)-1,"-") -> -0.62306234 | J12: =IFERROR((J11/I11)-1,"-") -> -0.19123202 | K12: =IFERROR((K11/J11)-1,"-") -> 0.26334721 | ... N12: =IFERROR((N11/M11)-1,"-") -> -0.030543765
B15: REVENUE TREND CHART (clustered bar — categories × months)

Sheet Receivables_Aging
B2: Receivables Aging · UAE & Singapore
B3: Outstanding by customer, bucketed by invoice age — live from Raw_Stripe
B5: UAE Company (UAE)
B6: Customer | C6: Total Outstanding | D6: Current (0-30) | E6: 31-60 days | F6: 60+ days | G6: Currency | H6: USD Equivalent | I6: % of Total | J6: Oldest Inv. | K6: Status
B7: Alphabet Logistics LLC | C7: =SUMIFS(Raw_Stripe!$L$6:$L$49,Raw_Stripe!$D$6:$D$49,B7,Raw_Stripe!$O$6:$O$49,"UAE") -> 10554.5 | D7: =SUMIFS(Raw_Stripe!$L$6:$L$49,Raw_Stripe!$D$6:$D$49,B7,Raw_Stripe!$O$6:$O$49,"UAE",Raw_Stripe!$C$6:$C$49,">="&(TODAY()-30)) -> 0 | E7: =SUMIFS(Raw_Stripe!$L$6:$L$49,Raw_Stripe!$D$6:$D$49,B7,Raw_Stripe!$O$6:$O$49,"UAE",Raw_Stripe!$C$6:$C$49,">="&(TODAY()-60),Raw_Stripe!$C$6:$C$49,"<"&(TODAY()-30)) -> 0 | F7: =SUMIFS(Raw_Stripe!$L$6:$L$49,Raw_Stripe!$D$6:$D$49,B7,Raw_Stripe!$O$6:$O$49,"UAE",Raw_Stripe!$C$6:$C$49,"<"&(TODAY()-60)) -> 10554.5 | G7: AED | H7: =C7*Settings_FX!D$27 -> 2873.9904 | I7: =IFERROR(C7/$C$15,0) -> 0.28104488 | J7: =IFERROR(minifs(Raw_Stripe!$C$6:$C$49,Raw_Stripe!$D$6:$D$49,B7,Raw_Stripe!$L$6:$L$49,">0"),"") | K7: =IF(F7>0,"⚠ 60+ days",IF(E7>0,"⚠ 31-60 days","✓ Current")) -> ⚠ 60+ days
B8: Emirates Retail Group | C8: =SUMIFS(Raw_Stripe!$L$6:$L$49,Raw_Stripe!$D$6:$D$49,B8,Raw_Stripe!$O$6:$O$49,"UAE") -> 4200 | D8: =SUMIFS(Raw_Stripe!$L$6:$L$49,Raw_Stripe!$D$6:$D$49,B8,Raw_Stripe!$O$6:$O$49,"UAE",Raw_Stripe!$C$6:$C$49,">="&(TODAY()-30)) -> 0 | E8: =SUMIFS(Raw_Stripe!$L$6:$L$49,Raw_Stripe!$D$6:$D$49,B8,Raw_Stripe!$O$6:$O$49,"UAE",Raw_Stripe!$C$6:$C$49,">="&(TODAY()-60),Raw_Stripe!$C$6:$C$49,"<"&(TODAY()-30)) -> 0 | F8: =SUMIFS(Raw_Stripe!$L$6:$L$49,Raw_Stripe!$D$6:$D$49,B8,Raw_Stripe!$O$6:$O$49,"UAE",Raw_Stripe!$C$6:$C$49,"<"&(TODAY()-60)) -> 4200 | G8: AED | H8: =C8*Settings_FX!D$27 -> 1143.66 | I8: =IFERROR(C8/$C$15,0) -> 0.11183746 | J8: =IFERROR(minifs(Raw_Stripe!$C$6:$C$49,Raw_Stripe!$D$6:$D$49,B8,Raw_Stripe!$L$6:$L$49,">0"),"") | K8: =IF(F8>0,"⚠ 60+ days",IF(E8>0,"⚠ 31-60 days","✓ Current")) -> ⚠ 60+ days
B9: Gulf Tech Distribution | C9: =SUMIFS(Raw_Stripe!$L$6:$L$49,Raw_Stripe!$D$6:$D$49,B9,Raw_Stripe!$O$6:$O$49,"UAE") -> 9500 | D9: =SUMIFS(Raw_Stripe!$L$6:$L$49,Raw_Stripe!$D$6:$D$49,B9,Raw_Stripe!$O$6:$O$49,"UAE",Raw_Stripe!$C$6:$C$49,">="&(TODAY()-30)) -> 0 | E9: =SUMIFS(Raw_Stripe!$L$6:$L$49,Raw_Stripe!$D$6:$D$49,B9,Raw_Stripe!$O$6:$O$49,"UAE",Raw_Stripe!$C$6:$C$49,">="&(TODAY()-60),Raw_Stripe!$C$6:$C$49,"<"&(TODAY()-30)) -> 0 | F9: =SUMIFS(Raw_Stripe!$L$6:$L$49,Raw_Stripe!$D$6:$D$49,B9,Raw_Stripe!$O$6:$O$49,"UAE",Raw_Stripe!$C$6:$C$49,"<"&(TODAY()-60)) -> 9500 | G9: USD | H9: =C9 -> 9500 | I9: =IFERROR(C9/$C$15,0) -> 0.25296569 | J9: =IFERROR(minifs(Raw_Stripe!$C$6:$C$49,Raw_Stripe!$D$6:$D$49,B9,Raw_Stripe!$L$6:$L$49,">0"),"") | K9: =IF(F9>0,"⚠ 60+ days",IF(E9>0,"⚠ 31-60 days","✓ Current")) -> ⚠ 60+ days
B10: Dubai Properties Co | C10: =SUMIFS(Raw_Stripe!$L$6:$L$49,Raw_Stripe!$D$6:$D$49,B10,Raw_Stripe!$O$6:$O$49,"UAE") -> 0 | D10: =SUMIFS(Raw_Stripe!$L$6:$L$49,Raw_Stripe!$D$6:$D$49,B10,Raw_Stripe!$O$6:$O$49,"UAE",Raw_Stripe!$C$6:$C$49,">="&(TODAY()-30)) -> 0 | E10: =SUMIFS(Raw_Stripe!$L$6:$L$49,Raw_Stripe!$D$6:$D$49,B10,Raw_Stripe!$O$6:$O$49,"UAE",Raw_Stripe!$C$6:$C$49,">="&(TODAY()-60),Raw_Stripe!$C$6:$C$49,"<"&(TODAY()-30)) -> 0 | F10: =SUMIFS(Raw_Stripe!$L$6:$L$49,Raw_Stripe!$D$6:$D$49,B10,Raw_Stripe!$O$6:$O$49,"UAE",Raw_Stripe!$C$6:$C$49,"<"&(TODAY()-60)) -> 0 | G10: AED | H10: =C10*Settings_FX!D$27 -> 0 | I10: =IFERROR(C10/$C$15,0) -> 0 | J10: =IFERROR(minifs(Raw_Stripe!$C$6:$C$49,Raw_Stripe!$D$6:$D$49,B10,Raw_Stripe!$L$6:$L$49,">0"),"") | K10: =IF(F10>0,"⚠ 60+ days",IF(E10>0,"⚠ 31-60 days","✓ Current")) -> ✓ Current
B11: Abu Dhabi Trading | C11: =SUMIFS(Raw_Stripe!$L$6:$L$49,Raw_Stripe!$D$6:$D$49,B11,Raw_Stripe!$O$6:$O$49,"UAE") -> 0 | D11: =SUMIFS(Raw_Stripe!$L$6:$L$49,Raw_Stripe!$D$6:$D$49,B11,Raw_Stripe!$O$6:$O$49,"UAE",Raw_Stripe!$C$6:$C$49,">="&(TODAY()-30)) -> 0 | E11: =SUMIFS(Raw_Stripe!$L$6:$L$49,Raw_Stripe!$D$6:$D$49,B11,Raw_Stripe!$O$6:$O$49,"UAE",Raw_Stripe!$C$6:$C$49,">="&(TODAY()-60),Raw_Stripe!$C$6:$C$49,"<"&(TODAY()-30)) -> 0 | F11: =SUMIFS(Raw_Stripe!$L$6:$L$49,Raw_Stripe!$D$6:$D$49,B11,Raw_Stripe!$O$6:$O$49,"UAE",Raw_Stripe!$C$6:$C$49,"<"&(TODAY()-60)) -> 0 | G11: AED | H11: =C11*Settings_FX!D$27 -> 0 | I11: =IFERROR(C11/$C$15,0) -> 0 | J11: =IFERROR(minifs(Raw_Stripe!$C$6:$C$49,Raw_Stripe!$D$6:$D$49,B11,Raw_Stripe!$L$6:$L$49,">0"),"") | K11: =IF(F11>0,"⚠ 60+ days",IF(E11>0,"⚠ 31-60 days","✓ Current")) -> ✓ Current
B12: Rak Bank Digital | C12: =SUMIFS(Raw_Stripe!$L$6:$L$49,Raw_Stripe!$D$6:$D$49,B12,Raw_Stripe!$O$6:$O$49,"UAE") -> 6800 | D12: =SUMIFS(Raw_Stripe!$L$6:$L$49,Raw_Stripe!$D$6:$D$49,B12,Raw_Stripe!$O$6:$O$49,"UAE",Raw_Stripe!$C$6:$C$49,">="&(TODAY()-30)) -> 0 | E12: =SUMIFS(Raw_Stripe!$L$6:$L$49,Raw_Stripe!$D$6:$D$49,B12,Raw_Stripe!$O$6:$O$49,"UAE",Raw_Stripe!$C$6:$C$49,">="&(TODAY()-60),Raw_Stripe!$C$6:$C$49,"<"&(TODAY()-30)) -> 0 | F12: =SUMIFS(Raw_Stripe!$L$6:$L$49,Raw_Stripe!$D$6:$D$49,B12,Raw_Stripe!$O$6:$O$49,"UAE",Raw_Stripe!$C$6:$C$49,"<"&(TODAY()-60)) -> 6800 | G12: AED | H12: =C12*Settings_FX!D$27 -> 1851.64 | I12: =IFERROR(C12/$C$15,0) -> 0.18107018 | J12: =IFERROR(minifs(Raw_Stripe!$C$6:$C$49,Raw_Stripe!$D$6:$D$49,B12,Raw_Stripe!$L$6:$L$49,">0"),"") | K12: =IF(F12>0,"⚠ 60+ days",IF(E12>0,"⚠ 31-60 days","✓ Current")) -> ⚠ 60+ days
B13: Global SaaS Inc | C13: =SUMIFS(Raw_Stripe!$L$6:$L$49,Raw_Stripe!$D$6:$D$49,B13,Raw_Stripe!$O$6:$O$49,"UAE") -> 0 | D13: =SUMIFS(Raw_Stripe!$L$6:$L$49,Raw_Stripe!$D$6:$D$49,B13,Raw_Stripe!$O$6:$O$49,"UAE",Raw_Stripe!$C$6:$C$49,">="&(TODAY()-30)) -> 0 | E13: =SUMIFS(Raw_Stripe!$L$6:$L$49,Raw_Stripe!$D$6:$D$49,B13,Raw_Stripe!$O$6:$O$49,"UAE",Raw_Stripe!$C$6:$C$49,">="&(TODAY()-60),Raw_Stripe!$C$6:$C$49,"<"&(TODAY()-30)) -> 0 | F13: =SUMIFS(Raw_Stripe!$L$6:$L$49,Raw_Stripe!$D$6:$D$49,B13,Raw_Stripe!$O$6:$O$49,"UAE",Raw_Stripe!$C$6:$C$49,"<"&(TODAY()-60)) -> 0 | G13: USD | H13: =C13 -> 0 | I13: =IFERROR(C13/$C$15,0) -> 0 | J13: =IFERROR(minifs(Raw_Stripe!$C$6:$C$49,Raw_Stripe!$D$6:$D$49,B13,Raw_Stripe!$L$6:$L$49,">0"),"") | K13: =IF(F13>0,"⚠ 60+ days",IF(E13>0,"⚠ 31-60 days","✓ Current")) -> ✓ Current
B14: Mena Apps FZ-LLC | C14: =SUMIFS(Raw_Stripe!$L$6:$L$49,Raw_Stripe!$D$6:$D$49,B14,Raw_Stripe!$O$6:$O$49,"UAE") -> 6500 | D14: =SUMIFS(Raw_Stripe!$L$6:$L$49,Raw_Stripe!$D$6:$D$49,B14,Raw_Stripe!$O$6:$O$49,"UAE",Raw_Stripe!$C$6:$C$49,">="&(TODAY()-30)) -> 0 | E14: =SUMIFS(Raw_Stripe!$L$6:$L$49,Raw_Stripe!$D$6:$D$49,B14,Raw_Stripe!$O$6:$O$49,"UAE",Raw_Stripe!$C$6:$C$49,">="&(TODAY()-60),Raw_Stripe!$C$6:$C$49,"<"&(TODAY()-30)) -> 0 | F14: =SUMIFS(Raw_Stripe!$L$6:$L$49,Raw_Stripe!$D$6:$D$49,B14,Raw_Stripe!$O$6:$O$49,"UAE",Raw_Stripe!$C$6:$C$49,"<"&(TODAY()-60)) -> 6500 | G14: USD | H14: =C14 -> 6500 | I14: =IFERROR(C14/$C$15,0) -> 0.17308179 | J14: =IFERROR(minifs(Raw_Stripe!$C$6:$C$49,Raw_Stripe!$D$6:$D$49,B14,Raw_Stripe!$L$6:$L$49,">0"),"") | K14: =IF(F14>0,"⚠ 60+ days",IF(E14>0,"⚠ 31-60 days","✓ Current")) -> ⚠ 60+ days
B15: TOTAL UAE | C15: =SUM(C7:C14) -> 37554.5 | D15: =SUM(D7:D14) -> 0 | E15: =SUM(E7:E14) -> 0 | F15: =SUM(F7:F14) -> 37554.5 | H15: =SUM(H7:H14) -> 21869.29
B18: Singapore Company (SG)
B19: Customer | C19: Total Outstanding | D19: Current (0-30) | E19: 31-60 days | F19: 60+ days | G19: Currency | H19: USD Equivalent | I19: % of Total | J19: Oldest Inv. | K19: Status
B20: Singapore FinTech Hub | C20: =SUMIFS(Raw_Stripe!$L$6:$L$49,Raw_Stripe!$D$6:$D$49,B20,Raw_Stripe!$O$6:$O$49,"SG") -> 4200 | D20: =SUMIFS(Raw_Stripe!$L$6:$L$49,Raw_Stripe!$D$6:$D$49,B20,Raw_Stripe!$O$6:$O$49,"SG",Raw_Stripe!$C$6:$C$49,">="&(TODAY()-30)) -> 0 | E20: =SUMIFS(Raw_Stripe!$L$6:$L$49,Raw_Stripe!$D$6:$D$49,B20,Raw_Stripe!$O$6:$O$49,"SG",Raw_Stripe!$C$6:$C$49,">="&(TODAY()-60),Raw_Stripe!$C$6:$C$49,"<"&(TODAY()-30)) -> 0 | F20: =SUMIFS(Raw_Stripe!$L$6:$L$49,Raw_Stripe!$D$6:$D$49,B20,Raw_Stripe!$O$6:$O$49,"SG",Raw_Stripe!$C$6:$C$49,"<"&(TODAY()-60)) -> 4200 | G20: SGD | H20: =C20*Settings_FX!E$27 -> 3137.4 | I20: =IFERROR(C20/$C$27,0) -> 0.11968233 | J20: =IFERROR(minifs(Raw_Stripe!$C$6:$C$49,Raw_Stripe!$D$6:$D$49,B20,Raw_Stripe!$L$6:$L$49,">0"),"") | K20: =IF(F20>0,"⚠ 60+ days",IF(E20>0,"⚠ 31-60 days","✓ Current")) -> ⚠ 60+ days
B21: Asia Pacific Solutions | C21: =SUMIFS(Raw_Stripe!$L$6:$L$49,Raw_Stripe!$D$6:$D$49,B21,Raw_Stripe!$O$6:$O$49,"SG") -> 0 | D21: =SUMIFS(Raw_Stripe!$L$6:$L$49,Raw_Stripe!$D$6:$D$49,B21,Raw_Stripe!$O$6:$O$49,"SG",Raw_Stripe!$C$6:$C$49,">="&(TODAY()-30)) -> 0 | E21: =SUMIFS(Raw_Stripe!$L$6:$L$49,Raw_Stripe!$D$6:$D$49,B21,Raw_Stripe!$O$6:$O$49,"SG",Raw_Stripe!$C$6:$C$49,">="&(TODAY()-60),Raw_Stripe!$C$6:$C$49,"<"&(TODAY()-30)) -> 0 | F21: =SUMIFS(Raw_Stripe!$L$6:$L$49,Raw_Stripe!$D$6:$D$49,B21,Raw_Stripe!$O$6:$O$49,"SG",Raw_Stripe!$C$6:$C$49,"<"&(TODAY()-60)) -> 0 | G21: USD | H21: =C21 -> 0 | I21: =IFERROR(C21/$C$27,0) -> 0 | J21: =IFERROR(minifs(Raw_Stripe!$C$6:$C$49,Raw_Stripe!$D$6:$D$49,B21,Raw_Stripe!$L$6:$L$49,">0"),"") | K21: =IF(F21>0,"⚠ 60+ days",IF(E21>0,"⚠ 31-60 days","✓ Current")) -> ✓ Current
B22: Marina Bay Holdings | C22: =SUMIFS(Raw_Stripe!$L$6:$L$49,Raw_Stripe!$D$6:$D$49,B22,Raw_Stripe!$O$6:$O$49,"SG") -> 1800 | D22: =SUMIFS(Raw_Stripe!$L$6:$L$49,Raw_Stripe!$D$6:$D$49,B22,Raw_Stripe!$O$6:$O$49,"SG",Raw_Stripe!$C$6:$C$49,">="&(TODAY()-30)) -> 0 | E22: =SUMIFS(Raw_Stripe!$L$6:$L$49,Raw_Stripe!$D$6:$D$49,B22,Raw_Stripe!$O$6:$O$49,"SG",Raw_Stripe!$C$6:$C$49,">="&(TODAY()-60),Raw_Stripe!$C$6:$C$49,"<"&(TODAY()-30)) -> 0 | F22: =SUMIFS(Raw_Stripe!$L$6:$L$49,Raw_Stripe!$D$6:$D$49,B22,Raw_Stripe!$O$6:$O$49,"SG",Raw_Stripe!$C$6:$C$49,"<"&(TODAY()-60)) -> 1800 | G22: SGD | H22: =C22*Settings_FX!E$27 -> 1344.6 | I22: =IFERROR(C22/$C$27,0) -> 0.051292427 | J22: =IFERROR(minifs(Raw_Stripe!$C$6:$C$49,Raw_Stripe!$D$6:$D$49,B22,Raw_Stripe!$L$6:$L$49,">0"),"") | K22: =IF(F22>0,"⚠ 60+ days",IF(E22>0,"⚠ 31-60 days","✓ Current")) -> ⚠ 60+ days
B23: Lion City Media | C23: =SUMIFS(Raw_Stripe!$L$6:$L$49,Raw_Stripe!$D$6:$D$49,B23,Raw_Stripe!$O$6:$O$49,"SG") -> 0 | D23: =SUMIFS(Raw_Stripe!$L$6:$L$49,Raw_Stripe!$D$6:$D$49,B23,Raw_Stripe!$O$6:$O$49,"SG",Raw_Stripe!$C$6:$C$49,">="&(TODAY()-30)) -> 0 | E23: =SUMIFS(Raw_Stripe!$L$6:$L$49,Raw_Stripe!$D$6:$D$49,B23,Raw_Stripe!$O$6:$O$49,"SG",Raw_Stripe!$C$6:$C$49,">="&(TODAY()-60),Raw_Stripe!$C$6:$C$49,"<"&(TODAY()-30)) -> 0 | F23: =SUMIFS(Raw_Stripe!$L$6:$L$49,Raw_Stripe!$D$6:$D$49,B23,Raw_Stripe!$O$6:$O$49,"SG",Raw_Stripe!$C$6:$C$49,"<"&(TODAY()-60)) -> 0 | G23: SGD | H23: =C23*Settings_FX!E$27 -> 0 | I23: =IFERROR(C23/$C$27,0) -> 0 | J23: =IFERROR(minifs(Raw_Stripe!$C$6:$C$49,Raw_Stripe!$D$6:$D$49,B23,Raw_Stripe!$L$6:$L$49,">0"),"") | K23: =IF(F23>0,"⚠ 60+ days",IF(E23>0,"⚠ 31-60 days","✓ Current")) -> ✓ Current
B24: Sentosa E-Commerce | C24: =SUMIFS(Raw_Stripe!$L$6:$L$49,Raw_Stripe!$D$6:$D$49,B24,Raw_Stripe!$O$6:$O$49,"SG") -> 24000 | D24: =SUMIFS(Raw_Stripe!$L$6:$L$49,Raw_Stripe!$D$6:$D$49,B24,Raw_Stripe!$O$6:$O$49,"SG",Raw_Stripe!$C$6:$C$49,">="&(TODAY()-30)) -> 0 | E24: =SUMIFS(Raw_Stripe!$L$6:$L$49,Raw_Stripe!$D$6:$D$49,B24,Raw_Stripe!$O$6:$O$49,"SG",Raw_Stripe!$C$6:$C$49,">="&(TODAY()-60),Raw_Stripe!$C$6:$C$49,"<"&(TODAY()-30)) -> 0 | F24: =SUMIFS(Raw_Stripe!$L$6:$L$49,Raw_Stripe!$D$6:$D$49,B24,Raw_Stripe!$O$6:$O$49,"SG",Raw_Stripe!$C$6:$C$49,"<"&(TODAY()-60)) -> 24000 | G24: USD | H24: =C24 -> 24000 | I24: =IFERROR(C24/$C$27,0) -> 0.68389902 | J24: =IFERROR(minifs(Raw_Stripe!$C$6:$C$49,Raw_Stripe!$D$6:$D$49,B24,Raw_Stripe!$L$6:$L$49,">0"),"") | K24: =IF(F24>0,"⚠ 60+ days",IF(E24>0,"⚠ 31-60 days","✓ Current")) -> ⚠ 60+ days
B25: Orchard Retail Pte | C25: =SUMIFS(Raw_Stripe!$L$6:$L$49,Raw_Stripe!$D$6:$D$49,B25,Raw_Stripe!$O$6:$O$49,"SG") -> 5092.9 | D25: =SUMIFS(Raw_Stripe!$L$6:$L$49,Raw_Stripe!$D$6:$D$49,B25,Raw_Stripe!$O$6:$O$49,"SG",Raw_Stripe!$C$6:$C$49,">="&(TODAY()-30)) -> 0 | E25: =SUMIFS(Raw_Stripe!$L$6:$L$49,Raw_Stripe!$D$6:$D$49,B25,Raw_Stripe!$O$6:$O$49,"SG",Raw_Stripe!$C$6:$C$49,">="&(TODAY()-60),Raw_Stripe!$C$6:$C$49,"<"&(TODAY()-30)) -> 0 | F25: =SUMIFS(Raw_Stripe!$L$6:$L$49,Raw_Stripe!$D$6:$D$49,B25,Raw_Stripe!$O$6:$O$49,"SG",Raw_Stripe!$C$6:$C$49,"<"&(TODAY()-60)) -> 5092.9 | G25: SGD | H25: =C25*Settings_FX!E$27 -> 3804.3963 | I25: =IFERROR(C25/$C$27,0) -> 0.14512622 | J25: =IFERROR(minifs(Raw_Stripe!$C$6:$C$49,Raw_Stripe!$D$6:$D$49,B25,Raw_Stripe!$L$6:$L$49,">0"),"") | K25: =IF(F25>0,"⚠ 60+ days",IF(E25>0,"⚠ 31-60 days","✓ Current")) -> ⚠ 60+ days
B26: Jakarta Digital Ventures | C26: =SUMIFS(Raw_Stripe!$L$6:$L$49,Raw_Stripe!$D$6:$D$49,B26,Raw_Stripe!$O$6:$O$49,"SG") -> 0 | D26: =SUMIFS(Raw_Stripe!$L$6:$L$49,Raw_Stripe!$D$6:$D$49,B26,Raw_Stripe!$O$6:$O$49,"SG",Raw_Stripe!$C$6:$C$49,">="&(TODAY()-30)) -> 0 | E26: =SUMIFS(Raw_Stripe!$L$6:$L$49,Raw_Stripe!$D$6:$D$49,B26,Raw_Stripe!$O$6:$O$49,"SG",Raw_Stripe!$C$6:$C$49,">="&(TODAY()-60),Raw_Stripe!$C$6:$C$49,"<"&(TODAY()-30)) -> 0 | F26: =SUMIFS(Raw_Stripe!$L$6:$L$49,Raw_Stripe!$D$6:$D$49,B26,Raw_Stripe!$O$6:$O$49,"SG",Raw_Stripe!$C$6:$C$49,"<"&(TODAY()-60)) -> 0 | G26: USD | H26: =C26 -> 0 | I26: =IFERROR(C26/$C$27,0) -> 0 | J26: =IFERROR(minifs(Raw_Stripe!$C$6:$C$49,Raw_Stripe!$D$6:$D$49,B26,Raw_Stripe!$L$6:$L$49,">0"),"") | K26: =IF(F26>0,"⚠ 60+ days",IF(E26>0,"⚠ 31-60 days","✓ Current")) -> ✓ Current
B27: TOTAL SG | C27: =SUM(C20:C26) -> 35092.9 | D27: =SUM(D20:D26) -> 0 | E27: =SUM(E20:E26) -> 0 | F27: =SUM(F20:F26) -> 35092.9 | H27: =SUM(H20:H26) -> 32286.396
B29: COMBINED A/R SUMMARY
B30: Total UAE Outstanding (USD) | C30: =H15 -> 21869.29
B31: Total SG Outstanding (USD) | C31: =H27 -> 32286.396
B32: Combined Outstanding (USD) | C32: =H15+H27 -> 54155.687
B33: Customers with 60+ days A/R | C33: =COUNTIF(K6:K14,"*60+*")+COUNTIF(K19:K26,"*60+*") -> 9

Sheet Customer_Receivables
B2: Customer Receivables · Xero + Stripe
B3: Per-customer invoice status breakdown — Draft · Unsent · AwaitPay · Partial · Paid · Void
B5: XERO CUSTOMER RECEIVABLES (per customer × invoice status)
B6: Customer | C6: Total Invoiced USD | D6: Draft | E6: Unsent | F6: Await Pay | G6: Partial | H6: Paid | I6: Void | J6: Outstanding USD | K6: # Invoices
B7: Alphabet Logistics LLC | C7: =SUMIFS(Raw_Xero_Invoices!$H$6:$H$26,Raw_Xero_Invoices!$D$6:$D$26,B7) -> 5527.69 | D7: =SUMIFS(Raw_Xero_Invoices!$H$6:$H$26,Raw_Xero_Invoices!$D$6:$D$26,B7,Raw_Xero_Invoices!$M$6:$M$26,"Draft") -> 0 | E7: =SUMIFS(Raw_Xero_Invoices!$H$6:$H$26,Raw_Xero_Invoices!$D$6:$D$26,B7,Raw_Xero_Invoices!$M$6:$M$26,"Unsent") -> 0 | F7: =SUMIFS(Raw_Xero_Invoices!$H$6:$H$26,Raw_Xero_Invoices!$D$6:$D$26,B7,Raw_Xero_Invoices!$M$6:$M$26,"Awaiting Payment") -> 1225.35 | G7: =SUMIFS(Raw_Xero_Invoices!$H$6:$H$26,Raw_Xero_Invoices!$D$6:$D$26,B7,Raw_Xero_Invoices!$M$6:$M$26,"Partial") -> 1034.74 | H7: =SUMIFS(Raw_Xero_Invoices!$H$6:$H$26,Raw_Xero_Invoices!$D$6:$D$26,B7,Raw_Xero_Invoices!$M$6:$M$26,"Paid") -> 3267.6 | I7: =SUMIFS(Raw_Xero_Invoices!$H$6:$H$26,Raw_Xero_Invoices!$D$6:$D$26,B7,Raw_Xero_Invoices!$M$6:$M$26,"Void") -> 0 | J7: =D7+E7+F7+G7 -> 2260.09 | K7: =COUNTIFS(Raw_Xero_Invoices!$D$6:$D$26,B7) -> 3
B8: Emirates Retail Group | C8: =SUMIFS(Raw_Xero_Invoices!$H$6:$H$26,Raw_Xero_Invoices!$D$6:$D$26,B8) -> 2178.4 | D8: =SUMIFS(Raw_Xero_Invoices!$H$6:$H$26,Raw_Xero_Invoices!$D$6:$D$26,B8,Raw_Xero_Invoices!$M$6:$M$26,"Draft") -> 0 | E8: =SUMIFS(Raw_Xero_Invoices!$H$6:$H$26,Raw_Xero_Invoices!$D$6:$D$26,B8,Raw_Xero_Invoices!$M$6:$M$26,"Unsent") -> 0 | F8: =SUMIFS(Raw_Xero_Invoices!$H$6:$H$26,Raw_Xero_Invoices!$D$6:$D$26,B8,Raw_Xero_Invoices!$M$6:$M$26,"Awaiting Payment") -> 0 | G8: =SUMIFS(Raw_Xero_Invoices!$H$6:$H$26,Raw_Xero_Invoices!$D$6:$D$26,B8,Raw_Xero_Invoices!$M$6:$M$26,"Partial") -> 0 | H8: =SUMIFS(Raw_Xero_Invoices!$H$6:$H$26,Raw_Xero_Invoices!$D$6:$D$26,B8,Raw_Xero_Invoices!$M$6:$M$26,"Paid") -> 1225.35 | I8: =SUMIFS(Raw_Xero_Invoices!$H$6:$H$26,Raw_Xero_Invoices!$D$6:$D$26,B8,Raw_Xero_Invoices!$M$6:$M$26,"Void") -> 953.05 | J8: =D8+E8+F8+G8 -> 0 | K8: =COUNTIFS(Raw_Xero_Invoices!$D$6:$D$26,B8) -> 2
B9: Gulf Tech Distribution | C9: =SUMIFS(Raw_Xero_Invoices!$H$6:$H$26,Raw_Xero_Invoices!$D$6:$D$26,B9) -> 27500 | D9: =SUMIFS(Raw_Xero_Invoices!$H$6:$H$26,Raw_Xero_Invoices!$D$6:$D$26,B9,Raw_Xero_Invoices!$M$6:$M$26,"Draft") -> 0 | E9: =SUMIFS(Raw_Xero_Invoices!$H$6:$H$26,Raw_Xero_Invoices!$D$6:$D$26,B9,Raw_Xero_Invoices!$M$6:$M$26,"Unsent") -> 9500 | F9: =SUMIFS(Raw_Xero_Invoices!$H$6:$H$26,Raw_Xero_Invoices!$D$6:$D$26,B9,Raw_Xero_Invoices!$M$6:$M$26,"Awaiting Payment") -> 0 | G9: =SUMIFS(Raw_Xero_Invoices!$H$6:$H$26,Raw_Xero_Invoices!$D$6:$D$26,B9,Raw_Xero_Invoices!$M$6:$M$26,"Partial") -> 0 | H9: =SUMIFS(Raw_Xero_Invoices!$H$6:$H$26,Raw_Xero_Invoices!$D$6:$D$26,B9,Raw_Xero_Invoices!$M$6:$M$26,"Paid") -> 18000 | I9: =SUMIFS(Raw_Xero_Invoices!$H$6:$H$26,Raw_Xero_Invoices!$D$6:$D$26,B9,Raw_Xero_Invoices!$M$6:$M$26,"Void") -> 0 | J9: =D9+E9+F9+G9 -> 9500 | K9: =COUNTIFS(Raw_Xero_Invoices!$D$6:$D$26,B9) -> 2
B10: Dubai Properties Co | C10: =SUMIFS(Raw_Xero_Invoices!$H$6:$H$26,Raw_Xero_Invoices!$D$6:$D$26,B10) -> 2586.85 | D10: =SUMIFS(Raw_Xero_Invoices!$H$6:$H$26,Raw_Xero_Invoices!$D$6:$D$26,B10,Raw_Xero_Invoices!$M$6:$M$26,"Draft") -> 0 | E10: =SUMIFS(Raw_Xero_Invoices!$H$6:$H$26,Raw_Xero_Invoices!$D$6:$D$26,B10,Raw_Xero_Invoices!$M$6:$M$26,"Unsent") -> 0 | F10: =SUMIFS(Raw_Xero_Invoices!$H$6:$H$26,Raw_Xero_Invoices!$D$6:$D$26,B10,Raw_Xero_Invoices!$M$6:$M$26,"Awaiting Payment") -> 0 | G10: =SUMIFS(Raw_Xero_Invoices!$H$6:$H$26,Raw_Xero_Invoices!$D$6:$D$26,B10,Raw_Xero_Invoices!$M$6:$M$26,"Partial") -> 2586.85 | H10: =SUMIFS(Raw_Xero_Invoices!$H$6:$H$26,Raw_Xero_Invoices!$D$6:$D$26,B10,Raw_Xero_Invoices!$M$6:$M$26,"Paid") -> 0 | I10: =SUMIFS(Raw_Xero_Invoices!$H$6:$H$26,Raw_Xero_Invoices!$D$6:$D$26,B10,Raw_Xero_Invoices!$M$6:$M$26,"Void") -> 0 | J10: =D10+E10+F10+G10 -> 2586.85 | K10: =COUNTIFS(Raw_Xero_Invoices!$D$6:$D$26,B10) -> 1
B11: Abu Dhabi Trading | C11: =SUMIFS(Raw_Xero_Invoices!$H$6:$H$26,Raw_Xero_Invoices!$D$6:$D$26,B11) -> 2042.25 | D11: =SUMIFS(Raw_Xero_Invoices!$H$6:$H$26,Raw_Xero_Invoices!$D$6:$D$26,B11,Raw_Xero_Invoices!$M$6:$M$26,"Draft") -> 0 | E11: =SUMIFS(Raw_Xero_Invoices!$H$6:$H$26,Raw_Xero_Invoices!$D$6:$D$26,B11,Raw_Xero_Invoices!$M$6:$M$26,"Unsent") -> 0 | F11: =SUMIFS(Raw_Xero_Invoices!$H$6:$H$26,Raw_Xero_Invoices!$D$6:$D$26,B11,Raw_Xero_Invoices!$M$6:$M$26,"Awaiting Payment") -> 0 | G11: =SUMIFS(Raw_Xero_Invoices!$H$6:$H$26,Raw_Xero_Invoices!$D$6:$D$26,B11,Raw_Xero_Invoices!$M$6:$M$26,"Partial") -> 0 | H11: =SUMIFS(Raw_Xero_Invoices!$H$6:$H$26,Raw_Xero_Invoices!$D$6:$D$26,B11,Raw_Xero_Invoices!$M$6:$M$26,"Paid") -> 2042.25 | I11: =SUMIFS(Raw_Xero_Invoices!$H$6:$H$26,Raw_Xero_Invoices!$D$6:$D$26,B11,Raw_Xero_Invoices!$M$6:$M$26,"Void") -> 0 | J11: =D11+E11+F11+G11 -> 0 | K11: =COUNTIFS(Raw_Xero_Invoices!$D$6:$D$26,B11) -> 1
B12: Rak Bank Digital | C12: =SUMIFS(Raw_Xero_Invoices!$H$6:$H$26,Raw_Xero_Invoices!$D$6:$D$26,B12) -> 2314.55 | D12: =SUMIFS(Raw_Xero_Invoices!$H$6:$H$26,Raw_Xero_Invoices!$D$6:$D$26,B12,Raw_Xero_Invoices!$M$6:$M$26,"Draft") -> 0 | E12: =SUMIFS(Raw_Xero_Invoices!$H$6:$H$26,Raw_Xero_Invoices!$D$6:$D$26,B12,Raw_Xero_Invoices!$M$6:$M$26,"Unsent") -> 0 | F12: =SUMIFS(Raw_Xero_Invoices!$H$6:$H$26,Raw_Xero_Invoices!$D$6:$D$26,B12,Raw_Xero_Invoices!$M$6:$M$26,"Awaiting Payment") -> 0 | G12: =SUMIFS(Raw_Xero_Invoices!$H$6:$H$26,Raw_Xero_Invoices!$D$6:$D$26,B12,Raw_Xero_Invoices!$M$6:$M$26,"Partial") -> 0 | H12: =SUMIFS(Raw_Xero_Invoices!$H$6:$H$26,Raw_Xero_Invoices!$D$6:$D$26,B12,Raw_Xero_Invoices!$M$6:$M$26,"Paid") -> 0 | I12: =SUMIFS(Raw_Xero_Invoices!$H$6:$H$26,Raw_Xero_Invoices!$D$6:$D$26,B12,Raw_Xero_Invoices!$M$6:$M$26,"Void") -> 2314.55 | J12: =D12+E12+F12+G12 -> 0 | K12: =COUNTIFS(Raw_Xero_Invoices!$D$6:$D$26,B12) -> 1
B13: Global SaaS Inc | C13: =SUMIFS(Raw_Xero_Invoices!$H$6:$H$26,Raw_Xero_Invoices!$D$6:$D$26,B13) -> 9200 | D13: =SUMIFS(Raw_Xero_Invoices!$H$6:$H$26,Raw_Xero_Invoices!$D$6:$D$26,B13,Raw_Xero_Invoices!$M$6:$M$26,"Draft") -> 9200 | E13: =SUMIFS(Raw_Xero_Invoices!$H$6:$H$26,Raw_Xero_Invoices!$D$6:$D$26,B13,Raw_Xero_Invoices!$M$6:$M$26,"Unsent") -> 0 | F13: =SUMIFS(Raw_Xero_Invoices!$H$6:$H$26,Raw_Xero_Invoices!$D$6:$D$26,B13,Raw_Xero_Invoices!$M$6:$M$26,"Awaiting Payment") -> 0 | G13: =SUMIFS(Raw_Xero_Invoices!$H$6:$H$26,Raw_Xero_Invoices!$D$6:$D$26,B13,Raw_Xero_Invoices!$M$6:$M$26,"Partial") -> 0 | H13: =SUMIFS(Raw_Xero_Invoices!$H$6:$H$26,Raw_Xero_Invoices!$D$6:$D$26,B13,Raw_Xero_Invoices!$M$6:$M$26,"Paid") -> 0 | I13: =SUMIFS(Raw_Xero_Invoices!$H$6:$H$26,Raw_Xero_Invoices!$D$6:$D$26,B13,Raw_Xero_Invoices!$M$6:$M$26,"Void") -> 0 | J13: =D13+E13+F13+G13 -> 9200 | K13: =COUNTIFS(Raw_Xero_Invoices!$D$6:$D$26,B13) -> 1
B14: Mena Apps FZ-LLC | C14: =SUMIFS(Raw_Xero_Invoices!$H$6:$H$26,Raw_Xero_Invoices!$D$6:$D$26,B14) -> 5800 | D14: =SUMIFS(Raw_Xero_Invoices!$H$6:$H$26,Raw_Xero_Invoices!$D$6:$D$26,B14,Raw_Xero_Invoices!$M$6:$M$26,"Draft") -> 0 | E14: =SUMIFS(Raw_Xero_Invoices!$H$6:$H$26,Raw_Xero_Invoices!$D$6:$D$26,B14,Raw_Xero_Invoices!$M$6:$M$26,"Unsent") -> 0 | F14: =SUMIFS(Raw_Xero_Invoices!$H$6:$H$26,Raw_Xero_Invoices!$D$6:$D$26,B14,Raw_Xero_Invoices!$M$6:$M$26,"Awaiting Payment") -> 0 | G14: =SUMIFS(Raw_Xero_Invoices!$H$6:$H$26,Raw_Xero_Invoices!$D$6:$D$26,B14,Raw_Xero_Invoices!$M$6:$M$26,"Partial") -> 0 | H14: =SUMIFS(Raw_Xero_Invoices!$H$6:$H$26,Raw_Xero_Invoices!$D$6:$D$26,B14,Raw_Xero_Invoices!$M$6:$M$26,"Paid") -> 5800 | I14: =SUMIFS(Raw_Xero_Invoices!$H$6:$H$26,Raw_Xero_Invoices!$D$6:$D$26,B14,Raw_Xero_Invoices!$M$6:$M$26,"Void") -> 0 | J14: =D14+E14+F14+G14 -> 0 | K14: =COUNTIFS(Raw_Xero_Invoices!$D$6:$D$26,B14) -> 1
B15: Singapore FinTech Hub | C15: =SUMIFS(Raw_Xero_Invoices!$H$6:$H$26,Raw_Xero_Invoices!$D$6:$D$26,B15) -> 8189.8 | D15: =SUMIFS(Raw_Xero_Invoices!$H$6:$H$26,Raw_Xero_Invoices!$D$6:$D$26,B15,Raw_Xero_Invoices!$M$6:$M$26,"Draft") -> 3137.4 | E15: =SUMIFS(Raw_Xero_Invoices!$H$6:$H$26,Raw_Xero_Invoices!$D$6:$D$26,B15,Raw_Xero_Invoices!$M$6:$M$26,"Unsent") -> 0 | F15: =SUMIFS(Raw_Xero_Invoices!$H$6:$H$26,Raw_Xero_Invoices!$D$6:$D$26,B15,Raw_Xero_Invoices!$M$6:$M$26,"Awaiting Payment") -> 0 | G15: =SUMIFS(Raw_Xero_Invoices!$H$6:$H$26,Raw_Xero_Invoices!$D$6:$D$26,B15,Raw_Xero_Invoices!$M$6:$M$26,"Partial") -> 0 | H15: =SUMIFS(Raw_Xero_Invoices!$H$6:$H$26,Raw_Xero_Invoices!$D$6:$D$26,B15,Raw_Xero_Invoices!$M$6:$M$26,"Paid") -> 5052.4 | I15: =SUMIFS(Raw_Xero_Invoices!$H$6:$H$26,Raw_Xero_Invoices!$D$6:$D$26,B15,Raw_Xero_Invoices!$M$6:$M$26,"Void") -> 0 | J15: =D15+E15+F15+G15 -> 3137.4 | K15: =COUNTIFS(Raw_Xero_Invoices!$D$6:$D$26,B15) -> 2
B16: Asia Pacific Solutions | C16: =SUMIFS(Raw_Xero_Invoices!$H$6:$H$26,Raw_Xero_Invoices!$D$6:$D$26,B16) -> 15500 | D16: =SUMIFS(Raw_Xero_Invoices!$H$6:$H$26,Raw_Xero_Invoices!$D$6:$D$26,B16,Raw_Xero_Invoices!$M$6:$M$26,"Draft") -> 0 | E16: =SUMIFS(Raw_Xero_Invoices!$H$6:$H$26,Raw_Xero_Invoices!$D$6:$D$26,B16,Raw_Xero_Invoices!$M$6:$M$26,"Unsent") -> 0 | F16: =SUMIFS(Raw_Xero_Invoices!$H$6:$H$26,Raw_Xero_Invoices!$D$6:$D$26,B16,Raw_Xero_Invoices!$M$6:$M$26,"Awaiting Payment") -> 0 | G16: =SUMIFS(Raw_Xero_Invoices!$H$6:$H$26,Raw_Xero_Invoices!$D$6:$D$26,B16,Raw_Xero_Invoices!$M$6:$M$26,"Partial") -> 0 | H16: =SUMIFS(Raw_Xero_Invoices!$H$6:$H$26,Raw_Xero_Invoices!$D$6:$D$26,B16,Raw_Xero_Invoices!$M$6:$M$26,"Paid") -> 15500 | I16: =SUMIFS(Raw_Xero_Invoices!$H$6:$H$26,Raw_Xero_Invoices!$D$6:$D$26,B16,Raw_Xero_Invoices!$M$6:$M$26,"Void") -> 0 | J16: =D16+E16+F16+G16 -> 0 | K16: =COUNTIFS(Raw_Xero_Invoices!$D$6:$D$26,B16) -> 1
B17: Marina Bay Holdings | C17: =SUMIFS(Raw_Xero_Invoices!$H$6:$H$26,Raw_Xero_Invoices!$D$6:$D$26,B17) -> 22758.9 | D17: =SUMIFS(Raw_Xero_Invoices!$H$6:$H$26,Raw_Xero_Invoices!$D$6:$D$26,B17,Raw_Xero_Invoices!$M$6:$M$26,"Draft") -> 0 | E17: =SUMIFS(Raw_Xero_Invoices!$H$6:$H$26,Raw_Xero_Invoices!$D$6:$D$26,B17,Raw_Xero_Invoices!$M$6:$M$26,"Unsent") -> 0 | F17: =SUMIFS(Raw_Xero_Invoices!$H$6:$H$26,Raw_Xero_Invoices!$D$6:$D$26,B17,Raw_Xero_Invoices!$M$6:$M$26,"Awaiting Payment") -> 4926.9 | G17: =SUMIFS(Raw_Xero_Invoices!$H$6:$H$26,Raw_Xero_Invoices!$D$6:$D$26,B17,Raw_Xero_Invoices!$M$6:$M$26,"Partial") -> 0 | H17: =SUMIFS(Raw_Xero_Invoices!$H$6:$H$26,Raw_Xero_Invoices!$D$6:$D$26,B17,Raw_Xero_Invoices!$M$6:$M$26,"Paid") -> 17832 | I17: =SUMIFS(Raw_Xero_Invoices!$H$6:$H$26,Raw_Xero_Invoices!$D$6:$D$26,B17,Raw_Xero_Invoices!$M$6:$M$26,"Void") -> 0 | J17: =D17+E17+F17+G17 -> 4926.9 | K17: =COUNTIFS(Raw_Xero_Invoices!$D$6:$D$26,B17) -> 2
B18: Lion City Media | C18: =SUMIFS(Raw_Xero_Invoices!$H$6:$H$26,Raw_Xero_Invoices!$D$6:$D$26,B18) -> 3124.8 | D18: =SUMIFS(Raw_Xero_Invoices!$H$6:$H$26,Raw_Xero_Invoices!$D$6:$D$26,B18,Raw_Xero_Invoices!$M$6:$M$26,"Draft") -> 0 | E18: =SUMIFS(Raw_Xero_Invoices!$H$6:$H$26,Raw_Xero_Invoices!$D$6:$D$26,B18,Raw_Xero_Invoices!$M$6:$M$26,"Unsent") -> 0 | F18: =SUMIFS(Raw_Xero_Invoices!$H$6:$H$26,Raw_Xero_Invoices!$D$6:$D$26,B18,Raw_Xero_Invoices!$M$6:$M$26,"Awaiting Payment") -> 0 | G18: =SUMIFS(Raw_Xero_Invoices!$H$6:$H$26,Raw_Xero_Invoices!$D$6:$D$26,B18,Raw_Xero_Invoices!$M$6:$M$26,"Partial") -> 0 | H18: =SUMIFS(Raw_Xero_Invoices!$H$6:$H$26,Raw_Xero_Invoices!$D$6:$D$26,B18,Raw_Xero_Invoices!$M$6:$M$26,"Paid") -> 3124.8 | I18: =SUMIFS(Raw_Xero_Invoices!$H$6:$H$26,Raw_Xero_Invoices!$D$6:$D$26,B18,Raw_Xero_Invoices!$M$6:$M$26,"Void") -> 0 | J18: =D18+E18+F18+G18 -> 0 | K18: =COUNTIFS(Raw_Xero_Invoices!$D$6:$D$26,B18) -> 1
... B21: Jakarta Digital Ventures | C21: =SUMIFS(Raw_Xero_Invoices!$H$6:$H$26,Raw_Xero_Invoices!$D$6:$D$26,B21) -> 11500 | D21: =SUMIFS(Raw_Xero_Invoices!$H$6:$H$26,Raw_Xero_Invoices!$D$6:$D$26,B21,Raw_Xero_Invoices!$M$6:$M$26,"Draft") -> 0 | E21: =SUMIFS(Raw_Xero_Invoices!$H$6:$H$26,Raw_Xero_Invoices!$D$6:$D$26,B21,Raw_Xero_Invoices!$M$6:$M$26,"Unsent") -> 11500 | F21: =SUMIFS(Raw_Xero_Invoices!$H$6:$H$26,Raw_Xero_Invoices!$D$6:$D$26,B21,Raw_Xero_Invoices!$M$6:$M$26,"Awaiting Payment") -> 0 | G21: =SUMIFS(Raw_Xero_Invoices!$H$6:$H$26,Raw_Xero_Invoices!$D$6:$D$26,B21,Raw_Xero_Invoices!$M$6:$M$26,"Partial") -> 0 | H21: =SUMIFS(Raw_Xero_Invoices!$H$6:$H$26,Raw_Xero_Invoices!$D$6:$D$26,B21,Raw_Xero_Invoices!$M$6:$M$26,"Paid") -> 0 | I21: =SUMIFS(Raw_Xero_Invoices!$H$6:$H$26,Raw_Xero_Invoices!$D$6:$D$26,B21,Raw_Xero_Invoices!$M$6:$M$26,"Void") -> 0 | J21: =D21+E21+F21+G21 -> 11500 | K21: =COUNTIFS(Raw_Xero_Invoices!$D$6:$D$26,B21) -> 1
B22: TOTAL | C22: =SUM(C7:C21) -> 134873.99 | D22: =SUM(D7:D21) -> 12337.4 | E22: =SUM(E7:E21) -> 21000 | F22: =SUM(F7:F21) -> 6152.25 | G22: =SUM(G7:G21) -> 13672.34 | H22: =SUM(H7:H21) -> 78444.4 | I22: =SUM(I7:I21) -> 3267.6 | J22: =SUM(J7:J21) -> 53161.99 | K22: =SUM(K7:K21) -> 21
B25: STRIPE CUSTOMER RECEIVABLES (per customer × invoice status)
B26: Customer | C26: Total Invoiced USD | D26: Draft | E26: Unsent | F26: Await Pay | G26: Partial | H26: Paid | I26: Void | J26: Outstanding USD | K26: # Invoices
B27: Alphabet Logistics LLC | C27: =SUMIFS(Raw_Stripe!$H$6:$H$49,Raw_Stripe!$D$6:$D$49,B27) -> 9394.35 | D27: =SUMIFS(Raw_Stripe!$H$6:$H$49,Raw_Stripe!$D$6:$D$49,B27,Raw_Stripe!$P$6:$P$49,"Draft") -> 0 | E27: =SUMIFS(Raw_Stripe!$H$6:$H$49,Raw_Stripe!$D$6:$D$49,B27,Raw_Stripe!$P$6:$P$49,"Unsent") -> 2314.55 | F27: =SUMIFS(Raw_Stripe!$H$6:$H$49,Raw_Stripe!$D$6:$D$49,B27,Raw_Stripe!$P$6:$P$49,"Awaiting Payment") -> 0 | G27: =SUMIFS(Raw_Stripe!$H$6:$H$49,Raw_Stripe!$D$6:$D$49,B27,Raw_Stripe!$P$6:$P$49,"Partial") -> 1279.81 | H27: =SUMIFS(Raw_Stripe!$H$6:$H$49,Raw_Stripe!$D$6:$D$49,B27,Raw_Stripe!$P$6:$P$49,"Paid") -> 5799.99 | I27: =SUMIFS(Raw_Stripe!$H$6:$H$49,Raw_Stripe!$D$6:$D$49,B27,Raw_Stripe!$P$6:$P$49,"Void") -> 0 | J27: =D27+E27+F27+G27 -> 3594.36 | K27: =COUNTIFS(Raw_Stripe!$D$6:$D$49,B27) -> 7
B28: Emirates Retail Group | C28: =SUMIFS(Raw_Stripe!$H$6:$H$49,Raw_Stripe!$D$6:$D$49,B28) -> 3322.06 | D28: =SUMIFS(Raw_Stripe!$H$6:$H$49,Raw_Stripe!$D$6:$D$49,B28,Raw_Stripe!$P$6:$P$49,"Draft") -> 0 | E28: =SUMIFS(Raw_Stripe!$H$6:$H$49,Raw_Stripe!$D$6:$D$49,B28,Raw_Stripe!$P$6:$P$49,"Unsent") -> 1143.66 | F28: =SUMIFS(Raw_Stripe!$H$6:$H$49,Raw_Stripe!$D$6:$D$49,B28,Raw_Stripe!$P$6:$P$49,"Awaiting Payment") -> 0 | G28: =SUMIFS(Raw_Stripe!$H$6:$H$49,Raw_Stripe!$D$6:$D$49,B28,Raw_Stripe!$P$6:$P$49,"Partial") -> 0 | H28: =SUMIFS(Raw_Stripe!$H$6:$H$49,Raw_Stripe!$D$6:$D$49,B28,Raw_Stripe!$P$6:$P$49,"Paid") -> 2178.4 | I28: =SUMIFS(Raw_Stripe!$H$6:$H$49,Raw_Stripe!$D$6:$D$49,B28,Raw_Stripe!$P$6:$P$49,"Void") -> 0 | J28: =D28+E28+F28+G28 -> 1143.66 | K28: =COUNTIFS(Raw_Stripe!$D$6:$D$49,B28) -> 5
B29: Gulf Tech Distribution | C29: =SUMIFS(Raw_Stripe!$H$6:$H$49,Raw_Stripe!$D$6:$D$49,B29) -> 46000 | D29: =SUMIFS(Raw_Stripe!$H$6:$H$49,Raw_Stripe!$D$6:$D$49,B29,Raw_Stripe!$P$6:$P$49,"Draft") -> 9500 | E29: =SUMIFS(Raw_Stripe!$H$6:$H$49,Raw_Stripe!$D$6:$D$49,B29,Raw_Stripe!$P$6:$P$49,"Unsent") -> 0 | F29: =SUMIFS(Raw_Stripe!$H$6:$H$49,Raw_Stripe!$D$6:$D$49,B29,Raw_Stripe!$P$6:$P$49,"Awaiting Payment") -> 0 | G29: =SUMIFS(Raw_Stripe!$H$6:$H$49,Raw_Stripe!$D$6:$D$49,B29,Raw_Stripe!$P$6:$P$49,"Partial") -> 0 | H29: =SUMIFS(Raw_Stripe!$H$6:$H$49,Raw_Stripe!$D$6:$D$49,B29,Raw_Stripe!$P$6:$P$49,"Paid") -> 36500 | I29: =SUMIFS(Raw_Stripe!$H$6:$H$49,Raw_Stripe!$D$6:$D$49,B29,Raw_Stripe!$P$6:$P$49,"Void") -> 0 | J29: =D29+E29+F29+G29 -> 9500 | K29: =COUNTIFS(Raw_Stripe!$D$6:$D$49,B29) -> 5
B30: Dubai Properties Co | C30: =SUMIFS(Raw_Stripe!$H$6:$H$49,Raw_Stripe!$D$6:$D$49,B30) -> 4656.33 | D30: =SUMIFS(Raw_Stripe!$H$6:$H$49,Raw_Stripe!$D$6:$D$49,B30,Raw_Stripe!$P$6:$P$49,"Draft") -> 0 | E30: =SUMIFS(Raw_Stripe!$H$6:$H$49,Raw_Stripe!$D$6:$D$49,B30,Raw_Stripe!$P$6:$P$49,"Unsent") -> 0 | F30: =SUMIFS(Raw_Stripe!$H$6:$H$49,Raw_Stripe!$D$6:$D$49,B30,Raw_Stripe!$P$6:$P$49,"Awaiting Payment") -> 0 | G30: =SUMIFS(Raw_Stripe!$H$6:$H$49,Raw_Stripe!$D$6:$D$49,B30,Raw_Stripe!$P$6:$P$49,"Partial") -> 0 | H30: =SUMIFS(Raw_Stripe!$H$6:$H$49,Raw_Stripe!$D$6:$D$49,B30,Raw_Stripe!$P$6:$P$49,"Paid") -> 4656.33 | I30: =SUMIFS(Raw_Stripe!$H$6:$H$49,Raw_Stripe!$D$6:$D$49,B30,Raw_Stripe!$P$6:$P$49,"Void") -> 0 | J30: =D30+E30+F30+G30 -> 0 | K30: =COUNTIFS(Raw_Stripe!$D$6:$D$49,B30) -> 3
B31: Abu Dhabi Trading | C31: =SUMIFS(Raw_Stripe!$H$6:$H$49,Raw_Stripe!$D$6:$D$49,B31) -> 1715.49 | D31: =SUMIFS(Raw_Stripe!$H$6:$H$49,Raw_Stripe!$D$6:$D$49,B31,Raw_Stripe!$P$6:$P$49,"Draft") -> 0 | E31: =SUMIFS(Raw_Stripe!$H$6:$H$49,Raw_Stripe!$D$6:$D$49,B31,Raw_Stripe!$P$6:$P$49,"Unsent") -> 0 | F31: =SUMIFS(Raw_Stripe!$H$6:$H$49,Raw_Stripe!$D$6:$D$49,B31,Raw_Stripe!$P$6:$P$49,"Awaiting Payment") -> 0 | G31: =SUMIFS(Raw_Stripe!$H$6:$H$49,Raw_Stripe!$D$6:$D$49,B31,Raw_Stripe!$P$6:$P$49,"Partial") -> 0 | H31: =SUMIFS(Raw_Stripe!$H$6:$H$49,Raw_Stripe!$D$6:$D$49,B31,Raw_Stripe!$P$6:$P$49,"Paid") -> 1715.49 | I31: =SUMIFS(Raw_Stripe!$H$6:$H$49,Raw_Stripe!$D$6:$D$49,B31,Raw_Stripe!$P$6:$P$49,"Void") -> 0 | J31: =D31+E31+F31+G31 -> 0 | K31: =COUNTIFS(Raw_Stripe!$D$6:$D$49,B31) -> 2
B32: Rak Bank Digital | C32: =SUMIFS(Raw_Stripe!$H$6:$H$49,Raw_Stripe!$D$6:$D$49,B32) -> 4438.49 | D32: =SUMIFS(Raw_Stripe!$H$6:$H$49,Raw_Stripe!$D$6:$D$49,B32,Raw_Stripe!$P$6:$P$49,"Draft") -> 0 | E32: =SUMIFS(Raw_Stripe!$H$6:$H$49,Raw_Stripe!$D$6:$D$49,B32,Raw_Stripe!$P$6:$P$49,"Unsent") -> 0 | F32: =SUMIFS(Raw_Stripe!$H$6:$H$49,Raw_Stripe!$D$6:$D$49,B32,Raw_Stripe!$P$6:$P$49,"Awaiting Payment") -> 0 | G32: =SUMIFS(Raw_Stripe!$H$6:$H$49,Raw_Stripe!$D$6:$D$49,B32,Raw_Stripe!$P$6:$P$49,"Partial") -> 0 | H32: =SUMIFS(Raw_Stripe!$H$6:$H$49,Raw_Stripe!$D$6:$D$49,B32,Raw_Stripe!$P$6:$P$49,"Paid") -> 2586.85 | I32: =SUMIFS(Raw_Stripe!$H$6:$H$49,Raw_Stripe!$D$6:$D$49,B32,Raw_Stripe!$P$6:$P$49,"Void") -> 1851.64 | J32: =D32+E32+F32+G32 -> 0 | K32: =COUNTIFS(Raw_Stripe!$D$6:$D$49,B32) -> 2
B33: Global SaaS Inc | C33: =SUMIFS(Raw_Stripe!$H$6:$H$49,Raw_Stripe!$D$6:$D$49,B33) -> 24000 | D33: =SUMIFS(Raw_Stripe!$H$6:$H$49,Raw_Stripe!$D$6:$D$49,B33,Raw_Stripe!$P$6:$P$49,"Draft") -> 0 | E33: =SUMIFS(Raw_Stripe!$H$6:$H$49,Raw_Stripe!$D$6:$D$49,B33,Raw_Stripe!$P$6:$P$49,"Unsent") -> 0 | F33: =SUMIFS(Raw_Stripe!$H$6:$H$49,Raw_Stripe!$D$6:$D$49,B33,Raw_Stripe!$P$6:$P$49,"Awaiting Payment") -> 0 | G33: =SUMIFS(Raw_Stripe!$H$6:$H$49,Raw_Stripe!$D$6:$D$49,B33,Raw_Stripe!$P$6:$P$49,"Partial") -> 0 | H33: =SUMIFS(Raw_Stripe!$H$6:$H$49,Raw_Stripe!$D$6:$D$49,B33,Raw_Stripe!$P$6:$P$49,"Paid") -> 24000 | I33: =SUMIFS(Raw_Stripe!$H$6:$H$49,Raw_Stripe!$D$6:$D$49,B33,Raw_Stripe!$P$6:$P$49,"Void") -> 0 | J33: =D33+E33+F33+G33 -> 0 | K33: =COUNTIFS(Raw_Stripe!$D$6:$D$49,B33) -> 1
B34: Mena Apps FZ-LLC | C34: =SUMIFS(Raw_Stripe!$H$6:$H$49,Raw_Stripe!$D$6:$D$49,B34) -> 11900 | D34: =SUMIFS(Raw_Stripe!$H$6:$H$49,Raw_Stripe!$D$6:$D$49,B34,Raw_Stripe!$P$6:$P$49,"Draft") -> 0 | E34: =SUMIFS(Raw_Stripe!$H$6:$H$49,Raw_Stripe!$D$6:$D$49,B34,Raw_Stripe!$P$6:$P$49,"Unsent") -> 6500 | F34: =SUMIFS(Raw_Stripe!$H$6:$H$49,Raw_Stripe!$D$6:$D$49,B34,Raw_Stripe!$P$6:$P$49,"Awaiting Payment") -> 0 | G34: =SUMIFS(Raw_Stripe!$H$6:$H$49,Raw_Stripe!$D$6:$D$49,B34,Raw_Stripe!$P$6:$P$49,"Partial") -> 0 | H34: =SUMIFS(Raw_Stripe!$H$6:$H$49,Raw_Stripe!$D$6:$D$49,B34,Raw_Stripe!$P$6:$P$49,"Paid") -> 5400 | I34: =SUMIFS(Raw_Stripe!$H$6:$H$49,Raw_Stripe!$D$6:$D$49,B34,Raw_Stripe!$P$6:$P$49,"Void") -> 0 | J34: =D34+E34+F34+G34 -> 6500 | K34: =COUNTIFS(Raw_Stripe!$D$6:$D$49,B34) -> 2
B35: Singapore FinTech Hub | C35: =SUMIFS(Raw_Stripe!$H$6:$H$49,Raw_Stripe!$D$6:$D$49,B35) -> 17744.4 | D35: =SUMIFS(Raw_Stripe!$H$6:$H$49,Raw_Stripe!$D$6:$D$49,B35,Raw_Stripe!$P$6:$P$49,"Draft") -> 3135.3 | E35: =SUMIFS(Raw_Stripe!$H$6:$H$49,Raw_Stripe!$D$6:$D$49,B35,Raw_Stripe!$P$6:$P$49,"Unsent") -> 0 | F35: =SUMIFS(Raw_Stripe!$H$6:$H$49,Raw_Stripe!$D$6:$D$49,B35,Raw_Stripe!$P$6:$P$49,"Awaiting Payment") -> 0 | G35: =SUMIFS(Raw_Stripe!$H$6:$H$49,Raw_Stripe!$D$6:$D$49,B35,Raw_Stripe!$P$6:$P$49,"Partial") -> 0 | H35: =SUMIFS(Raw_Stripe!$H$6:$H$49,Raw_Stripe!$D$6:$D$49,B35,Raw_Stripe!$P$6:$P$49,"Paid") -> 14609.1 | I35: =SUMIFS(Raw_Stripe!$H$6:$H$49,Raw_Stripe!$D$6:$D$49,B35,Raw_Stripe!$P$6:$P$49,"Void") -> 0 | J35: =D35+E35+F35+G35 -> 3135.3 | K35: =COUNTIFS(Raw_Stripe!$D$6:$D$49,B35) -> 5
B36: Asia Pacific Solutions | C36: =SUMIFS(Raw_Stripe!$H$6:$H$49,Raw_Stripe!$D$6:$D$49,B36) -> 23000 | D36: =SUMIFS(Raw_Stripe!$H$6:$H$49,Raw_Stripe!$D$6:$D$49,B36,Raw_Stripe!$P$6:$P$49,"Draft") -> 0 | E36: =SUMIFS(Raw_Stripe!$H$6:$H$49,Raw_Stripe!$D$6:$D$49,B36,Raw_Stripe!$P$6:$P$49,"Unsent") -> 0 | F36: =SUMIFS(Raw_Stripe!$H$6:$H$49,Raw_Stripe!$D$6:$D$49,B36,Raw_Stripe!$P$6:$P$49,"Awaiting Payment") -> 0 | G36: =SUMIFS(Raw_Stripe!$H$6:$H$49,Raw_Stripe!$D$6:$D$49,B36,Raw_Stripe!$P$6:$P$49,"Partial") -> 0 | H36: =SUMIFS(Raw_Stripe!$H$6:$H$49,Raw_Stripe!$D$6:$D$49,B36,Raw_Stripe!$P$6:$P$49,"Paid") -> 23000 | I36: =SUMIFS(Raw_Stripe!$H$6:$H$49,Raw_Stripe!$D$6:$D$49,B36,Raw_Stripe!$P$6:$P$49,"Void") -> 0 | J36: =D36+E36+F36+G36 -> 0 | K36: =COUNTIFS(Raw_Stripe!$D$6:$D$49,B36) -> 2
B37: Marina Bay Holdings | C37: =SUMIFS(Raw_Stripe!$H$6:$H$49,Raw_Stripe!$D$6:$D$49,B37) -> 19400.4 | D37: =SUMIFS(Raw_Stripe!$H$6:$H$49,Raw_Stripe!$D$6:$D$49,B37,Raw_Stripe!$P$6:$P$49,"Draft") -> 0 | E37: =SUMIFS(Raw_Stripe!$H$6:$H$49,Raw_Stripe!$D$6:$D$49,B37,Raw_Stripe!$P$6:$P$49,"Unsent") -> 0 | F37: =SUMIFS(Raw_Stripe!$H$6:$H$49,Raw_Stripe!$D$6:$D$49,B37,Raw_Stripe!$P$6:$P$49,"Awaiting Payment") -> 0 | G37: =SUMIFS(Raw_Stripe!$H$6:$H$49,Raw_Stripe!$D$6:$D$49,B37,Raw_Stripe!$P$6:$P$49,"Partial") -> 0 | H37: =SUMIFS(Raw_Stripe!$H$6:$H$49,Raw_Stripe!$D$6:$D$49,B37,Raw_Stripe!$P$6:$P$49,"Paid") -> 18056.7 | I37: =SUMIFS(Raw_Stripe!$H$6:$H$49,Raw_Stripe!$D$6:$D$49,B37,Raw_Stripe!$P$6:$P$49,"Void") -> 1343.7 | J37: =D37+E37+F37+G37 -> 0 | K37: =COUNTIFS(Raw_Stripe!$D$6:$D$49,B37) -> 4
B38: Lion City Media | C38: =SUMIFS(Raw_Stripe!$H$6:$H$49,Raw_Stripe!$D$6:$D$49,B38) -> 5873.5 | D38: =SUMIFS(Raw_Stripe!$H$6:$H$49,Raw_Stripe!$D$6:$D$49,B38,Raw_Stripe!$P$6:$P$49,"Draft") -> 0 | E38: =SUMIFS(Raw_Stripe!$H$6:$H$49,Raw_Stripe!$D$6:$D$49,B38,Raw_Stripe!$P$6:$P$49,"Unsent") -> 0 | F38: =SUMIFS(Raw_Stripe!$H$6:$H$49,Raw_Stripe!$D$6:$D$49,B38,Raw_Stripe!$P$6:$P$49,"Awaiting Payment") -> 0 | G38: =SUMIFS(Raw_Stripe!$H$6:$H$49,Raw_Stripe!$D$6:$D$49,B38,Raw_Stripe!$P$6:$P$49,"Partial") -> 0 | H38: =SUMIFS(Raw_Stripe!$H$6:$H$49,Raw_Stripe!$D$6:$D$49,B38,Raw_Stripe!$P$6:$P$49,"Paid") -> 5873.5 | I38: =SUMIFS(Raw_Stripe!$H$6:$H$49,Raw_Stripe!$D$6:$D$49,B38,Raw_Stripe!$P$6:$P$49,"Void") -> 0 | J38: =D38+E38+F38+G38 -> 0 | K38: =COUNTIFS(Raw_Stripe!$D$6:$D$49,B38) -> 2
... B41: Jakarta Digital Ventures | C41: =SUMIFS(Raw_Stripe!$H$6:$H$49,Raw_Stripe!$D$6:$D$49,B41) -> 11200 | D41: =SUMIFS(Raw_Stripe!$H$6:$H$49,Raw_Stripe!$D$6:$D$49,B41,Raw_Stripe!$P$6:$P$49,"Draft") -> 0 | E41: =SUMIFS(Raw_Stripe!$H$6:$H$49,Raw_Stripe!$D$6:$D$49,B41,Raw_Stripe!$P$6:$P$49,"Unsent") -> 0 | F41: =SUMIFS(Raw_Stripe!$H$6:$H$49,Raw_Stripe!$D$6:$D$49,B41,Raw_Stripe!$P$6:$P$49,"Awaiting Payment") -> 0 | G41: =SUMIFS(Raw_Stripe!$H$6:$H$49,Raw_Stripe!$D$6:$D$49,B41,Raw_Stripe!$P$6:$P$49,"Partial") -> 0 | H41: =SUMIFS(Raw_Stripe!$H$6:$H$49,Raw_Stripe!$D$6:$D$49,B41,Raw_Stripe!$P$6:$P$49,"Paid") -> 11200 | I41: =SUMIFS(Raw_Stripe!$H$6:$H$49,Raw_Stripe!$D$6:$D$49,B41,Raw_Stripe!$P$6:$P$49,"Void") -> 0 | J41: =D41+E41+F41+G41 -> 0 | K41: =COUNTIFS(Raw_Stripe!$D$6:$D$49,B41) -> 1
B42: TOTAL | C42: =SUM(C27:C41) -> 218895.77 | D42: =SUM(D27:D41) -> 36635.3 | E42: =SUM(E27:E41) -> 9958.21 | F42: =SUM(F27:F41) -> 0 | G42: =SUM(G27:G41) -> 11330.56 | H42: =SUM(H27:H41) -> 157776.36 | I42: =SUM(I27:I41) -> 3195.34 | J42: =SUM(J27:J41) -> 57924.07 | K42: =SUM(K27:K41) -> 44
B44: COMBINED RECEIVABLES SUMMARY
B45: Xero: Total Invoiced (USD) | C45: =C22 -> 134873.99
B46: Xero: Outstanding (USD) | C46: =J22 -> 53161.99
B47: Stripe: Total Charged (USD) | C47: =C42 -> 218895.77
B48: Stripe: Outstanding (USD) | C48: =J42 -> 57924.07
B49: Combined Outstanding (USD) | C49: =J22+J42 -> 111086.06
...

Sheet Meta_Expenses
B2: Meta Expenses · With Discount Add-Back
B3: Per-customer Meta cost: Net Paid + Discount Given = Amount With Add-Back (USD)
B5: PER-CUSTOMER META COST (USD equivalent, with add-back)
B6: Customer | C6: Gross Billed | D6: Discount Given | E6: Net Paid | F6: Amount With AddBack | G6: % Discount | H6: # Invoices | I6: Jan | J6: Feb | K6: Mar | L6: Apr | M6: May | N6: Jun | O6: Jul-Aug-Dec
B7: Alphabet Logistics LLC | C7: =SUMIFS(Raw_Meta!$L$6:$L$28,Raw_Meta!$E$6:$E$28,B7) -> 35700 | D7: =IFERROR(SUMIFS(Raw_Meta!$L$6:$L$28,Raw_Meta!$E$6:$E$28,B7)*SUMIFS(Raw_Meta!$H$6:$H$28,Raw_Meta!$E$6:$E$28,B7)/SUMIFS(Raw_Meta!$G$6:$G$28,Raw_Meta!$E$6:$E$28,B7),0) -> 3500 | E7: =C7-D7 -> 32200 | F7: =C7 -> 35700 | G7: =IFERROR(D7/C7,0) -> 0.098039216 | H7: =COUNTIFS(Raw_Meta!$E$6:$E$28,B7) -> 6 | I7: =SUMIFS(Raw_Meta!$L$6:$L$28,Raw_Meta!$E$6:$E$28,B7,Raw_Meta!$N$6:$N$28,"Jan-25") -> 5200 | J7: =SUMIFS(Raw_Meta!$L$6:$L$28,Raw_Meta!$E$6:$E$28,B7,Raw_Meta!$N$6:$N$28,"Feb-25") -> 5500 | K7: =SUMIFS(Raw_Meta!$L$6:$L$28,Raw_Meta!$E$6:$E$28,B7,Raw_Meta!$N$6:$N$28,"Mar-25") -> 5800 | L7: =SUMIFS(Raw_Meta!$L$6:$L$28,Raw_Meta!$E$6:$E$28,B7,Raw_Meta!$N$6:$N$28,"Apr-25") -> 6100 | M7: =SUMIFS(Raw_Meta!$L$6:$L$28,Raw_Meta!$E$6:$E$28,B7,Raw_Meta!$N$6:$N$28,"May-25") -> 6300 | N7: =SUMIFS(Raw_Meta!$L$6:$L$28,Raw_Meta!$E$6:$E$28,B7,Raw_Meta!$N$6:$N$28,"Jun-25") -> 0 | O7: =SUMIFS(Raw_Meta!$L$6:$L$28,Raw_Meta!$E$6:$E$28,B7,Raw_Meta!$N$6:$N$28,"Jul-25")+SUMIFS(Raw_Meta!$L$6:$L$28,Raw_Meta!$E$6:$E$28,B7,Raw_Meta!$N$6:$N$28,"Aug-25")+SUMIFS(Raw_Meta!$L$6:$L$28,Raw_Meta!$E$6:$E$28,B7,Raw_Meta!$N$6:$N$28,"Sep-25")+SUMIFS(Raw_Meta!$L$6:$L$28,Raw_Meta!$E$6:$E$28,B7,Raw_Meta!$N$6:$N$28,"Oct-25")+SUMIFS(Raw_Meta!$L$6:$L$28,Raw_Meta!$E$6:$E$28,B7,Raw_Meta!$N$6:$N$28,"Nov-25")+SUMIFS(Raw_Meta!$L$6:$L$28,Raw_Meta!$E$6:$E$28,B7,Raw_Meta!$N$6:$N$28,"Dec-25") -> 6800
B8: Emirates Retail Group | C8: =SUMIFS(Raw_Meta!$L$6:$L$28,Raw_Meta!$E$6:$E$28,B8) -> 7800 | D8: =IFERROR(SUMIFS(Raw_Meta!$L$6:$L$28,Raw_Meta!$E$6:$E$28,B8)*SUMIFS(Raw_Meta!$H$6:$H$28,Raw_Meta!$E$6:$E$28,B8)/SUMIFS(Raw_Meta!$G$6:$G$28,Raw_Meta!$E$6:$E$28,B8),0) -> 600 | E8: =C8-D8 -> 7200 | F8: =C8 -> 7800 | G8: =IFERROR(D8/C8,0) -> 0.076923077 | H8: =COUNTIFS(Raw_Meta!$E$6:$E$28,B8) -> 2 | I8: =SUMIFS(Raw_Meta!$L$6:$L$28,Raw_Meta!$E$6:$E$28,B8,Raw_Meta!$N$6:$N$28,"Jan-25") -> 3800 | J8: =SUMIFS(Raw_Meta!$L$6:$L$28,Raw_Meta!$E$6:$E$28,B8,Raw_Meta!$N$6:$N$28,"Feb-25") -> 4000 | K8: =SUMIFS(Raw_Meta!$L$6:$L$28,Raw_Meta!$E$6:$E$28,B8,Raw_Meta!$N$6:$N$28,"Mar-25") -> 0 | L8: =SUMIFS(Raw_Meta!$L$6:$L$28,Raw_Meta!$E$6:$E$28,B8,Raw_Meta!$N$6:$N$28,"Apr-25") -> 0 | M8: =SUMIFS(Raw_Meta!$L$6:$L$28,Raw_Meta!$E$6:$E$28,B8,Raw_Meta!$N$6:$N$28,"May-25") -> 0 | N8: =SUMIFS(Raw_Meta!$L$6:$L$28,Raw_Meta!$E$6:$E$28,B8,Raw_Meta!$N$6:$N$28,"Jun-25") -> 0 | O8: =SUMIFS(Raw_Meta!$L$6:$L$28,Raw_Meta!$E$6:$E$28,B8,Raw_Meta!$N$6:$N$28,"Jul-25")+SUMIFS(Raw_Meta!$L$6:$L$28,Raw_Meta!$E$6:$E$28,B8,Raw_Meta!$N$6:$N$28,"Aug-25")+SUMIFS(Raw_Meta!$L$6:$L$28,Raw_Meta!$E$6:$E$28,B8,Raw_Meta!$N$6:$N$28,"Sep-25")+SUMIFS(Raw_Meta!$L$6:$L$28,Raw_Meta!$E$6:$E$28,B8,Raw_Meta!$N$6:$N$28,"Oct-25")+SUMIFS(Raw_Meta!$L$6:$L$28,Raw_Meta!$E$6:$E$28,B8,Raw_Meta!$N$6:$N$28,"Nov-25")+SUMIFS(Raw_Meta!$L$6:$L$28,Raw_Meta!$E$6:$E$28,B8,Raw_Meta!$N$6:$N$28,"Dec-25") -> 0
B9: Gulf Tech Distribution | C9: =SUMIFS(Raw_Meta!$L$6:$L$28,Raw_Meta!$E$6:$E$28,B9) -> 20400 | D9: =IFERROR(SUMIFS(Raw_Meta!$L$6:$L$28,Raw_Meta!$E$6:$E$28,B9)*SUMIFS(Raw_Meta!$H$6:$H$28,Raw_Meta!$E$6:$E$28,B9)/SUMIFS(Raw_Meta!$G$6:$G$28,Raw_Meta!$E$6:$E$28,B9),0) -> 1650 | E9: =C9-D9 -> 18750 | F9: =C9 -> 20400 | G9: =IFERROR(D9/C9,0) -> 0.080882353 | H9: =COUNTIFS(Raw_Meta!$E$6:$E$28,B9) -> 3 | I9: =SUMIFS(Raw_Meta!$L$6:$L$28,Raw_Meta!$E$6:$E$28,B9,Raw_Meta!$N$6:$N$28,"Jan-25") -> 6500 | J9: =SUMIFS(Raw_Meta!$L$6:$L$28,Raw_Meta!$E$6:$E$28,B9,Raw_Meta!$N$6:$N$28,"Feb-25") -> 6800 | K9: =SUMIFS(Raw_Meta!$L$6:$L$28,Raw_Meta!$E$6:$E$28,B9,Raw_Meta!$N$6:$N$28,"Mar-25") -> 0 | L9: =SUMIFS(Raw_Meta!$L$6:$L$28,Raw_Meta!$E$6:$E$28,B9,Raw_Meta!$N$6:$N$28,"Apr-25") -> 0 | M9: =SUMIFS(Raw_Meta!$L$6:$L$28,Raw_Meta!$E$6:$E$28,B9,Raw_Meta!$N$6:$N$28,"May-25") -> 7100 | N9: =SUMIFS(Raw_Meta!$L$6:$L$28,Raw_Meta!$E$6:$E$28,B9,Raw_Meta!$N$6:$N$28,"Jun-25") -> 0 | O9: =SUMIFS(Raw_Meta!$L$6:$L$28,Raw_Meta!$E$6:$E$28,B9,Raw_Meta!$N$6:$N$28,"Jul-25")+SUMIFS(Raw_Meta!$L$6:$L$28,Raw_Meta!$E$6:$E$28,B9,Raw_Meta!$N$6:$N$28,"Aug-25")+SUMIFS(Raw_Meta!$L$6:$L$28,Raw_Meta!$E$6:$E$28,B9,Raw_Meta!$N$6:$N$28,"Sep-25")+SUMIFS(Raw_Meta!$L$6:$L$28,Raw_Meta!$E$6:$E$28,B9,Raw_Meta!$N$6:$N$28,"Oct-25")+SUMIFS(Raw_Meta!$L$6:$L$28,Raw_Meta!$E$6:$E$28,B9,Raw_Meta!$N$6:$N$28,"Nov-25")+SUMIFS(Raw_Meta!$L$6:$L$28,Raw_Meta!$E$6:$E$28,B9,Raw_Meta!$N$6:$N$28,"Dec-25") -> 0
B10: Singapore FinTech Hub | C10: =SUMIFS(Raw_Meta!$L$6:$L$28,Raw_Meta!$E$6:$E$28,B10) -> 8700 | D10: =IFERROR(SUMIFS(Raw_Meta!$L$6:$L$28,Raw_Meta!$E$6:$E$28,B10)*SUMIFS(Raw_Meta!$H$6:$H$28,Raw_Meta!$E$6:$E$28,B10)/SUMIFS(Raw_Meta!$G$6:$G$28,Raw_Meta!$E$6:$E$28,B10),0) -> 750 | E10: =C10-D10 -> 7950 | F10: =C10 -> 8700 | G10: =IFERROR(D10/C10,0) -> 0.086206897 | H10: =COUNTIFS(Raw_Meta!$E$6:$E$28,B10) -> 2 | I10: =SUMIFS(Raw_Meta!$L$6:$L$28,Raw_Meta!$E$6:$E$28,B10,Raw_Meta!$N$6:$N$28,"Jan-25") -> 4200 | J10: =SUMIFS(Raw_Meta!$L$6:$L$28,Raw_Meta!$E$6:$E$28,B10,Raw_Meta!$N$6:$N$28,"Feb-25") -> 0 | K10: =SUMIFS(Raw_Meta!$L$6:$L$28,Raw_Meta!$E$6:$E$28,B10,Raw_Meta!$N$6:$N$28,"Mar-25") -> 0 | L10: =SUMIFS(Raw_Meta!$L$6:$L$28,Raw_Meta!$E$6:$E$28,B10,Raw_Meta!$N$6:$N$28,"Apr-25") -> 0 | M10: =SUMIFS(Raw_Meta!$L$6:$L$28,Raw_Meta!$E$6:$E$28,B10,Raw_Meta!$N$6:$N$28,"May-25") -> 0 | N10: =SUMIFS(Raw_Meta!$L$6:$L$28,Raw_Meta!$E$6:$E$28,B10,Raw_Meta!$N$6:$N$28,"Jun-25") -> 0 | O10: =SUMIFS(Raw_Meta!$L$6:$L$28,Raw_Meta!$E$6:$E$28,B10,Raw_Meta!$N$6:$N$28,"Jul-25")+SUMIFS(Raw_Meta!$L$6:$L$28,Raw_Meta!$E$6:$E$28,B10,Raw_Meta!$N$6:$N$28,"Aug-25")+SUMIFS(Raw_Meta!$L$6:$L$28,Raw_Meta!$E$6:$E$28,B10,Raw_Meta!$N$6:$N$28,"Sep-25")+SUMIFS(Raw_Meta!$L$6:$L$28,Raw_Meta!$E$6:$E$28,B10,Raw_Meta!$N$6:$N$28,"Oct-25")+SUMIFS(Raw_Meta!$L$6:$L$28,Raw_Meta!$E$6:$E$28,B10,Raw_Meta!$N$6:$N$28,"Nov-25")+SUMIFS(Raw_Meta!$L$6:$L$28,Raw_Meta!$E$6:$E$28,B10,Raw_Meta!$N$6:$N$28,"Dec-25") -> 4500
B11: Abu Dhabi Trading | C11: =SUMIFS(Raw_Meta!$L$6:$L$28,Raw_Meta!$E$6:$E$28,B11) -> 4500 | D11: =IFERROR(SUMIFS(Raw_Meta!$L$6:$L$28,Raw_Meta!$E$6:$E$28,B11)*SUMIFS(Raw_Meta!$H$6:$H$28,Raw_Meta!$E$6:$E$28,B11)/SUMIFS(Raw_Meta!$G$6:$G$28,Raw_Meta!$E$6:$E$28,B11),0) -> 400 | E11: =C11-D11 -> 4100 | F11: =C11 -> 4500 | G11: =IFERROR(D11/C11,0) -> 0.088888889 | H11: =COUNTIFS(Raw_Meta!$E$6:$E$28,B11) -> 1 | I11: =SUMIFS(Raw_Meta!$L$6:$L$28,Raw_Meta!$E$6:$E$28,B11,Raw_Meta!$N$6:$N$28,"Jan-25") -> 0 | J11: =SUMIFS(Raw_Meta!$L$6:$L$28,Raw_Meta!$E$6:$E$28,B11,Raw_Meta!$N$6:$N$28,"Feb-25") -> 0 | K11: =SUMIFS(Raw_Meta!$L$6:$L$28,Raw_Meta!$E$6:$E$28,B11,Raw_Meta!$N$6:$N$28,"Mar-25") -> 4500 | L11: =SUMIFS(Raw_Meta!$L$6:$L$28,Raw_Meta!$E$6:$E$28,B11,Raw_Meta!$N$6:$N$28,"Apr-25") -> 0 | M11: =SUMIFS(Raw_Meta!$L$6:$L$28,Raw_Meta!$E$6:$E$28,B11,Raw_Meta!$N$6:$N$28,"May-25") -> 0 | N11: =SUMIFS(Raw_Meta!$L$6:$L$28,Raw_Meta!$E$6:$E$28,B11,Raw_Meta!$N$6:$N$28,"Jun-25") -> 0 | O11: =SUMIFS(Raw_Meta!$L$6:$L$28,Raw_Meta!$E$6:$E$28,B11,Raw_Meta!$N$6:$N$28,"Jul-25")+SUMIFS(Raw_Meta!$L$6:$L$28,Raw_Meta!$E$6:$E$28,B11,Raw_Meta!$N$6:$N$28,"Aug-25")+SUMIFS(Raw_Meta!$L$6:$L$28,Raw_Meta!$E$6:$E$28,B11,Raw_Meta!$N$6:$N$28,"Sep-25")+SUMIFS(Raw_Meta!$L$6:$L$28,Raw_Meta!$E$6:$E$28,B11,Raw_Meta!$N$6:$N$28,"Oct-25")+SUMIFS(Raw_Meta!$L$6:$L$28,Raw_Meta!$E$6:$E$28,B11,Raw_Meta!$N$6:$N$28,"Nov-25")+SUMIFS(Raw_Meta!$L$6:$L$28,Raw_Meta!$E$6:$E$28,B11,Raw_Meta!$N$6:$N$28,"Dec-25") -> 0
